Workbook

Sheet Front
B1: SF10-JHS
B2: Republic of the Philippines
B3: Department of Education
B4: Learner Permanent Academic Record for Junior High School (SF10-JHS)
B5: (Formerly Form 137)
B6: LEARNER'S INFORMATION
B7: LAST NAME: | G7: CAMIGAO | R7: FIRST NAME: | W7: DHENISE CLARE | AH7: NAME EXT. (Jr,I,II): | AQ7: MIDDLE NAME: | AX7: VELASQUEZ
B8: Learner Reference Number (LRN): | M8: 129781170072 | Z8: Birthdate (mm/dd/yyyy): | AH8: 03/28/2012 | AS8: Sex: | AV8: FEMALE
B10: ELIGIBILITY FOR JHS ENROLLMENT
D12: Elementary School Completer | W12: General Average: | AC12: 82 | AJ12: Citation (if Any):
D13: Name of Elementary School: | M13: CABILI ELEMENTARY SCHOOL | AC13: School ID: | AH13: 129781 | AK13: Address of School: | AR13: QUEZON, PANABO CITY
B15: Other Credential Presented
D16: PEPT Passer | I16: Rating: | X16: ALS A & E Passer | AF16: Rating: | AQ16: Others (Pls. Specify):
D17: Date of Examination/Assessment (mm/dd/yyyy): | AC17: Name and Address of Testing Center:
B19: SCHOLASTIC RECORD
B21: School: | E21: MARYKNOLL COLLEGE OF PANABO, INC. | Q21: School ID: | U21: 405584 | AA21: District: | AD21: PANABO CENTRAL | AM21: Division: | AP21: PANABO CITY | AY21: Region: | BB21: XI
B22: Classified as Grade: | I22: 7 | K22: Section: | N22: ST.JEROME | R22: School Year: | V22: 2024-2025 | AA22: Name of Adviser/Teacher: | AI22: PRINCESS MARLA S. LUMAMBAS | AS22: Signature:
B24: LEARNING AREAS | U24: Quarterly Rating | AJ24: FINAL RATING | AP24: REMARKS
U25: 1 | Y25: 2 | AC25: 3 | AG25: 4
B26: Filipino | U26: 80 | Y26: 82 | AC26: 83 | AG26: 84 | AJ26: =(AG26+AC26+Y26+U26)/4 -> 82.25 | AP26: Passed
B27: English | U27: 80 | Y27: 81 | AC27: 83 | AG27: 83 | AJ27: =(AG27+AC27+Y27+U27)/4 -> 81.75 | AP27: Passed
B28: Mathematics | U28: 82 | Y28: 83 | AC28: 86 | AG28: 85 | AJ28: =(AG28+AC28+Y28+U28)/4 -> 84 | AP28: Passed
B29: Science | U29: 84 | Y29: 85 | AC29: 83 | AG29: 85 | AJ29: =(AG29+AC29+Y29+U29)/4 -> 84.25 | AP29: Passed
B30: Araling Panlipunan (AP) | U30: 86 | Y30: 86 | AC30: 86 | AG30: 88 | AJ30: =(AG30+AC30+Y30+U30)/4 -> 86.5 | AP30: Passed
B31: Christian Living and Values Education (CLVED) | U31: 82 | Y31: 80 | AC31: 85 | AG31: 85 | AJ31: =(AG31+AC31+Y31+U31)/4 -> 83 | AP31: Passed
B32: TLE/Computer Education | U32: 83 | Y32: 83 | AC32: 84 | AG32: 86 | AJ32: =(AG32+AC32+Y32+U32)/4 -> 84 | AP32: Passed
B33: MAPEH | U33: 87 | Y33: 87 | AC33: 87 | AG33: 93 | AJ33: =(AG33+AC33+Y33+U33)/4 -> 88.5 | AP33: Passed
B34: Music and Arts (Performing and Visual Arts) | U34: 86 | Y34: 86 | AC34: 85 | AG34: 91
B35: PE and Health | U35: 88 | Y35: 88 | AC35: 88 | AG35: 94
B36: Conduct | U36: 87 | Y36: 87 | AC36: 86 | AG36: 86 | AJ36: =(AG36+AC36+Y36+U36)/4 -> 86.5 | AP36: Passed
U40: General Average | AJ40: 84 | AP40: Promoted
B42: Remedial Classes | L42: Conducted from (mm/dd/yyyy) | AG42: to (mm/dd/yyyy)
BD43: u
B44: Learning Areas | L44: Final Rating | U44: Remedial Class Mark | AH44: Recomputed Final Grade | AP44: Remarks
B49: School: | E49: QUEZON NATIONAL HIGH SCHOOL | Q49: School ID: | U49: 316405 | AA49: District: | AD49: SECONDARY | AM49: Division: | AP49: PANABO CITY | AY49: Region: | BB49: =BB21 -> XI
B50: Classified as Grade: | I50: 8 | K50: Section: | N50: ARIES | R50: School Year: | V50: 2025-2026 | AA50: Name of Adviser/Teacher: | AI50: JENIVIVE ORTEGA PUNAY | AS50: Signature:
B52: LEARNING AREAS | U52: Quarterly Rating | AJ52: FINAL RATING | AP52: REMARKS
U53: 1 | Y53: 2 | AC53: 3 | AG53: 4
B54: Filipino | U54: 87 | Y54: 79 | AC54: 77 | AG54: 89 | AJ54: =AVERAGE(U54:AI54) -> 83 | AP54: Passed
B55: English | U55: 83 | Y55: 84 | AC55: 83 | AG55: 88 | AJ55: =AVERAGE(U55:AI55) -> 84.5 | AP55: Passed
...

Sheet SirWedz Guides
A1: Edited as of Feb. 24, 2018
A2: 1 | B2: Format of the template
A3: 2 | B3: Margins set at the lowest, zero headers, additional 1 click for the left panel.
A4: 3 | B4: Arial Narrow Font
A5: 4 | B5: Shading for each title headers and separators
A6: 5 | B6: Adjusted Column Width to fit more spaces
A7: 6 | B7: Scaled at 74%
A11: As edited, Wedzmer B. Munjilul, Head Teacher 1, SDO-Davao City, CID-LRMDS Unit.

Sheet Back
B1: SF10-JHS | AZ1: Page 2 of
B3: School: | Q3: School ID: | AA3: District: | AM3: Division: | AY3: Region:
B4: Classified as Grade: | K4: Section: | R4: School Year: | AA4: Name of Adviser/Teacher: | AS4: Signature:
B6: LEARNING AREAS | U6: Quarterly Rating | AJ6: FINAL RATING | AP6: REMARKS
U7: 1 | Y7: 2 | AC7: 3 | AG7: 4
B8: Filipino
B9: English
B10: Mathematics
B11: Science
B12: Araling Panlipunan (AP)
B13: Values Education
B14: Technology and Livelihood Education (TLE)
B15: MAPEH
B16: Music & Arts
B17: Physical Education & Health
U22: General Average
B24: Remedial Classes | L24: Conducted from (mm/dd/yyyy) | AG24: to (mm/dd/yyyy)
BD25: u
B26: Learning Areas | L26: Final Rating | U26: Remedial Class Mark | AH26: Recomputed Final Grade | AP26: Remarks
B31: School: | Q31: School ID: | AA31: District: | AM31: Division: | AY31: Region:
B32: Classified as Grade: | K32: Section: | R32: School Year: | AA32: Name of Adviser/Teacher: | AS32: Signature:
B34: LEARNING AREAS | U34: Quarterly Rating | AJ34: FINAL RATING | AP34: REMARKS
U35: 1 | Y35: 2 | AC35: 3 | AG35: 4
B36: Filipino
B37: English
B38: Mathematics
B39: Science
B40: Araling Panlipunan (AP)
B41: Values Education
B42: Technology and Livelihood Education (TLE)
B43: MAPEH
B44: Music & Arts
B45: Physical Education & Health
U50: General Average
B52: Remedial Classes | L52: Conducted from (mm/dd/yyyy) | AG52: to (mm/dd/yyyy)
BD53: u
B54: Learning Areas | L54: Final Rating | U54: Remedial Class Mark | AH54: Recomputed Final Grade | AP54: Remarks
B59: School: | Q59: School ID: | AA59: District: | AM59: Division: | AY59: Region:
B60: Classified as Grade: | K60: Section: | R60: School Year: | AA60: Name of Adviser/Teacher: | AS60: Signature:
B62: LEARNING AREAS | U62: Quarterly Rating | AJ62: FINAL RATING | AP62: REMARKS
...
