Workbook

Sheet INPUT DATA
A1: Input Data Sheet for E-Class Record
C4: REGION | G4: XI | L4: DIVISION | O4: PANABO CITY
B5: SCHOOL NAME | G5: QUEZON NATIONAL HIGH SCHOOL | T5: SCHOOL ID | X5: 316405 | AD5: SCHOOL YEAR | AG5: 2025 - 2026
A7: FOURTH QUARTER | F7: GRADE & SECTION: | K7: 8 - ARIES | Q7: TEACHER: | S7: JENIVIVE ORTEGA PUNAY | AC7: SUBJECT:
B8: LEARNERS' NAMES
B11: MALE
A12: 1 | B12: ANUBLING, REGIE C.
A13: 2 | B13: BANGCOY, JOHN PAUL P.
A14: 3 | B14: BARRIENTOS, JOHN PAUL M.
A15: 4 | B15: BRIGOLE, ROMEL
A16: 5 | B16: BULAHAN,ROVIC L.
A17: 6 | B17: CIJAS, ROLIE JR. A.
A18: 7 | B18: GARCIA, DAVE P.
A19: 8 | B19: GONZALES, JAMES A.
A20: 9 | B20: LAGUNA, J.B. B.
A21: 10 | B21: LARODA, STEVEN S.
A22: 11 | B22: MERINO, SEDRIK R.
A23: 12 | B23: MONTERAS, VINCENT S.
... A31: 20 | B31: ZOILO, JOHN LORENCE M.
A32: 21
A33: 22
A34: 23
A35: 24
A36: 25
A37: 26
A38: 27 | C38: 0 | D38: 0 | E38: 0
A39: 28
A40: 29
A41: 30
A42: 31
A43: 32
A44: 33
A45: 34
A46: 35
A47: 36
A48: 37
A49: 38
A50: 39
A51: 21 | B51: CABO, JEREM CARL B.
B52: FEMALE
...

Sheet FILIPINO
A1: Summary of Quarterly Grades
C5: REGION | G5: XI | L5: DIVISION | O5: Panabo City
B6: SCHOOL NAME | G6: QUEZON NATIONAL HIGH SCHOOL | S6: SCHOOL ID | W6: 316405
B7: LEARNERS' NAMES | F7: GRADE & SECTION: | K7: ='INPUT DATA'!K7 -> 8 - ARIES | S7: SCHOOL YEAR: | W7: ='INPUT DATA'!AG5 -> 2025 - 2026
F8: TEACHER: | K8: JENIVIVE ORTEGA PUNAY | S8: SUBJECT: | W8: FILIPINO
F9: FILIPINO | J9: FILIPINO | N9: FILIPINO | R9: FILIPINO | V9: FINAL | Z9: REMARK
F10: 1st Quarter | J10: 2nd Quarter | N10: 3rd Quarter | R10: 4th Quarter | V10: GRADE
B11: MALE
A12: 1 | B12: ='INPUT DATA'!B12:D12 -> ANUBLING, REGIE C. | F12: 75 | J12: 75 | N12: 78 | R12: 75 | V12: =SUM(F12,J12,N12,R12)/4 -> 75.75 | Z12: =IF(V12>=75,"PASSED","FAILED") -> PASSED
A13: 2 | B13: ='INPUT DATA'!B13:D13 -> BANGCOY, JOHN PAUL P. | F13: 60 | J13: 60 | N13: 60 | R13: 60 | V13: =SUM(F13,J13,N13,R13)/4 -> 60 | Z13: =IF(V13>=75,"PASSED","FAILED") -> FAILED
A14: 3 | B14: ='INPUT DATA'!B14:D14 -> BARRIENTOS, JOHN PAUL M. | F14: 90 | J14: 85 | N14: 93 | R14: 95 | V14: =SUM(F14,J14,N14,R14)/4 -> 90.75 | Z14: =IF(V14>=75,"PASSED","FAILED") -> PASSED
A15: 4 | B15: ='INPUT DATA'!B15:D15 -> BRIGOLE, ROMEL | F15: 75 | J15: 75 | N15: 65 | R15: 65 | V15: =SUM(F15,J15,N15,R15)/4 -> 70 | Z15: =IF(V15>=75,"PASSED","FAILED") -> FAILED
A16: 5 | B16: ='INPUT DATA'!B16:D16 -> BULAHAN,ROVIC L. | F16: 91 | J16: 92 | N16: 89 | R16: 91 | V16: =SUM(F16,J16,N16,R16)/4 -> 90.75 | Z16: =IF(V16>=75,"PASSED","FAILED") -> PASSED
A17: 6 | B17: ='INPUT DATA'!B17:D17 -> CIJAS, ROLIE JR. A. | F17: 87 | J17: 84 | N17: 86 | R17: 94 | V17: =SUM(F17,J17,N17,R17)/4 -> 87.75 | Z17: =IF(V17>=75,"PASSED","FAILED") -> PASSED
A18: 7 | B18: ='INPUT DATA'!B18:D18 -> GARCIA, DAVE P. | F18: 86 | J18: 78 | N18: 74 | R18: 85 | V18: =SUM(F18,J18,N18,R18)/4 -> 80.75 | Z18: =IF(V18>=75,"PASSED","FAILED") -> PASSED
A19: 8 | B19: ='INPUT DATA'!B19:C19 -> GONZALES, JAMES A. | F19: 80 | J19: 78 | N19: 85 | R19: 85 | V19: =SUM(F19,J19,N19,R19)/4 -> 82 | Z19: =IF(V19>=75,"PASSED","FAILED") -> PASSED
A20: 9 | B20: ='INPUT DATA'!B20:D20 -> LAGUNA, J.B. B. | D20: 0 | F20: 85 | J20: 88 | N20: 80 | R20: 94 | V20: =SUM(F20,J20,N20,R20)/4 -> 86.75 | Z20: =IF(V20>=75,"PASSED","FAILED") -> PASSED
A21: 10 | B21: ='INPUT DATA'!B21:D21 -> LARODA, STEVEN S. | F21: 75 | J21: 79 | N21: 82 | R21: 85 | V21: =SUM(F21,J21,N21,R21)/4 -> 80.25 | Z21: =IF(V21>=75,"PASSED","FAILED") -> PASSED
A22: 11 | B22: ='INPUT DATA'!B22:D22 -> MERINO, SEDRIK R. | F22: 74 | J22: 75 | N22: 74 | R22: 78 | V22: =SUM(F22,J22,N22,R22)/4 -> 75.25 | Z22: =IF(V22>=75,"PASSED","FAILED") -> PASSED
A23: 12 | B23: ='INPUT DATA'!B23:D23 -> MONTERAS, VINCENT S. | D23: 0 | F23: 85 | J23: 77 | N23: 76 | R23: 73 | V23: =SUM(F23,J23,N23,R23)/4 -> 77.75 | Z23: =IF(V23>=75,"PASSED","FAILED") -> PASSED
A24: 13 | B24: ='INPUT DATA'!B24:D24 -> NACAWILI, ANDRIE L. | F24: 85 | J24: 85 | N24: 82 | R24: 82 | V24: =SUM(F24,J24,N24,R24)/4 -> 83.5 | Z24: =IF(V24>=75,"PASSED","FAILED") -> PASSED
A25: 14 | B25: ='INPUT DATA'!B25:D25 -> OLIVERIO, CYREL JAY G. | F25: 70 | J25: 74 | N25: 72 | R25: 65 | V25: =SUM(F25,J25,N25,R25)/4 -> 70.25 | Z25: =IF(V25>=75,"PASSED","FAILED") -> FAILED
A26: 15 | B26: ='INPUT DATA'!B26:D26 -> ORBITA,BRENN JOHN A. | F26: 84 | J26: 78 | N26: 88 | R26: 77 | V26: =SUM(F26,J26,N26,R26)/4 -> 81.75 | Z26: =IF(V26>=75,"PASSED","FAILED") -> PASSED
A27: 16 | B27: ='INPUT DATA'!B27:D27 -> PAINLO,SHERWIN V. | F27: 90 | J27: 92 | N27: 94 | R27: 95 | V27: =SUM(F27,J27,N27,R27)/4 -> 92.75 | Z27: =IF(V27>=75,"PASSED","FAILED") -> PASSED
A28: 17 | B28: ='INPUT DATA'!B28:D28 -> RAMIREZ, MATTEO JOHN DAVE D. | F28: 70 | J28: 60 | N28: 60 | R28: 60 | V28: =SUM(F28,J28,N28,R28)/4 -> 62.5 | Z28: =IF(V28>=75,"PASSED","FAILED") -> FAILED
A29: 18 | B29: ='INPUT DATA'!B29:D29 -> SIGUIRA, JASTINE B. | F29: 75 | J29: 60 | N29: 60 | R29: 60 | V29: =SUM(F29,J29,N29,R29)/4 -> 63.75 | Z29: =IF(V29>=75,"PASSED","FAILED") -> FAILED
A30: 19 | B30: ='INPUT DATA'!B30:D30 -> TAA, JHONVINZ Y. | F30: 75 | J30: 74 | N30: 73 | R30: 76 | V30: =SUM(F30,J30,N30,R30)/4 -> 74.5 | Z30: =IF(V30>=75,"PASSED","FAILED") -> FAILED
A31: 20 | B31: ='INPUT DATA'!B31:D31 -> ZOILO, JOHN LORENCE M. | F31: 84 | J31: 79 | N31: 88 | R31: 89 | V31: =SUM(F31,J31,N31,R31)/4 -> 85 | Z31: =IF(V31>=75,"PASSED","FAILED") -> PASSED
A32: 21 | B32: CABO, JEREM | F32: 81 | J32: 78 | N32: 78 | R32: 76 | V32: =SUM(F32,J32,N32,R32)/4 -> 78.25 | Z32: =IF(V32>=75,"PASSED","FAILED") -> PASSED
A33: 22 | B33: ='INPUT DATA'!B33:D33 -> 0 | V33: =SUM(F33,J33,N33,R33)/4 -> 0 | Z33: =IF(V33>=75,"PASSED","FAILED") -> FAILED
A34: 23 | B34: ='INPUT DATA'!B34:D34 -> 0 | V34: =SUM(F34,J34,N34,R34)/4 -> 0 | Z34: =IF(V34>=75,"PASSED","FAILED") -> FAILED
A35: 24 | B35: ='INPUT DATA'!B35:D35 -> 0 | V35: =SUM(F35,J35,N35,R35)/4 -> 0 | Z35: =IF(V35>=75,"PASSED","FAILED") -> FAILED
A36: 25 | B36: ='INPUT DATA'!B36:D36 -> 0 | V36: =SUM(F36,J36,N36,R36)/4 -> 0 | Z36: =IF(V36>=75,"PASSED","FAILED") -> FAILED
A37: 26 | B37: ='INPUT DATA'!B37:D37 -> 0 | V37: =SUM(F37,J37,N37,R37)/4 -> 0 | Z37: =IF(V37>=75,"PASSED","FAILED") -> FAILED
A38: 31 | B38: ='INPUT DATA'!B42:D42 -> 0 | V38: =SUM(F38,J38,N38,R38)/4 -> 0 | Z38: =IF(V38>=75,"PASSED","FAILED") -> FAILED
A39: 32 | B39: ='INPUT DATA'!B43:D43 -> 0 | V39: =SUM(F39,J39,N39,R39)/4 -> 0 | Z39: =IF(V39>=75,"PASSED","FAILED") -> FAILED
A40: 33 | B40: ='INPUT DATA'!B44:D44 -> 0 | V40: =SUM(F40,J40,N40,R40)/4 -> 0 | Z40: =IF(V40>=75,"PASSED","FAILED") -> FAILED
A41: 34 | B41: ='INPUT DATA'!B45:D45 -> 0 | Z41: =IF(V41>=75,"PASSED","FAILED") -> FAILED
A42: 35 | B42: ='INPUT DATA'!B46:D46 -> 0 | Z42: =IF(V42>=75,"PASSED","FAILED") -> FAILED
A43: 36 | B43: ='INPUT DATA'!B47:D47 -> 0 | Z43: =IF(V43>=75,"PASSED","FAILED") -> FAILED
...

Sheet ENGLISH
A1: Summary of Quarterly Grades
C5: REGION | G5: XI | L5: DIVISION | O5: Panabo City
B6: SCHOOL NAME | G6: QUEZON NATIONAL HIGH SCHOOL | S6: SCHOOL ID | W6: 316405
B7: LEARNERS' NAMES | F7: GRADE & SECTION: | K7: ='INPUT DATA'!K7 -> 8 - ARIES | S7: SCHOOL YEAR: | W7: ='INPUT DATA'!AG5 -> 2025 - 2026
F8: TEACHER: | K8: EHLA AMOR V. LIGAD | S8: SUBJECT: | W8: ENGLISH
F9: ENGLISH | J9: ENGLISH | N9: ENGLISH | R9: ENGLISH | V9: FINAL | Z9: REMARK
F10: 1st Quarter | J10: 2nd Quarter | N10: 3rd Quarter | R10: 4th Quarter | V10: GRADE
B11: MALE
A12: 1 | B12: ='INPUT DATA'!B12:D12 -> ANUBLING, REGIE C. | F12: 75 | J12: 73 | N12: 76 | R12: 81 | V12: =SUM(F12,J12,N12,R12)/4 -> 76.25 | Z12: =IF(V12>=75,"PASSED","FAILED") -> PASSED
A13: 2 | B13: ='INPUT DATA'!B13:D13 -> BANGCOY, JOHN PAUL P. | V13: =SUM(F13,J13,N13,R13)/4 -> 0 | Z13: =IF(V13>=75,"PASSED","FAILED") -> FAILED
A14: 3 | B14: ='INPUT DATA'!B14:D14 -> BARRIENTOS, JOHN PAUL M. | F14: 90 | J14: 86 | N14: 89 | R14: 90 | V14: =SUM(F14,J14,N14,R14)/4 -> 88.75 | Z14: =IF(V14>=75,"PASSED","FAILED") -> PASSED
A15: 4 | B15: ='INPUT DATA'!B15:D15 -> BRIGOLE, ROMEL | F15: 75 | V15: =SUM(F15,J15,N15,R15)/4 -> 18.75 | Z15: =IF(V15>=75,"PASSED","FAILED") -> FAILED
A16: 5 | B16: ='INPUT DATA'!B16:D16 -> BULAHAN,ROVIC L. | F16: 88 | J16: 83 | N16: 92 | R16: 92 | V16: =SUM(F16,J16,N16,R16)/4 -> 88.75 | Z16: =IF(V16>=75,"PASSED","FAILED") -> PASSED
A17: 6 | B17: ='INPUT DATA'!B17:D17 -> CIJAS, ROLIE JR. A. | F17: 84 | J17: 84 | N17: 93 | R17: 92 | V17: =SUM(F17,J17,N17,R17)/4 -> 88.25 | Z17: =IF(V17>=75,"PASSED","FAILED") -> PASSED
A18: 7 | B18: ='INPUT DATA'!B18:D18 -> GARCIA, DAVE P. | F18: 81 | J18: 81 | N18: 85 | R18: 86 | V18: =SUM(F18,J18,N18,R18)/4 -> 83.25 | Z18: =IF(V18>=75,"PASSED","FAILED") -> PASSED
A19: 8 | B19: ='INPUT DATA'!B19:D19 -> GONZALES, JAMES A. | D19: 0 | F19: 75 | J19: 80 | N19: 84 | R19: 87 | V19: =SUM(F19,J19,N19,R19)/4 -> 81.5 | Z19: =IF(V19>=75,"PASSED","FAILED") -> PASSED
A20: 9 | B20: ='INPUT DATA'!B20:D20 -> LAGUNA, J.B. B. | F20: 88 | J20: 84 | N20: 86 | R20: 88 | V20: =SUM(F20,J20,N20,R20)/4 -> 86.5 | Z20: =IF(V20>=75,"PASSED","FAILED") -> PASSED
A21: 10 | B21: ='INPUT DATA'!B21:D21 -> LARODA, STEVEN S. | F21: 75 | J21: 77 | N21: 82 | R21: 80 | V21: =SUM(F21,J21,N21,R21)/4 -> 78.5 | Z21: =IF(V21>=75,"PASSED","FAILED") -> PASSED
A22: 11 | B22: ='INPUT DATA'!B22:D22 -> MERINO, SEDRIK R. | D22: 0 | F22: 65 | J22: 73 | N22: 75 | R22: 65 | V22: =SUM(F22,J22,N22,R22)/4 -> 69.5 | Z22: =IF(V22>=75,"PASSED","FAILED") -> FAILED
A23: 12 | B23: ='INPUT DATA'!B23:D23 -> MONTERAS, VINCENT S. | F23: 81 | J23: 78 | N23: 75 | R23: 81 | V23: =SUM(F23,J23,N23,R23)/4 -> 78.75 | Z23: =IF(V23>=75,"PASSED","FAILED") -> PASSED
A24: 13 | B24: ='INPUT DATA'!B24:D24 -> NACAWILI, ANDRIE L. | F24: 80 | J24: 82 | N24: 91 | R24: 90 | V24: =SUM(F24,J24,N24,R24)/4 -> 85.75 | Z24: =IF(V24>=75,"PASSED","FAILED") -> PASSED
A25: 14 | B25: ='INPUT DATA'!B25:D25 -> OLIVERIO, CYREL JAY G. | F25: 72 | J25: 73 | N25: 76 | R25: 77 | V25: =SUM(F25,J25,N25,R25)/4 -> 74.5 | Z25: =IF(V25>=75,"PASSED","FAILED") -> FAILED
A26: 15 | B26: ='INPUT DATA'!B26:D26 -> ORBITA,BRENN JOHN A. | F26: 85 | J26: 83 | N26: 80 | R26: 81 | V26: =SUM(F26,J26,N26,R26)/4 -> 82.25 | Z26: =IF(V26>=75,"PASSED","FAILED") -> PASSED
A27: 16 | B27: ='INPUT DATA'!B27:D27 -> PAINLO,SHERWIN V. | F27: 88 | J27: 87 | N27: 91 | R27: 92 | V27: =SUM(F27,J27,N27,R27)/4 -> 89.5 | Z27: =IF(V27>=75,"PASSED","FAILED") -> PASSED
A28: 17 | B28: ='INPUT DATA'!B28:D28 -> RAMIREZ, MATTEO JOHN DAVE D. | V28: =SUM(F28,J28,N28,R28)/4 -> 0 | Z28: =IF(V28>=75,"PASSED","FAILED") -> FAILED
A29: 18 | B29: ='INPUT DATA'!B29:D29 -> SIGUIRA, JASTINE B. | V29: =SUM(F29,J29,N29,R29)/4 -> 0 | Z29: =IF(V29>=75,"PASSED","FAILED") -> FAILED
A30: 19 | B30: ='INPUT DATA'!B30:D30 -> TAA, JHONVINZ Y. | F30: 75 | J30: 75 | N30: 78 | R30: 78 | V30: =SUM(F30,J30,N30,R30)/4 -> 76.5 | Z30: =IF(V30>=75,"PASSED","FAILED") -> PASSED
A31: 20 | B31: ='INPUT DATA'!B31:D31 -> ZOILO, JOHN LORENCE M. | F31: 80 | J31: 79 | N31: 84 | R31: 83 | V31: =SUM(F31,J31,N31,R31)/4 -> 81.5 | Z31: =IF(V31>=75,"PASSED","FAILED") -> PASSED
A32: 21 | B32: CABO, JEREM | F32: 81 | J32: 80 | N32: 79 | R32: 78 | V32: =SUM(F32,J32,N32,R32)/4 -> 79.5 | Z32: =IF(V32>=75,"PASSED","FAILED") -> PASSED
A33: 22 | B33: ='INPUT DATA'!B33:D33 -> 0 | V33: =SUM(F33,J33,N33,R33)/4 -> 0 | Z33: =IF(V33>=75,"PASSED","FAILED") -> FAILED
A34: 23 | B34: ='INPUT DATA'!B34:D34 -> 0 | V34: =SUM(F34,J34,N34,R34)/4 -> 0 | Z34: =IF(V34>=75,"PASSED","FAILED") -> FAILED
A35: 24 | B35: ='INPUT DATA'!B35:D35 -> 0 | V35: =SUM(F35,J35,N35,R35)/4 -> 0 | Z35: =IF(V35>=75,"PASSED","FAILED") -> FAILED
A36: 25 | B36: ='INPUT DATA'!B36:D36 -> 0 | V36: =SUM(F36,J36,N36,R36)/4 -> 0 | Z36: =IF(V36>=75,"PASSED","FAILED") -> FAILED
A37: 26 | B37: ='INPUT DATA'!B37:D37 -> 0 | V37: =SUM(F37,J37,N37,R37)/4 -> 0 | Z37: =IF(V37>=75,"PASSED","FAILED") -> FAILED
A38: 27 | B38: ='INPUT DATA'!B38:D38 -> 0 | V38: =SUM(F38,J38,N38,R38)/4 -> 0 | Z38: =IF(V38>=75,"PASSED","FAILED") -> FAILED
A39: 28 | B39: ='INPUT DATA'!B39:D39 -> 0 | V39: =SUM(F39,J39,N39,R39)/4 -> 0 | Z39: =IF(V39>=75,"PASSED","FAILED") -> FAILED
A40: 29 | B40: ='INPUT DATA'!B40:D40 -> 0 | V40: =SUM(F40,J40,N40,R40)/4 -> 0 | Z40: =IF(V40>=75,"PASSED","FAILED") -> FAILED
A41: 30 | B41: ='INPUT DATA'!B41:D41 -> 0 | V41: =SUM(F41,J41,N41,R41)/4 -> 0 | Z41: =IF(V41>=75,"PASSED","FAILED") -> FAILED
A42: 31 | B42: ='INPUT DATA'!B42:D42 -> 0 | V42: =SUM(F42,J42,N42,R42)/4 -> 0 | Z42: =IF(V42>=75,"PASSED","FAILED") -> FAILED
A43: 32 | B43: ='INPUT DATA'!B43:D43 -> 0 | V43: =SUM(F43,J43,N43,R43)/4 -> 0 | Z43: =IF(V43>=75,"PASSED","FAILED") -> FAILED
...

Sheet MATHEMATICS
A1: Summary of Quarterly Grades
C5: REGION | G5: XI | L5: DIVISION | O5: Panabo City
B6: SCHOOL NAME | G6: QUEZON NATIONAL HIGH SCHOOL | S6: SCHOOL ID | W6: 316405
B7: LEARNERS' NAMES | F7: GRADE & SECTION: | K7: ='INPUT DATA'!K7 -> 8 - ARIES | S7: SCHOOL YEAR: | W7: ='INPUT DATA'!AG5 -> 2025 - 2026
F8: TEACHER: | K8: MARK KRISTOFFER AROCHA | S8: SUBJECT: | W8: MATHEMATICS
F9: MATHEMATICS | J9: MATHEMATICS | N9: MATHEMATICS | R9: MATHEMATICS | V9: FINAL | Z9: REMARK
F10: 1st Quarter | J10: 2nd Quarter | N10: 3rd Quarter | R10: 4th Quarter | V10: GRADE
B11: MALE
A12: 1 | B12: ='INPUT DATA'!B12:D12 -> ANUBLING, REGIE C. | F12: 77 | J12: 79 | N12: 79 | R12: 80 | V12: =SUM(F12,J12,N12,R12)/4 -> 78.75 | Z12: =IF(V12>=75,"PASSED","FAILED") -> PASSED
A13: 2 | B13: ='INPUT DATA'!B13:D13 -> BANGCOY, JOHN PAUL P. | V13: =SUM(F13,J13,N13,R13)/4 -> 0 | Z13: =IF(V13>=75,"PASSED","FAILED") -> FAILED
A14: 3 | B14: ='INPUT DATA'!B14:D14 -> BARRIENTOS, JOHN PAUL M. | F14: 86 | J14: 89 | N14: 90 | R14: 90 | V14: =SUM(F14,J14,N14,R14)/4 -> 88.75 | Z14: =IF(V14>=75,"PASSED","FAILED") -> PASSED
A15: 4 | B15: ='INPUT DATA'!B15:D15 -> BRIGOLE, ROMEL | V15: =SUM(F15,J15,N15,R15)/4 -> 0 | Z15: =IF(V15>=75,"PASSED","FAILED") -> FAILED
A16: 5 | B16: ='INPUT DATA'!B16:D16 -> BULAHAN,ROVIC L. | F16: 82 | J16: 84 | N16: 86 | R16: 87 | V16: =SUM(F16,J16,N16,R16)/4 -> 84.75 | Z16: =IF(V16>=75,"PASSED","FAILED") -> PASSED
A17: 6 | B17: ='INPUT DATA'!B17:D17 -> CIJAS, ROLIE JR. A. | F17: 89 | J17: 91 | N17: 91 | R17: 92 | V17: =SUM(F17,J17,N17,R17)/4 -> 90.75 | Z17: =IF(V17>=75,"PASSED","FAILED") -> PASSED
A18: 7 | B18: ='INPUT DATA'!B18:D18 -> GARCIA, DAVE P. | F18: 84 | J18: 85 | N18: 84 | R18: 85 | V18: =SUM(F18,J18,N18,R18)/4 -> 84.5 | Z18: =IF(V18>=75,"PASSED","FAILED") -> PASSED
A19: 8 | B19: ='INPUT DATA'!B19:D19 -> GONZALES, JAMES A. | D19: 0 | F19: 87 | J19: 90 | N19: 90 | R19: 90 | V19: =SUM(F19,J19,N19,R19)/4 -> 89.25 | Z19: =IF(V19>=75,"PASSED","FAILED") -> PASSED
A20: 9 | B20: ='INPUT DATA'!B20:D20 -> LAGUNA, J.B. B. | F20: 84 | J20: 86 | N20: 86 | R20: 87 | V20: =SUM(F20,J20,N20,R20)/4 -> 85.75 | Z20: =IF(V20>=75,"PASSED","FAILED") -> PASSED
A21: 10 | B21: ='INPUT DATA'!B21:D21 -> LARODA, STEVEN S. | F21: 77 | J21: 79 | N21: 79 | R21: 80 | V21: =SUM(F21,J21,N21,R21)/4 -> 78.75 | Z21: =IF(V21>=75,"PASSED","FAILED") -> PASSED
A22: 11 | B22: ='INPUT DATA'!B22:D22 -> MERINO, SEDRIK R. | D22: 0 | V22: =SUM(F22,J22,N22,R22)/4 -> 0 | Z22: =IF(V22>=75,"PASSED","FAILED") -> FAILED
A23: 12 | B23: ='INPUT DATA'!B23:D23 -> MONTERAS, VINCENT S. | F23: 77 | J23: 79 | N23: 79 | R23: 80 | V23: =SUM(F23,J23,N23,R23)/4 -> 78.75 | Z23: =IF(V23>=75,"PASSED","FAILED") -> PASSED
A24: 13 | B24: ='INPUT DATA'!B24:D24 -> NACAWILI, ANDRIE L. | F24: 86 | J24: 89 | N24: 89 | R24: 90 | V24: =SUM(F24,J24,N24,R24)/4 -> 88.5 | Z24: =IF(V24>=75,"PASSED","FAILED") -> PASSED
A25: 14 | B25: ='INPUT DATA'!B25:D25 -> OLIVERIO, CYREL JAY G. | F25: 70 | J25: 70 | N25: 87 | R25: 70 | V25: =SUM(F25,J25,N25,R25)/4 -> 74.25 | Z25: =IF(V25>=75,"PASSED","FAILED") -> FAILED
A26: 15 | B26: ='INPUT DATA'!B26:D26 -> ORBITA,BRENN JOHN A. | F26: 84 | J26: 86 | N26: 87 | R26: 89 | V26: =SUM(F26,J26,N26,R26)/4 -> 86.5 | Z26: =IF(V26>=75,"PASSED","FAILED") -> PASSED
A27: 16 | B27: ='INPUT DATA'!B27:D27 -> PAINLO,SHERWIN V. | F27: 89 | J27: 91 | N27: 91 | R27: 92 | V27: =SUM(F27,J27,N27,R27)/4 -> 90.75 | Z27: =IF(V27>=75,"PASSED","FAILED") -> PASSED
A28: 17 | B28: ='INPUT DATA'!B28:D28 -> RAMIREZ, MATTEO JOHN DAVE D. | V28: =SUM(F28,J28,N28,R28)/4 -> 0 | Z28: =IF(V28>=75,"PASSED","FAILED") -> FAILED
A29: 18 | B29: ='INPUT DATA'!B29:D29 -> SIGUIRA, JASTINE B. | V29: =SUM(F29,J29,N29,R29)/4 -> 0 | Z29: =IF(V29>=75,"PASSED","FAILED") -> FAILED
A30: 19 | B30: ='INPUT DATA'!B30:D30 -> TAA, JHONVINZ Y. | F30: 85 | J30: 87 | N30: 87 | R30: 87 | V30: =SUM(F30,J30,N30,R30)/4 -> 86.5 | Z30: =IF(V30>=75,"PASSED","FAILED") -> PASSED
A31: 20 | B31: ='INPUT DATA'!B31:D31 -> ZOILO, JOHN LORENCE M. | F31: 85 | J31: 87 | N31: 87 | R31: 88 | V31: =SUM(F31,J31,N31,R31)/4 -> 86.75 | Z31: =IF(V31>=75,"PASSED","FAILED") -> PASSED
A32: 21 | B32: CABO, JEREM | F32: 75 | J32: 75 | N32: 75 | R32: 88 | V32: =SUM(F32,J32,N32,R32)/4 -> 78.25 | Z32: =IF(V32>=75,"PASSED","FAILED") -> PASSED
A33: 22 | B33: ='INPUT DATA'!B33:D33 -> 0 | V33: =SUM(F33,J33,N33,R33)/4 -> 0 | Z33: =IF(V33>=75,"PASSED","FAILED") -> FAILED
A34: 23 | B34: ='INPUT DATA'!B34:D34 -> 0 | V34: =SUM(F34,J34,N34,R34)/4 -> 0 | Z34: =IF(V34>=75,"PASSED","FAILED") -> FAILED
A35: 24 | B35: ='INPUT DATA'!B35:D35 -> 0 | V35: =SUM(F35,J35,N35,R35)/4 -> 0 | Z35: =IF(V35>=75,"PASSED","FAILED") -> FAILED
A36: 25 | B36: ='INPUT DATA'!B36:D36 -> 0 | V36: =SUM(F36,J36,N36,R36)/4 -> 0 | Z36: =IF(V36>=75,"PASSED","FAILED") -> FAILED
A37: 26 | B37: ='INPUT DATA'!B37:D37 -> 0 | V37: =SUM(F37,J37,N37,R37)/4 -> 0 | Z37: =IF(V37>=75,"PASSED","FAILED") -> FAILED
A38: 27 | B38: ='INPUT DATA'!B38:D38 -> 0 | V38: =SUM(F38,J38,N38,R38)/4 -> 0 | Z38: =IF(V38>=75,"PASSED","FAILED") -> FAILED
A39: 28 | B39: ='INPUT DATA'!B39:D39 -> 0 | V39: =SUM(F39,J39,N39,R39)/4 -> 0 | Z39: =IF(V39>=75,"PASSED","FAILED") -> FAILED
A40: 29 | B40: ='INPUT DATA'!B40:D40 -> 0 | V40: =SUM(F40,J40,N40,R40)/4 -> 0 | Z40: =IF(V40>=75,"PASSED","FAILED") -> FAILED
A41: 30 | B41: ='INPUT DATA'!B41:D41 -> 0 | V41: =SUM(F41,J41,N41,R41)/4 -> 0 | Z41: =IF(V41>=75,"PASSED","FAILED") -> FAILED
A42: 31 | B42: ='INPUT DATA'!B42:D42 -> 0 | V42: =SUM(F42,J42,N42,R42)/4 -> 0 | Z42: =IF(V42>=75,"PASSED","FAILED") -> FAILED
A43: 32 | B43: ='INPUT DATA'!B43:D43 -> 0 | V43: =SUM(F43,J43,N43,R43)/4 -> 0 | Z43: =IF(V43>=75,"PASSED","FAILED") -> FAILED
...

Sheet SCIENCE
A1: Summary of Quarterly Grades
C5: REGION | G5: XI | L5: DIVISION | O5: Panabo City
B6: SCHOOL NAME | G6: QUEZON NATIONAL HIGH SCHOOL | S6: SCHOOL ID | W6: 316405
B7: LEARNERS' NAMES | F7: GRADE & SECTION: | K7: ='INPUT DATA'!K7 -> 8 - ARIES | S7: SCHOOL YEAR: | W7: ='INPUT DATA'!AG5 -> 2025 - 2026
F8: TEACHER: | K8: ARMAN LOUIE T. CAÑETE | S8: SUBJECT: | W8: SCIENCE
F9: SCIENCE | J9: SCIENCE | N9: SCIENCE | R9: SCIENCE | V9: FINAL | Z9: REMARK
F10: 1st Quarter | J10: 2nd Quarter | N10: 3rd Quarter | R10: 4th Quarter | V10: GRADE
B11: MALE
A12: 1 | B12: ='INPUT DATA'!B12:D12 -> ANUBLING, REGIE C. | F12: 79 | J12: 80 | N12: 82 | R12: 82 | V12: =SUM(F12,J12,N12,R12)/4 -> 80.75 | Z12: =IF(V12>=75,"PASSED","FAILED") -> PASSED
A13: 2 | B13: ='INPUT DATA'!B13:D13 -> BANGCOY, JOHN PAUL P. | V13: =SUM(F13,J13,N13,R13)/4 -> 0 | Z13: =IF(V13>=75,"PASSED","FAILED") -> FAILED
A14: 3 | B14: ='INPUT DATA'!B14:D14 -> BARRIENTOS, JOHN PAUL M. | F14: 90 | J14: 89 | N14: 91 | R14: 92 | V14: =SUM(F14,J14,N14,R14)/4 -> 90.5 | Z14: =IF(V14>=75,"PASSED","FAILED") -> PASSED
A15: 4 | B15: ='INPUT DATA'!B15:D15 -> BRIGOLE, ROMEL | F15: 70 | J15: 70 | N15: 70 | R15: 70 | V15: =SUM(F15,J15,N15,R15)/4 -> 70 | Z15: =IF(V15>=75,"PASSED","FAILED") -> FAILED
A16: 5 | B16: ='INPUT DATA'!B16:D16 -> BULAHAN,ROVIC L. | F16: 91 | J16: 92 | N16: 92 | R16: 93 | V16: =SUM(F16,J16,N16,R16)/4 -> 92 | Z16: =IF(V16>=75,"PASSED","FAILED") -> PASSED
A17: 6 | B17: ='INPUT DATA'!B17:D17 -> CIJAS, ROLIE JR. A. | F17: 90 | J17: 92 | N17: 92 | R17: 93 | V17: =SUM(F17,J17,N17,R17)/4 -> 91.75 | Z17: =IF(V17>=75,"PASSED","FAILED") -> PASSED
A18: 7 | B18: ='INPUT DATA'!B18:D18 -> GARCIA, DAVE P. | F18: 82 | J18: 83 | N18: 82 | R18: 83 | V18: =SUM(F18,J18,N18,R18)/4 -> 82.5 | Z18: =IF(V18>=75,"PASSED","FAILED") -> PASSED
A19: 8 | B19: ='INPUT DATA'!B19:D19 -> GONZALES, JAMES A. | D19: 0 | F19: 83 | J19: 85 | N19: 86 | R19: 87 | V19: =SUM(F19,J19,N19,R19)/4 -> 85.25 | Z19: =IF(V19>=75,"PASSED","FAILED") -> PASSED
A20: 9 | B20: ='INPUT DATA'!B20:D20 -> LAGUNA, J.B. B. | F20: 90 | J20: 89 | N20: 90 | R20: 91 | V20: =SUM(F20,J20,N20,R20)/4 -> 90 | Z20: =IF(V20>=75,"PASSED","FAILED") -> PASSED
A21: 10 | B21: ='INPUT DATA'!B21:D21 -> LARODA, STEVEN S. | F21: 84 | J21: 84 | N21: 83 | R21: 84 | V21: =SUM(F21,J21,N21,R21)/4 -> 83.75 | Z21: =IF(V21>=75,"PASSED","FAILED") -> PASSED
A22: 11 | B22: ='INPUT DATA'!B22:D22 -> MERINO, SEDRIK R. | D22: 0 | F22: 76 | J22: 76 | N22: 75 | R22: 72 | V22: =SUM(F22,J22,N22,R22)/4 -> 74.75 | Z22: =IF(V22>=75,"PASSED","FAILED") -> FAILED
A23: 12 | B23: ='INPUT DATA'!B23:D23 -> MONTERAS, VINCENT S. | F23: 85 | J23: 82 | N23: 77 | R23: 77 | V23: =SUM(F23,J23,N23,R23)/4 -> 80.25 | Z23: =IF(V23>=75,"PASSED","FAILED") -> PASSED
A24: 13 | B24: ='INPUT DATA'!B24:D24 -> NACAWILI, ANDRIE L. | F24: 90 | J24: 91 | N24: 90 | R24: 89 | V24: =SUM(F24,J24,N24,R24)/4 -> 90 | Z24: =IF(V24>=75,"PASSED","FAILED") -> PASSED
A25: 14 | B25: ='INPUT DATA'!B25:D25 -> OLIVERIO, CYREL JAY G. | F25: 73 | J25: 73 | N25: 74 | R25: 60 | V25: =SUM(F25,J25,N25,R25)/4 -> 70 | Z25: =IF(V25>=75,"PASSED","FAILED") -> FAILED
A26: 15 | B26: ='INPUT DATA'!B26:D26 -> ORBITA,BRENN JOHN A. | F26: 89 | J26: 88 | N26: 90 | R26: 91 | V26: =SUM(F26,J26,N26,R26)/4 -> 89.5 | Z26: =IF(V26>=75,"PASSED","FAILED") -> PASSED
A27: 16 | B27: ='INPUT DATA'!B27:D27 -> PAINLO,SHERWIN V. | F27: 90 | J27: 92 | N27: 91 | R27: 92 | V27: =SUM(F27,J27,N27,R27)/4 -> 91.25 | Z27: =IF(V27>=75,"PASSED","FAILED") -> PASSED
A28: 17 | B28: ='INPUT DATA'!B28:D28 -> RAMIREZ, MATTEO JOHN DAVE D. | V28: =SUM(F28,J28,N28,R28)/4 -> 0 | Z28: =IF(V28>=75,"PASSED","FAILED") -> FAILED
A29: 18 | B29: ='INPUT DATA'!B29:D29 -> SIGUIRA, JASTINE B. | V29: =SUM(F29,J29,N29,R29)/4 -> 0 | Z29: =IF(V29>=75,"PASSED","FAILED") -> FAILED
A30: 19 | B30: ='INPUT DATA'!B30:D30 -> TAA, JHONVINZ Y. | F30: 75 | J30: 75 | N30: 76 | R30: 75 | V30: =SUM(F30,J30,N30,R30)/4 -> 75.25 | Z30: =IF(V30>=75,"PASSED","FAILED") -> PASSED
A31: 20 | B31: ='INPUT DATA'!B31:D31 -> ZOILO, JOHN LORENCE M. | F31: 85 | J31: 84 | N31: 85 | R31: 86 | V31: =SUM(F31,J31,N31,R31)/4 -> 85 | Z31: =IF(V31>=75,"PASSED","FAILED") -> PASSED
A32: 21 | B32: CABO, JEREM | F32: 75 | J32: 75 | N32: 75 | R32: 80 | V32: =SUM(F32,J32,N32,R32)/4 -> 76.25 | Z32: =IF(V32>=75,"PASSED","FAILED") -> PASSED
A33: 22 | B33: ='INPUT DATA'!B33:D33 -> 0 | V33: =SUM(F33,J33,N33,R33)/4 -> 0 | Z33: =IF(V33>=75,"PASSED","FAILED") -> FAILED
A34: 23 | B34: ='INPUT DATA'!B34:D34 -> 0 | V34: =SUM(F34,J34,N34,R34)/4 -> 0 | Z34: =IF(V34>=75,"PASSED","FAILED") -> FAILED
A35: 24 | B35: ='INPUT DATA'!B35:D35 -> 0 | V35: =SUM(F35,J35,N35,R35)/4 -> 0 | Z35: =IF(V35>=75,"PASSED","FAILED") -> FAILED
A36: 25 | B36: ='INPUT DATA'!B36:D36 -> 0 | V36: =SUM(F36,J36,N36,R36)/4 -> 0 | Z36: =IF(V36>=75,"PASSED","FAILED") -> FAILED
A37: 26 | B37: ='INPUT DATA'!B37:D37 -> 0 | V37: =SUM(F37,J37,N37,R37)/4 -> 0 | Z37: =IF(V37>=75,"PASSED","FAILED") -> FAILED
A38: 27 | B38: ='INPUT DATA'!B38:D38 -> 0 | V38: =SUM(F38,J38,N38,R38)/4 -> 0 | Z38: =IF(V38>=75,"PASSED","FAILED") -> FAILED
A39: 28 | B39: ='INPUT DATA'!B39:D39 -> 0 | V39: =SUM(F39,J39,N39,R39)/4 -> 0 | Z39: =IF(V39>=75,"PASSED","FAILED") -> FAILED
A40: 29 | B40: ='INPUT DATA'!B40:D40 -> 0 | V40: =SUM(F40,J40,N40,R40)/4 -> 0 | Z40: =IF(V40>=75,"PASSED","FAILED") -> FAILED
A41: 30 | B41: ='INPUT DATA'!B41:D41 -> 0 | V41: =SUM(F41,J41,N41,R41)/4 -> 0 | Z41: =IF(V41>=75,"PASSED","FAILED") -> FAILED
A42: 31 | B42: ='INPUT DATA'!B42:D42 -> 0 | V42: =SUM(F42,J42,N42,R42)/4 -> 0 | Z42: =IF(V42>=75,"PASSED","FAILED") -> FAILED
A43: 32 | B43: ='INPUT DATA'!B43:D43 -> 0 | V43: =SUM(F43,J43,N43,R43)/4 -> 0 | Z43: =IF(V43>=75,"PASSED","FAILED") -> FAILED
...

Sheet AP
A1: Summary of Quarterly Grades
C5: REGION | G5: XI | L5: DIVISION | O5: Panabo City
B6: SCHOOL NAME | G6: QUEZON NATIONAL HIGH SCHOOL | S6: SCHOOL ID | W6: 316405
B7: LEARNERS' NAMES | F7: GRADE & SECTION: | K7: ='INPUT DATA'!K7 -> 8 - ARIES | S7: SCHOOL YEAR: | W7: ='INPUT DATA'!AG5 -> 2025 - 2026
F8: TEACHER: | K8: JAY R. COGAL | S8: SUBJECT: | W8: ARALING PANLIPUNAN
F9: AP | J9: AP | N9: AP | R9: AP | V9: FINAL | Z9: REMARK
F10: 1st Quarter | J10: 2nd Quarter | N10: 3rd Quarter | R10: 4th Quarter | V10: GRADE
B11: MALE
A12: 1 | B12: ='INPUT DATA'!B12:D12 -> ANUBLING, REGIE C. | F12: 70 | J12: 75 | N12: 77 | R12: 79 | V12: =SUM(F12,J12,N12,R12)/4 -> 75.25 | Z12: =IF(V12>=75,"PASSED","FAILED") -> PASSED
A13: 2 | B13: ='INPUT DATA'!B13:D13 -> BANGCOY, JOHN PAUL P. | V13: =SUM(F13,J13,N13,R13)/4 -> 0 | Z13: =IF(V13>=75,"PASSED","FAILED") -> FAILED
A14: 3 | B14: ='INPUT DATA'!B14:D14 -> BARRIENTOS, JOHN PAUL M. | F14: 88 | J14: 86 | N14: 87 | R14: 90 | V14: =SUM(F14,J14,N14,R14)/4 -> 87.75 | Z14: =IF(V14>=75,"PASSED","FAILED") -> PASSED
A15: 4 | B15: ='INPUT DATA'!B15:D15 -> BRIGOLE, ROMEL | V15: =SUM(F15,J15,N15,R15)/4 -> 0 | Z15: =IF(V15>=75,"PASSED","FAILED") -> FAILED
A16: 5 | B16: ='INPUT DATA'!B16:D16 -> BULAHAN,ROVIC L. | F16: 91 | J16: 87 | N16: 90 | R16: 90 | V16: =SUM(F16,J16,N16,R16)/4 -> 89.5 | Z16: =IF(V16>=75,"PASSED","FAILED") -> PASSED
A17: 6 | B17: ='INPUT DATA'!B17:D17 -> CIJAS, ROLIE JR. A. | F17: 83 | J17: 84 | N17: 87 | R17: 92 | V17: =SUM(F17,J17,N17,R17)/4 -> 86.5 | Z17: =IF(V17>=75,"PASSED","FAILED") -> PASSED
A18: 7 | B18: ='INPUT DATA'!B18:D18 -> GARCIA, DAVE P. | F18: 80 | J18: 78 | N18: 80 | R18: 85 | V18: =SUM(F18,J18,N18,R18)/4 -> 80.75 | Z18: =IF(V18>=75,"PASSED","FAILED") -> PASSED
A19: 8 | B19: ='INPUT DATA'!B19:D19 -> GONZALES, JAMES A. | D19: 0 | F19: 80 | J19: 80 | N19: 80 | R19: 79 | V19: =SUM(F19,J19,N19,R19)/4 -> 79.75 | Z19: =IF(V19>=75,"PASSED","FAILED") -> PASSED
A20: 9 | B20: ='INPUT DATA'!B20:D20 -> LAGUNA, J.B. B. | F20: 85 | J20: 85 | N20: 82 | R20: 88 | V20: =SUM(F20,J20,N20,R20)/4 -> 85 | Z20: =IF(V20>=75,"PASSED","FAILED") -> PASSED
A21: 10 | B21: ='INPUT DATA'!B21:D21 -> LARODA, STEVEN S. | F21: 71 | J21: 75 | N21: 75 | R21: 82 | V21: =SUM(F21,J21,N21,R21)/4 -> 75.75 | Z21: =IF(V21>=75,"PASSED","FAILED") -> PASSED
A22: 11 | B22: ='INPUT DATA'!B22:D22 -> MERINO, SEDRIK R. | D22: 0 | F22: 70 | J22: 70 | N22: 75 | R22: 65 | V22: =SUM(F22,J22,N22,R22)/4 -> 70 | Z22: =IF(V22>=75,"PASSED","FAILED") -> FAILED
A23: 12 | B23: ='INPUT DATA'!B23:D23 -> MONTERAS, VINCENT S. | F23: 79 | J23: 77 | N23: 79 | R23: 76 | V23: =SUM(F23,J23,N23,R23)/4 -> 77.75 | Z23: =IF(V23>=75,"PASSED","FAILED") -> PASSED
A24: 13 | B24: ='INPUT DATA'!B24:D24 -> NACAWILI, ANDRIE L. | F24: 80 | J24: 86 | N24: 83 | R24: 82 | V24: =SUM(F24,J24,N24,R24)/4 -> 82.75 | Z24: =IF(V24>=75,"PASSED","FAILED") -> PASSED
A25: 14 | B25: ='INPUT DATA'!B25:D25 -> OLIVERIO, CYREL JAY G. | F25: 70 | J25: 75 | N25: 70 | R25: 65 | V25: =SUM(F25,J25,N25,R25)/4 -> 70 | Z25: =IF(V25>=75,"PASSED","FAILED") -> FAILED
A26: 15 | B26: ='INPUT DATA'!B26:D26 -> ORBITA,BRENN JOHN A. | F26: 88 | J26: 84 | N26: 84 | R26: 80 | V26: =SUM(F26,J26,N26,R26)/4 -> 84 | Z26: =IF(V26>=75,"PASSED","FAILED") -> PASSED
A27: 16 | B27: ='INPUT DATA'!B27:D27 -> PAINLO,SHERWIN V. | F27: 88 | J27: 91 | N27: 90 | R27: 92 | V27: =SUM(F27,J27,N27,R27)/4 -> 90.25 | Z27: =IF(V27>=75,"PASSED","FAILED") -> PASSED
A28: 17 | B28: ='INPUT DATA'!B28:D28 -> RAMIREZ, MATTEO JOHN DAVE D. | V28: =SUM(F28,J28,N28,R28)/4 -> 0 | Z28: =IF(V28>=75,"PASSED","FAILED") -> FAILED
A29: 18 | B29: ='INPUT DATA'!B29:D29 -> SIGUIRA, JASTINE B. | V29: =SUM(F29,J29,N29,R29)/4 -> 0 | Z29: =IF(V29>=75,"PASSED","FAILED") -> FAILED
A30: 19 | B30: ='INPUT DATA'!B30:D30 -> TAA, JHONVINZ Y. | F30: 71 | J30: 76 | N30: 76 | R30: 80 | V30: =SUM(F30,J30,N30,R30)/4 -> 75.75 | Z30: =IF(V30>=75,"PASSED","FAILED") -> PASSED
A31: 20 | B31: ='INPUT DATA'!B31:D31 -> ZOILO, JOHN LORENCE M. | F31: 81 | J31: 79 | N31: 79 | R31: 76 | V31: =SUM(F31,J31,N31,R31)/4 -> 78.75 | Z31: =IF(V31>=75,"PASSED","FAILED") -> PASSED
A32: 21 | B32: CABO, JEREM | F32: 77 | J32: 77 | N32: 78 | R32: 76 | V32: =SUM(F32,J32,N32,R32)/4 -> 77 | Z32: =IF(V32>=75,"PASSED","FAILED") -> PASSED
A33: 22 | B33: ='INPUT DATA'!B33:D33 -> 0 | V33: =SUM(F33,J33,N33,R33)/4 -> 0 | Z33: =IF(V33>=75,"PASSED","FAILED") -> FAILED
A34: 23 | B34: ='INPUT DATA'!B34:D34 -> 0 | V34: =SUM(F34,J34,N34,R34)/4 -> 0 | Z34: =IF(V34>=75,"PASSED","FAILED") -> FAILED
A35: 24 | B35: ='INPUT DATA'!B35:D35 -> 0 | V35: =SUM(F35,J35,N35,R35)/4 -> 0 | Z35: =IF(V35>=75,"PASSED","FAILED") -> FAILED
A36: 25 | B36: ='INPUT DATA'!B36:D36 -> 0 | V36: =SUM(F36,J36,N36,R36)/4 -> 0 | Z36: =IF(V36>=75,"PASSED","FAILED") -> FAILED
A37: 26 | B37: ='INPUT DATA'!B37:D37 -> 0 | V37: =SUM(F37,J37,N37,R37)/4 -> 0 | Z37: =IF(V37>=75,"PASSED","FAILED") -> FAILED
A38: 27 | B38: ='INPUT DATA'!B38:D38 -> 0 | V38: =SUM(F38,J38,N38,R38)/4 -> 0 | Z38: =IF(V38>=75,"PASSED","FAILED") -> FAILED
A39: 28 | B39: ='INPUT DATA'!B39:D39 -> 0 | V39: =SUM(F39,J39,N39,R39)/4 -> 0 | Z39: =IF(V39>=75,"PASSED","FAILED") -> FAILED
A40: 29 | B40: ='INPUT DATA'!B40:D40 -> 0 | V40: =SUM(F40,J40,N40,R40)/4 -> 0 | Z40: =IF(V40>=75,"PASSED","FAILED") -> FAILED
A41: 30 | B41: ='INPUT DATA'!B41:D41 -> 0 | V41: =SUM(F41,J41,N41,R41)/4 -> 0 | Z41: =IF(V41>=75,"PASSED","FAILED") -> FAILED
A42: 31 | B42: ='INPUT DATA'!B42:D42 -> 0 | V42: =SUM(F42,J42,N42,R42)/4 -> 0 | Z42: =IF(V42>=75,"PASSED","FAILED") -> FAILED
A43: 32 | B43: ='INPUT DATA'!B43:D43 -> 0 | V43: =SUM(F43,J43,N43,R43)/4 -> 0 | Z43: =IF(V43>=75,"PASSED","FAILED") -> FAILED
...

Sheet VALED
A1: Summary of Quarterly Grades
C5: REGION | G5: XI | L5: DIVISION | O5: Panabo City
B6: SCHOOL NAME | G6: QUEZON NATIONAL HIGH SCHOOL | S6: SCHOOL ID | W6: 316405
B7: LEARNERS' NAMES | F7: GRADE & SECTION: | K7: ='INPUT DATA'!K7 -> 8 - ARIES | S7: SCHOOL YEAR: | W7: ='INPUT DATA'!AG5 -> 2025 - 2026
F8: TEACHER: | K8: NOEMI TIMBAL | S8: SUBJECT: | W8: EDUKASYON SA PAGPAPAKATAO
F9: ESP | J9: ESP | N9: ESP | R9: ESP | V9: FINAL | Z9: REMARK
F10: 1st Quarter | J10: 2nd Quarter | N10: 3rd Quarter | R10: 4th Quarter | V10: GRADE
B11: MALE
A12: 1 | B12: ='INPUT DATA'!B12:D12 -> ANUBLING, REGIE C. | F12: 80 | J12: 80 | N12: 80 | R12: 80 | V12: =SUM(F12,J12,N12,R12)/4 -> 80 | Z12: =IF(V12>=75,"PASSED","FAILED") -> PASSED
A13: 2 | B13: ='INPUT DATA'!B13:D13 -> BANGCOY, JOHN PAUL P. | F13: 70 | J13: 70 | N13: 70 | R13: 70 | V13: =SUM(F13,J13,N13,R13)/4 -> 70 | Z13: =IF(V13>=75,"PASSED","FAILED") -> FAILED
A14: 3 | B14: ='INPUT DATA'!B14:D14 -> BARRIENTOS, JOHN PAUL M. | F14: 85 | J14: 88 | N14: 92 | R14: 95 | V14: =SUM(F14,J14,N14,R14)/4 -> 90 | Z14: =IF(V14>=75,"PASSED","FAILED") -> PASSED
A15: 4 | B15: ='INPUT DATA'!B15:D15 -> BRIGOLE, ROMEL | F15: 70 | J15: 70 | N15: 70 | R15: 70 | V15: =SUM(F15,J15,N15,R15)/4 -> 70 | Z15: =IF(V15>=75,"PASSED","FAILED") -> FAILED
A16: 5 | B16: ='INPUT DATA'!B16:D16 -> BULAHAN,ROVIC L. | F16: 80 | J16: 87 | N16: 90 | R16: 91 | V16: =SUM(F16,J16,N16,R16)/4 -> 87 | Z16: =IF(V16>=75,"PASSED","FAILED") -> PASSED
A17: 6 | B17: ='INPUT DATA'!B17:D17 -> CIJAS, ROLIE JR. A. | F17: 81 | J17: 87 | N17: 91 | R17: 92 | V17: =SUM(F17,J17,N17,R17)/4 -> 87.75 | Z17: =IF(V17>=75,"PASSED","FAILED") -> PASSED
A18: 7 | B18: ='INPUT DATA'!B18:D18 -> GARCIA, DAVE P. | F18: 78 | J18: 83 | N18: 82 | R18: 84 | V18: =SUM(F18,J18,N18,R18)/4 -> 81.75 | Z18: =IF(V18>=75,"PASSED","FAILED") -> PASSED
A19: 8 | B19: ='INPUT DATA'!B19:D19 -> GONZALES, JAMES A. | D19: 0 | F19: 80 | J19: 81 | N19: 83 | R19: 84 | V19: =SUM(F19,J19,N19,R19)/4 -> 82 | Z19: =IF(V19>=75,"PASSED","FAILED") -> PASSED
A20: 9 | B20: ='INPUT DATA'!B20:D20 -> LAGUNA, J.B. B. | F20: 83 | J20: 87 | N20: 88 | R20: 92 | V20: =SUM(F20,J20,N20,R20)/4 -> 87.5 | Z20: =IF(V20>=75,"PASSED","FAILED") -> PASSED
A21: 10 | B21: ='INPUT DATA'!B21:D21 -> LARODA, STEVEN S. | F21: 80 | J21: 81 | N21: 80 | R21: 82 | V21: =SUM(F21,J21,N21,R21)/4 -> 80.75 | Z21: =IF(V21>=75,"PASSED","FAILED") -> PASSED
A22: 11 | B22: ='INPUT DATA'!B22:D22 -> MERINO, SEDRIK R. | D22: 0 | F22: 80 | J22: 70 | N22: 70 | R22: 60 | V22: =SUM(F22,J22,N22,R22)/4 -> 70 | Z22: =IF(V22>=75,"PASSED","FAILED") -> FAILED
A23: 12 | B23: ='INPUT DATA'!B23:D23 -> MONTERAS, VINCENT S. | F23: 80 | J23: 80 | N23: 80 | R23: 82 | V23: =SUM(F23,J23,N23,R23)/4 -> 80.5 | Z23: =IF(V23>=75,"PASSED","FAILED") -> PASSED
A24: 13 | B24: ='INPUT DATA'!B24:D24 -> NACAWILI, ANDRIE L. | F24: 81 | J24: 88 | N24: 89 | R24: 91 | V24: =SUM(F24,J24,N24,R24)/4 -> 87.25 | Z24: =IF(V24>=75,"PASSED","FAILED") -> PASSED
A25: 14 | B25: ='INPUT DATA'!B25:D25 -> OLIVERIO, CYREL JAY G. | F25: 79 | J25: 65 | N25: 65 | R25: 70 | V25: =SUM(F25,J25,N25,R25)/4 -> 69.75 | Z25: =IF(V25>=75,"PASSED","FAILED") -> FAILED
A26: 15 | B26: ='INPUT DATA'!B26:D26 -> ORBITA,BRENN JOHN A. | F26: 80 | J26: 81 | N26: 80 | R26: 83 | V26: =SUM(F26,J26,N26,R26)/4 -> 81 | Z26: =IF(V26>=75,"PASSED","FAILED") -> PASSED
A27: 16 | B27: ='INPUT DATA'!B27:D27 -> PAINLO,SHERWIN V. | F27: 83 | J27: 89 | N27: 89 | R27: 91 | V27: =SUM(F27,J27,N27,R27)/4 -> 88 | Z27: =IF(V27>=75,"PASSED","FAILED") -> PASSED
A28: 17 | B28: ='INPUT DATA'!B28:D28 -> RAMIREZ, MATTEO JOHN DAVE D. | F28: 78 | V28: =SUM(F28,J28,N28,R28)/4 -> 19.5 | Z28: =IF(V28>=75,"PASSED","FAILED") -> FAILED
A29: 18 | B29: ='INPUT DATA'!B29:D29 -> SIGUIRA, JASTINE B. | F29: 78 | V29: =SUM(F29,J29,N29,R29)/4 -> 19.5 | Z29: =IF(V29>=75,"PASSED","FAILED") -> FAILED
A30: 19 | B30: ='INPUT DATA'!B30:D30 -> TAA, JHONVINZ Y. | F30: 80 | J30: 80 | N30: 80 | R30: 80 | V30: =SUM(F30,J30,N30,R30)/4 -> 80 | Z30: =IF(V30>=75,"PASSED","FAILED") -> PASSED
A31: 20 | B31: ='INPUT DATA'!B31:D31 -> ZOILO, JOHN LORENCE M. | F31: 80 | J31: 83 | N31: 81 | R31: 84 | V31: =SUM(F31,J31,N31,R31)/4 -> 82 | Z31: =IF(V31>=75,"PASSED","FAILED") -> PASSED
A32: 21 | B32: CABO, JEREM | F32: 82 | J32: 83 | N32: 82 | R32: 80 | V32: =SUM(F32,J32,N32,R32)/4 -> 81.75 | Z32: =IF(V32>=75,"PASSED","FAILED") -> PASSED
A33: 22 | B33: ='INPUT DATA'!B33:D33 -> 0 | V33: =SUM(F33,J33,N33,R33)/4 -> 0 | Z33: =IF(V33>=75,"PASSED","FAILED") -> FAILED
A34: 23 | B34: ='INPUT DATA'!B34:D34 -> 0 | V34: =SUM(F34,J34,N34,R34)/4 -> 0 | Z34: =IF(V34>=75,"PASSED","FAILED") -> FAILED
A35: 24 | B35: ='INPUT DATA'!B35:D35 -> 0 | V35: =SUM(F35,J35,N35,R35)/4 -> 0 | Z35: =IF(V35>=75,"PASSED","FAILED") -> FAILED
A36: 25 | B36: ='INPUT DATA'!B36:D36 -> 0 | V36: =SUM(F36,J36,N36,R36)/4 -> 0 | Z36: =IF(V36>=75,"PASSED","FAILED") -> FAILED
A37: 26 | B37: ='INPUT DATA'!B37:D37 -> 0 | V37: =SUM(F37,J37,N37,R37)/4 -> 0 | Z37: =IF(V37>=75,"PASSED","FAILED") -> FAILED
A38: 27 | B38: ='INPUT DATA'!B38:D38 -> 0 | V38: =SUM(F38,J38,N38,R38)/4 -> 0 | Z38: =IF(V38>=75,"PASSED","FAILED") -> FAILED
A39: 28 | B39: ='INPUT DATA'!B39:D39 -> 0 | V39: =SUM(F39,J39,N39,R39)/4 -> 0 | Z39: =IF(V39>=75,"PASSED","FAILED") -> FAILED
A40: 29 | B40: ='INPUT DATA'!B40:D40 -> 0 | V40: =SUM(F40,J40,N40,R40)/4 -> 0 | Z40: =IF(V40>=75,"PASSED","FAILED") -> FAILED
A41: 30 | B41: ='INPUT DATA'!B41:D41 -> 0 | V41: =SUM(F41,J41,N41,R41)/4 -> 0 | Z41: =IF(V41>=75,"PASSED","FAILED") -> FAILED
A42: 31 | B42: ='INPUT DATA'!B42:D42 -> 0 | V42: =SUM(F42,J42,N42,R42)/4 -> 0 | Z42: =IF(V42>=75,"PASSED","FAILED") -> FAILED
A43: 32 | B43: ='INPUT DATA'!B43:D43 -> 0 | V43: =SUM(F43,J43,N43,R43)/4 -> 0 | Z43: =IF(V43>=75,"PASSED","FAILED") -> FAILED
...

Sheet TLE
A1: Summary of Quarterly Grades
C5: REGION | G5: XI | L5: DIVISION | O5: Panabo City
B6: SCHOOL NAME | G6: QUEZON NATIONAL HIGH SCHOOL | S6: SCHOOL ID | W6: 316405
B7: LEARNERS' NAMES | F7: GRADE & SECTION: | K7: ='INPUT DATA'!K7 -> 8 - ARIES | S7: SCHOOL YEAR: | W7: ='INPUT DATA'!AG5 -> 2025 - 2026
F8: TEACHER: | K8: MARILOU B. MASAYON | S8: SUBJECT: | W8: TECHNOLOGY AND LIVELIHOOD EDUCATION
F9: TLE | J9: TLE | N9: TLE | R9: TLE | V9: FINAL | Z9: REMARK
F10: 1st Quarter | J10: 2nd Quarter | N10: 3rd Quarter | R10: 4th Quarter | V10: GRADE
B11: MALE
A12: 1 | B12: ='INPUT DATA'!B12:D12 -> ANUBLING, REGIE C. | F12: 76 | J12: 74 | N12: 73 | R12: 80 | V12: =SUM(F12,J12,N12,R12)/4 -> 75.75 | Z12: =IF(V12>=75,"PASSED","FAILED") -> PASSED
A13: 2 | B13: ='INPUT DATA'!B13:D13 -> BANGCOY, JOHN PAUL P. | V13: =SUM(F13,J13,N13,R13)/4 -> 0 | Z13: =IF(V13>=75,"PASSED","FAILED") -> FAILED
A14: 3 | B14: ='INPUT DATA'!B14:D14 -> BARRIENTOS, JOHN PAUL M. | F14: 81 | J14: 86 | N14: 90 | R14: 92 | V14: =SUM(F14,J14,N14,R14)/4 -> 87.25 | Z14: =IF(V14>=75,"PASSED","FAILED") -> PASSED
A15: 4 | B15: ='INPUT DATA'!B15:D15 -> BRIGOLE, ROMEL | F15: 70 | J15: 70 | N15: 70 | R15: 70 | V15: =SUM(F15,J15,N15,R15)/4 -> 70 | Z15: =IF(V15>=75,"PASSED","FAILED") -> FAILED
A16: 5 | B16: ='INPUT DATA'!B16:D16 -> BULAHAN,ROVIC L. | F16: 82 | J16: 86 | N16: 90 | R16: 92 | V16: =SUM(F16,J16,N16,R16)/4 -> 87.5 | Z16: =IF(V16>=75,"PASSED","FAILED") -> PASSED
A17: 6 | B17: ='INPUT DATA'!B17:D17 -> CIJAS, ROLIE JR. A. | F17: 86 | J17: 89 | N17: 90 | R17: 92 | V17: =SUM(F17,J17,N17,R17)/4 -> 89.25 | Z17: =IF(V17>=75,"PASSED","FAILED") -> PASSED
A18: 7 | B18: ='INPUT DATA'!B18:D18 -> GARCIA, DAVE P. | F18: 74 | J18: 76 | N18: 81 | R18: 81 | V18: =SUM(F18,J18,N18,R18)/4 -> 78 | Z18: =IF(V18>=75,"PASSED","FAILED") -> PASSED
A19: 8 | B19: ='INPUT DATA'!B19:D19 -> GONZALES, JAMES A. | D19: 0 | F19: 85 | J19: 86 | N19: 81 | R19: 83 | V19: =SUM(F19,J19,N19,R19)/4 -> 83.75 | Z19: =IF(V19>=75,"PASSED","FAILED") -> PASSED
A20: 9 | B20: ='INPUT DATA'!B20:D20 -> LAGUNA, J.B. B. | F20: 86 | J20: 79 | N20: 87 | R20: 85 | V20: =SUM(F20,J20,N20,R20)/4 -> 84.25 | Z20: =IF(V20>=75,"PASSED","FAILED") -> PASSED
A21: 10 | B21: ='INPUT DATA'!B21:D21 -> LARODA, STEVEN S. | F21: 76 | J21: 77 | N21: 75 | R21: 80 | V21: =SUM(F21,J21,N21,R21)/4 -> 77 | Z21: =IF(V21>=75,"PASSED","FAILED") -> PASSED
A22: 11 | B22: ='INPUT DATA'!B22:D22 -> MERINO, SEDRIK R. | D22: 0 | F22: 76 | J22: 70 | N22: 70 | R22: 70 | V22: =SUM(F22,J22,N22,R22)/4 -> 71.5 | Z22: =IF(V22>=75,"PASSED","FAILED") -> FAILED
A23: 12 | B23: ='INPUT DATA'!B23:D23 -> MONTERAS, VINCENT S. | F23: 84 | J23: 73 | N23: 76 | R23: 83 | V23: =SUM(F23,J23,N23,R23)/4 -> 79 | Z23: =IF(V23>=75,"PASSED","FAILED") -> PASSED
A24: 13 | B24: ='INPUT DATA'!B24:D24 -> NACAWILI, ANDRIE L. | F24: 76 | J24: 87 | N24: 79 | R24: 85 | V24: =SUM(F24,J24,N24,R24)/4 -> 81.75 | Z24: =IF(V24>=75,"PASSED","FAILED") -> PASSED
A25: 14 | B25: ='INPUT DATA'!B25:D25 -> OLIVERIO, CYREL JAY G. | F25: 70 | J25: 70 | N25: 70 | R25: 70 | V25: =SUM(F25,J25,N25,R25)/4 -> 70 | Z25: =IF(V25>=75,"PASSED","FAILED") -> FAILED
A26: 15 | B26: ='INPUT DATA'!B26:D26 -> ORBITA,BRENN JOHN A. | F26: 76 | J26: 82 | N26: 81 | R26: 85 | V26: =SUM(F26,J26,N26,R26)/4 -> 81 | Z26: =IF(V26>=75,"PASSED","FAILED") -> PASSED
A27: 16 | B27: ='INPUT DATA'!B27:D27 -> PAINLO,SHERWIN V. | F27: 84 | J27: 89 | N27: 89 | R27: 92 | V27: =SUM(F27,J27,N27,R27)/4 -> 88.5 | Z27: =IF(V27>=75,"PASSED","FAILED") -> PASSED
A28: 17 | B28: ='INPUT DATA'!B28:D28 -> RAMIREZ, MATTEO JOHN DAVE D. | V28: =SUM(F28,J28,N28,R28)/4 -> 0 | Z28: =IF(V28>=75,"PASSED","FAILED") -> FAILED
A29: 18 | B29: ='INPUT DATA'!B29:D29 -> SIGUIRA, JASTINE B. | V29: =SUM(F29,J29,N29,R29)/4 -> 0 | Z29: =IF(V29>=75,"PASSED","FAILED") -> FAILED
A30: 19 | B30: ='INPUT DATA'!B30:D30 -> TAA, JHONVINZ Y. | F30: 76 | J30: 73 | N30: 75 | R30: 78 | V30: =SUM(F30,J30,N30,R30)/4 -> 75.5 | Z30: =IF(V30>=75,"PASSED","FAILED") -> PASSED
A31: 20 | B31: ='INPUT DATA'!B31:D31 -> ZOILO, JOHN LORENCE M. | F31: 79 | J31: 80 | N31: 82 | R31: 85 | V31: =SUM(F31,J31,N31,R31)/4 -> 81.5 | Z31: =IF(V31>=75,"PASSED","FAILED") -> PASSED
A32: 21 | B32: CABO, JEREM | F32: 77 | J32: 75 | N32: 75 | R32: 78 | V32: =SUM(F32,J32,N32,R32)/4 -> 76.25 | Z32: =IF(V32>=75,"PASSED","FAILED") -> PASSED
A33: 22 | B33: ='INPUT DATA'!B33:D33 -> 0 | V33: =SUM(F33,J33,N33,R33)/4 -> 0 | Z33: =IF(V33>=75,"PASSED","FAILED") -> FAILED
A34: 23 | B34: ='INPUT DATA'!B34:D34 -> 0 | V34: =SUM(F34,J34,N34,R34)/4 -> 0 | Z34: =IF(V34>=75,"PASSED","FAILED") -> FAILED
A35: 24 | B35: ='INPUT DATA'!B35:D35 -> 0 | V35: =SUM(F35,J35,N35,R35)/4 -> 0 | Z35: =IF(V35>=75,"PASSED","FAILED") -> FAILED
A36: 25 | B36: ='INPUT DATA'!B36:D36 -> 0 | V36: =SUM(F36,J36,N36,R36)/4 -> 0 | Z36: =IF(V36>=75,"PASSED","FAILED") -> FAILED
A37: 26 | B37: ='INPUT DATA'!B37:D37 -> 0 | V37: =SUM(F37,J37,N37,R37)/4 -> 0 | Z37: =IF(V37>=75,"PASSED","FAILED") -> FAILED
A38: 27 | B38: ='INPUT DATA'!B38:D38 -> 0 | V38: =SUM(F38,J38,N38,R38)/4 -> 0 | Z38: =IF(V38>=75,"PASSED","FAILED") -> FAILED
A39: 28 | B39: ='INPUT DATA'!B39:D39 -> 0 | V39: =SUM(F39,J39,N39,R39)/4 -> 0 | Z39: =IF(V39>=75,"PASSED","FAILED") -> FAILED
A40: 29 | B40: ='INPUT DATA'!B40:D40 -> 0 | V40: =SUM(F40,J40,N40,R40)/4 -> 0 | Z40: =IF(V40>=75,"PASSED","FAILED") -> FAILED
A41: 30 | B41: ='INPUT DATA'!B41:D41 -> 0 | V41: =SUM(F41,J41,N41,R41)/4 -> 0 | Z41: =IF(V41>=75,"PASSED","FAILED") -> FAILED
A42: 31 | B42: ='INPUT DATA'!B42:D42 -> 0 | V42: =SUM(F42,J42,N42,R42)/4 -> 0 | Z42: =IF(V42>=75,"PASSED","FAILED") -> FAILED
A43: 32 | B43: ='INPUT DATA'!B43:D43 -> 0 | V43: =SUM(F43,J43,N43,R43)/4 -> 0 | Z43: =IF(V43>=75,"PASSED","FAILED") -> FAILED
...

Sheet MUSIC-ARTS
A1: Summary of Quarterly Grades
C5: REGION | G5: XI | L5: DIVISION | O5: PANABO CITY
B6: SCHOOL NAME | G6: QUEZON NATIONAL HIGH SCHOOL | S6: SCHOOL ID | W6: 316405
B7: LEARNERS' NAMES | F7: GRADE & SECTION: | K7: ='INPUT DATA'!K7 -> 8 - ARIES | S7: SCHOOL YEAR: | W7: ='INPUT DATA'!AG5 -> 2025 - 2026
F8: TEACHER: | K8: JUVELYN MATUTIS | S8: SUBJECT: | W8: MUSIC AND ARTS
F9: MUSIC AND ARTS | J9: MUSIC AND ARTS | N9: MUSIC AND ARTS | R9: MUSIC AND ARTS | V9: MUSIC AND ARTS
F10: 1st Quarter | J10: 2nd Quarter | N10: 3rd Quarter | R10: 4th Quarter | V10: FINAL GRADE
B11: MALE
A12: 1 | B12: ='INPUT DATA'!B12:D12 -> ANUBLING, REGIE C. | F12: 81 | J12: 75 | N12: 76 | R12: 80 | V12: =IF(OR(F12="",J12="",N12="",R12="",),"",IF(ISERROR(ROUND(AVERAGE(F12,J12,N12,R12),0)),"",ROUND(AVERAGE(F12,J12,N12,R12),0))) -> 78
A13: 2 | B13: ='INPUT DATA'!B13:D13 -> BANGCOY, JOHN PAUL P. | F13: 76 | V13: =IF(OR(F13="",J13="",N13="",R13="",),"",IF(ISERROR(ROUND(AVERAGE(F13,J13,N13,R13),0)),"",ROUND(AVERAGE(F13,J13,N13,R13),0)))
A14: 3 | B14: ='INPUT DATA'!B14:D14 -> BARRIENTOS, JOHN PAUL M. | F14: 84 | J14: 85 | N14: 88 | R14: 87 | V14: =IF(OR(F14="",J14="",N14="",R14="",),"",IF(ISERROR(ROUND(AVERAGE(F14,J14,N14,R14),0)),"",ROUND(AVERAGE(F14,J14,N14,R14),0))) -> 86
A15: 4 | B15: ='INPUT DATA'!B15:D15 -> BRIGOLE, ROMEL | F15: 65 | J15: 65 | N15: 65 | R15: 70 | V15: =IF(OR(F15="",J15="",N15="",R15="",),"",IF(ISERROR(ROUND(AVERAGE(F15,J15,N15,R15),0)),"",ROUND(AVERAGE(F15,J15,N15,R15),0))) -> 66
A16: 5 | B16: ='INPUT DATA'!B16:D16 -> BULAHAN,ROVIC L. | F16: 88 | J16: 86 | N16: 88 | R16: 89 | V16: =IF(OR(F16="",J16="",N16="",R16="",),"",IF(ISERROR(ROUND(AVERAGE(F16,J16,N16,R16),0)),"",ROUND(AVERAGE(F16,J16,N16,R16),0))) -> 88
A17: 6 | B17: ='INPUT DATA'!B17:D17 -> CIJAS, ROLIE JR. A. | F17: 84 | J17: 87 | N17: 89 | R17: 90 | V17: =IF(OR(F17="",J17="",N17="",R17="",),"",IF(ISERROR(ROUND(AVERAGE(F17,J17,N17,R17),0)),"",ROUND(AVERAGE(F17,J17,N17,R17),0))) -> 88
A18: 7 | B18: ='INPUT DATA'!B18:D18 -> GARCIA, DAVE P. | F18: 80 | J18: 79 | N18: 80 | R18: 82 | V18: =IF(OR(F18="",J18="",N18="",R18="",),"",IF(ISERROR(ROUND(AVERAGE(F18,J18,N18,R18),0)),"",ROUND(AVERAGE(F18,J18,N18,R18),0))) -> 80
A19: 8 | B19: ='INPUT DATA'!B19:D19 -> GONZALES, JAMES A. | D19: 0 | F19: 82 | J19: 83 | N19: 84 | R19: 83 | V19: =IF(OR(F19="",J19="",N19="",R19="",),"",IF(ISERROR(ROUND(AVERAGE(F19,J19,N19,R19),0)),"",ROUND(AVERAGE(F19,J19,N19,R19),0))) -> 83
A20: 9 | B20: ='INPUT DATA'!B20:D20 -> LAGUNA, J.B. B. | F20: 86 | J20: 84 | N20: 85 | R20: 86 | V20: =IF(OR(F20="",J20="",N20="",R20="",),"",IF(ISERROR(ROUND(AVERAGE(F20,J20,N20,R20),0)),"",ROUND(AVERAGE(F20,J20,N20,R20),0))) -> 85
A21: 10 | B21: ='INPUT DATA'!B21:D21 -> LARODA, STEVEN S. | F21: 84 | J21: 78 | N21: 79 | R21: 80 | V21: =IF(OR(F21="",J21="",N21="",R21="",),"",IF(ISERROR(ROUND(AVERAGE(F21,J21,N21,R21),0)),"",ROUND(AVERAGE(F21,J21,N21,R21),0))) -> 80
A22: 11 | B22: ='INPUT DATA'!B22:D22 -> MERINO, SEDRIK R. | D22: 0 | F22: 80 | J22: 70 | N22: 70 | R22: 70 | V22: =IF(OR(F22="",J22="",N22="",R22="",),"",IF(ISERROR(ROUND(AVERAGE(F22,J22,N22,R22),0)),"",ROUND(AVERAGE(F22,J22,N22,R22),0))) -> 73
A23: 12 | B23: ='INPUT DATA'!B23:D23 -> MONTERAS, VINCENT S. | F23: 84 | J23: 77 | N23: 80 | R23: 77 | V23: =IF(OR(F23="",J23="",N23="",R23="",),"",IF(ISERROR(ROUND(AVERAGE(F23,J23,N23,R23),0)),"",ROUND(AVERAGE(F23,J23,N23,R23),0))) -> 80
A24: 13 | B24: ='INPUT DATA'!B24:D24 -> NACAWILI, ANDRIE L. | F24: 82 | J24: 83 | N24: 85 | R24: 86 | V24: =IF(OR(F24="",J24="",N24="",R24="",),"",IF(ISERROR(ROUND(AVERAGE(F24,J24,N24,R24),0)),"",ROUND(AVERAGE(F24,J24,N24,R24),0))) -> 84
A25: 14 | B25: ='INPUT DATA'!B25:D25 -> OLIVERIO, CYREL JAY G. | F25: 77 | J25: 71 | N25: 75 | R25: 70 | V25: =IF(OR(F25="",J25="",N25="",R25="",),"",IF(ISERROR(ROUND(AVERAGE(F25,J25,N25,R25),0)),"",ROUND(AVERAGE(F25,J25,N25,R25),0))) -> 73
A26: 15 | B26: ='INPUT DATA'!B26:D26 -> ORBITA,BRENN JOHN A. | F26: 81 | J26: 80 | N26: 83 | R26: 84 | V26: =IF(OR(F26="",J26="",N26="",R26="",),"",IF(ISERROR(ROUND(AVERAGE(F26,J26,N26,R26),0)),"",ROUND(AVERAGE(F26,J26,N26,R26),0))) -> 82
A27: 16 | B27: ='INPUT DATA'!B27:D27 -> PAINLO,SHERWIN V. | F27: 88 | J27: 87 | N27: 90 | R27: 91 | V27: =IF(OR(F27="",J27="",N27="",R27="",),"",IF(ISERROR(ROUND(AVERAGE(F27,J27,N27,R27),0)),"",ROUND(AVERAGE(F27,J27,N27,R27),0))) -> 89
A28: 17 | B28: ='INPUT DATA'!B28:D28 -> RAMIREZ, MATTEO JOHN DAVE D. | F28: 73 | V28: =IF(OR(F28="",J28="",N28="",R28="",),"",IF(ISERROR(ROUND(AVERAGE(F28,J28,N28,R28),0)),"",ROUND(AVERAGE(F28,J28,N28,R28),0)))
A29: 18 | B29: ='INPUT DATA'!B29:D29 -> SIGUIRA, JASTINE B. | F29: 73 | V29: =IF(OR(F29="",J29="",N29="",R29="",),"",IF(ISERROR(ROUND(AVERAGE(F29,J29,N29,R29),0)),"",ROUND(AVERAGE(F29,J29,N29,R29),0)))
A30: 19 | B30: ='INPUT DATA'!B30:D30 -> TAA, JHONVINZ Y. | F30: 77 | J30: 75 | N30: 76 | R30: 76 | V30: =IF(OR(F30="",J30="",N30="",R30="",),"",IF(ISERROR(ROUND(AVERAGE(F30,J30,N30,R30),0)),"",ROUND(AVERAGE(F30,J30,N30,R30),0))) -> 76
A31: 20 | B31: ='INPUT DATA'!B31:D31 -> ZOILO, JOHN LORENCE M. | F31: 84 | J31: 85 | N31: 86 | R31: 87 | V31: =IF(OR(F31="",J31="",N31="",R31="",),"",IF(ISERROR(ROUND(AVERAGE(F31,J31,N31,R31),0)),"",ROUND(AVERAGE(F31,J31,N31,R31),0))) -> 86
A32: 21 | B32: CABO, JEREM | F32: 75 | J32: 75 | N32: 75 | R32: 85 | V32: =IF(OR(F32="",J32="",N32="",R32="",),"",IF(ISERROR(ROUND(AVERAGE(F32,J32,N32,R32),0)),"",ROUND(AVERAGE(F32,J32,N32,R32),0))) -> 78
A33: 22 | B33: ='INPUT DATA'!B33:D33 -> 0 | V33: =IF(OR(F33="",J33="",N33="",R33="",),"",IF(ISERROR(ROUND(AVERAGE(F33,J33,N33,R33),0)),"",ROUND(AVERAGE(F33,J33,N33,R33),0)))
A34: 23 | B34: ='INPUT DATA'!B34:D34 -> 0 | V34: =IF(OR(F34="",J34="",N34="",R34="",),"",IF(ISERROR(ROUND(AVERAGE(F34,J34,N34,R34),0)),"",ROUND(AVERAGE(F34,J34,N34,R34),0)))
A35: 24 | B35: ='INPUT DATA'!B35:D35 -> 0 | V35: =IF(OR(F35="",J35="",N35="",R35="",),"",IF(ISERROR(ROUND(AVERAGE(F35,J35,N35,R35),0)),"",ROUND(AVERAGE(F35,J35,N35,R35),0)))
A36: 25 | B36: ='INPUT DATA'!B36:D36 -> 0 | V36: =IF(OR(F36="",J36="",N36="",R36="",),"",IF(ISERROR(ROUND(AVERAGE(F36,J36,N36,R36),0)),"",ROUND(AVERAGE(F36,J36,N36,R36),0)))
A37: 26 | B37: ='INPUT DATA'!B37:D37 -> 0 | V37: =IF(OR(F37="",J37="",N37="",R37="",),"",IF(ISERROR(ROUND(AVERAGE(F37,J37,N37,R37),0)),"",ROUND(AVERAGE(F37,J37,N37,R37),0)))
A38: 27 | B38: ='INPUT DATA'!B38:D38 -> 0 | V38: =IF(OR(F38="",J38="",N38="",R38="",),"",IF(ISERROR(ROUND(AVERAGE(F38,J38,N38,R38),0)),"",ROUND(AVERAGE(F38,J38,N38,R38),0)))
A39: 28 | B39: ='INPUT DATA'!B39:D39 -> 0 | V39: =IF(OR(F39="",J39="",N39="",R39="",),"",IF(ISERROR(ROUND(AVERAGE(F39,J39,N39,R39),0)),"",ROUND(AVERAGE(F39,J39,N39,R39),0)))
A40: 29 | B40: ='INPUT DATA'!B40:D40 -> 0 | V40: =IF(OR(F40="",J40="",N40="",R40="",),"",IF(ISERROR(ROUND(AVERAGE(F40,J40,N40,R40),0)),"",ROUND(AVERAGE(F40,J40,N40,R40),0)))
A41: 30 | B41: ='INPUT DATA'!B41:D41 -> 0 | V41: =IF(OR(F41="",J41="",N41="",R41="",),"",IF(ISERROR(ROUND(AVERAGE(F41,J41,N41,R41),0)),"",ROUND(AVERAGE(F41,J41,N41,R41),0)))
A42: 31 | B42: ='INPUT DATA'!B42:D42 -> 0 | V42: =IF(OR(F42="",J42="",N42="",R42="",),"",IF(ISERROR(ROUND(AVERAGE(F42,J42,N42,R42),0)),"",ROUND(AVERAGE(F42,J42,N42,R42),0)))
A43: 32 | B43: ='INPUT DATA'!B43:D43 -> 0 | V43: =IF(OR(F43="",J43="",N43="",R43="",),"",IF(ISERROR(ROUND(AVERAGE(F43,J43,N43,R43),0)),"",ROUND(AVERAGE(F43,J43,N43,R43),0)))
...

Sheet ARTS
A1: Summary of Quarterly Grades
C5: REGION | G5: XI | L5: DIVISION | O5: PANABO CITY
B6: SCHOOL NAME | G6: QUEZON NATIONAL HIGH SCHOOL | S6: SCHOOL ID | W6: 316405
B7: LEARNERS' NAMES | F7: GRADE & SECTION: | K7: ='INPUT DATA'!K7 -> 8 - ARIES | S7: SCHOOL YEAR: | W7: ='INPUT DATA'!AG5 -> 2025 - 2026
F8: TEACHER: | K8: ='MUSIC-ARTS'!K8 -> JUVELYN MATUTIS | S8: SUBJECT: | W8: ARTS
F9: ARTS | J9: ARTS | N9: ARTS | R9: ARTS | V9: ARTS
F10: 1st Quarter | J10: 2nd Quarter | N10: 3rd Quarter | R10: 4th Quarter | V10: FINAL GRADE
B11: MALE
A12: 1 | B12: ='INPUT DATA'!B12:D12 -> ANUBLING, REGIE C. | V12: =IF(OR(F12="",J12="",N12="",R12="",),"",IF(ISERROR(ROUND(AVERAGE(F12,J12,N12,R12),0)),"",ROUND(AVERAGE(F12,J12,N12,R12),0)))
A13: 2 | B13: ='INPUT DATA'!B13:D13 -> BANGCOY, JOHN PAUL P. | V13: =IF(OR(F13="",J13="",N13="",R13="",),"",IF(ISERROR(ROUND(AVERAGE(F13,J13,N13,R13),0)),"",ROUND(AVERAGE(F13,J13,N13,R13),0)))
A14: 3 | B14: ='INPUT DATA'!B14:D14 -> BARRIENTOS, JOHN PAUL M. | V14: =IF(OR(F14="",J14="",N14="",R14="",),"",IF(ISERROR(ROUND(AVERAGE(F14,J14,N14,R14),0)),"",ROUND(AVERAGE(F14,J14,N14,R14),0)))
A15: 4 | B15: ='INPUT DATA'!B15:D15 -> BRIGOLE, ROMEL | V15: =IF(OR(F15="",J15="",N15="",R15="",),"",IF(ISERROR(ROUND(AVERAGE(F15,J15,N15,R15),0)),"",ROUND(AVERAGE(F15,J15,N15,R15),0)))
A16: 5 | B16: ='INPUT DATA'!B16:D16 -> BULAHAN,ROVIC L. | V16: =IF(OR(F16="",J16="",N16="",R16="",),"",IF(ISERROR(ROUND(AVERAGE(F16,J16,N16,R16),0)),"",ROUND(AVERAGE(F16,J16,N16,R16),0)))
A17: 6 | B17: ='INPUT DATA'!B17:D17 -> CIJAS, ROLIE JR. A. | V17: =IF(OR(F17="",J17="",N17="",R17="",),"",IF(ISERROR(ROUND(AVERAGE(F17,J17,N17,R17),0)),"",ROUND(AVERAGE(F17,J17,N17,R17),0)))
A18: 7 | B18: ='INPUT DATA'!B18:D18 -> GARCIA, DAVE P. | V18: =IF(OR(F18="",J18="",N18="",R18="",),"",IF(ISERROR(ROUND(AVERAGE(F18,J18,N18,R18),0)),"",ROUND(AVERAGE(F18,J18,N18,R18),0)))
A19: 8 | B19: ='INPUT DATA'!B19:D19 -> GONZALES, JAMES A. | D19: 0 | V19: =IF(OR(F19="",J19="",N19="",R19="",),"",IF(ISERROR(ROUND(AVERAGE(F19,J19,N19,R19),0)),"",ROUND(AVERAGE(F19,J19,N19,R19),0)))
A20: 9 | B20: ='INPUT DATA'!B20:D20 -> LAGUNA, J.B. B. | V20: =IF(OR(F20="",J20="",N20="",R20="",),"",IF(ISERROR(ROUND(AVERAGE(F20,J20,N20,R20),0)),"",ROUND(AVERAGE(F20,J20,N20,R20),0)))
A21: 10 | B21: ='INPUT DATA'!B21:D21 -> LARODA, STEVEN S. | V21: =IF(OR(F21="",J21="",N21="",R21="",),"",IF(ISERROR(ROUND(AVERAGE(F21,J21,N21,R21),0)),"",ROUND(AVERAGE(F21,J21,N21,R21),0)))
A22: 11 | B22: ='INPUT DATA'!B22:D22 -> MERINO, SEDRIK R. | D22: 0 | V22: =IF(OR(F22="",J22="",N22="",R22="",),"",IF(ISERROR(ROUND(AVERAGE(F22,J22,N22,R22),0)),"",ROUND(AVERAGE(F22,J22,N22,R22),0)))
A23: 12 | B23: ='INPUT DATA'!B23:D23 -> MONTERAS, VINCENT S. | V23: =IF(OR(F23="",J23="",N23="",R23="",),"",IF(ISERROR(ROUND(AVERAGE(F23,J23,N23,R23),0)),"",ROUND(AVERAGE(F23,J23,N23,R23),0)))
A24: 13 | B24: ='INPUT DATA'!B24:D24 -> NACAWILI, ANDRIE L. | V24: =IF(OR(F24="",J24="",N24="",R24="",),"",IF(ISERROR(ROUND(AVERAGE(F24,J24,N24,R24),0)),"",ROUND(AVERAGE(F24,J24,N24,R24),0)))
A25: 14 | B25: ='INPUT DATA'!B25:D25 -> OLIVERIO, CYREL JAY G. | V25: =IF(OR(F25="",J25="",N25="",R25="",),"",IF(ISERROR(ROUND(AVERAGE(F25,J25,N25,R25),0)),"",ROUND(AVERAGE(F25,J25,N25,R25),0)))
A26: 15 | B26: ='INPUT DATA'!B26:D26 -> ORBITA,BRENN JOHN A. | V26: =IF(OR(F26="",J26="",N26="",R26="",),"",IF(ISERROR(ROUND(AVERAGE(F26,J26,N26,R26),0)),"",ROUND(AVERAGE(F26,J26,N26,R26),0)))
A27: 16 | B27: ='INPUT DATA'!B27:D27 -> PAINLO,SHERWIN V. | V27: =IF(OR(F27="",J27="",N27="",R27="",),"",IF(ISERROR(ROUND(AVERAGE(F27,J27,N27,R27),0)),"",ROUND(AVERAGE(F27,J27,N27,R27),0)))
A28: 17 | B28: ='INPUT DATA'!B28:D28 -> RAMIREZ, MATTEO JOHN DAVE D. | V28: =IF(OR(F28="",J28="",N28="",R28="",),"",IF(ISERROR(ROUND(AVERAGE(F28,J28,N28,R28),0)),"",ROUND(AVERAGE(F28,J28,N28,R28),0)))
A29: 18 | B29: ='INPUT DATA'!B29:D29 -> SIGUIRA, JASTINE B. | V29: =IF(OR(F29="",J29="",N29="",R29="",),"",IF(ISERROR(ROUND(AVERAGE(F29,J29,N29,R29),0)),"",ROUND(AVERAGE(F29,J29,N29,R29),0)))
A30: 19 | B30: ='INPUT DATA'!B30:D30 -> TAA, JHONVINZ Y. | V30: =IF(OR(F30="",J30="",N30="",R30="",),"",IF(ISERROR(ROUND(AVERAGE(F30,J30,N30,R30),0)),"",ROUND(AVERAGE(F30,J30,N30,R30),0)))
A31: 20 | B31: ='INPUT DATA'!B31:D31 -> ZOILO, JOHN LORENCE M. | V31: =IF(OR(F31="",J31="",N31="",R31="",),"",IF(ISERROR(ROUND(AVERAGE(F31,J31,N31,R31),0)),"",ROUND(AVERAGE(F31,J31,N31,R31),0)))
A32: 21 | B32: ='INPUT DATA'!B32:D32 -> 0 | V32: =IF(OR(F32="",J32="",N32="",R32="",),"",IF(ISERROR(ROUND(AVERAGE(F32,J32,N32,R32),0)),"",ROUND(AVERAGE(F32,J32,N32,R32),0)))
A33: 22 | B33: ='INPUT DATA'!B33:D33 -> 0 | V33: =IF(OR(F33="",J33="",N33="",R33="",),"",IF(ISERROR(ROUND(AVERAGE(F33,J33,N33,R33),0)),"",ROUND(AVERAGE(F33,J33,N33,R33),0)))
A34: 23 | B34: ='INPUT DATA'!B34:D34 -> 0 | V34: =IF(OR(F34="",J34="",N34="",R34="",),"",IF(ISERROR(ROUND(AVERAGE(F34,J34,N34,R34),0)),"",ROUND(AVERAGE(F34,J34,N34,R34),0)))
... A50: 39 | B50: ='INPUT DATA'!B50:D50 -> 0 | V50: =IF(OR(F50="",J50="",N50="",R50="",),"",IF(ISERROR(ROUND(AVERAGE(F50,J50,N50,R50),0)),"",ROUND(AVERAGE(F50,J50,N50,R50),0)))
B51: FEMALE
A52: 1 | B52: ='INPUT DATA'!B53:D53 -> ANGCOY, PRINCESS NAILLE T. | V52: =IF(OR(F52="",J52="",N52="",R52="",),"",IF(ISERROR(ROUND(AVERAGE(F52,J52,N52,R52),0)),"",ROUND(AVERAGE(F52,J52,N52,R52),0)))
A53: 2 | B53: ='INPUT DATA'!B54:D54 -> BIMOS, SHEILLA KATE O. | V53: =IF(OR(F53="",J53="",N53="",R53="",),"",IF(ISERROR(ROUND(AVERAGE(F53,J53,N53,R53),0)),"",ROUND(AVERAGE(F53,J53,N53,R53),0)))
A54: 3 | B54: ='INPUT DATA'!B55:D55 -> BONGABONG, DWEYN ZHAIRA A. | V54: =IF(OR(F54="",J54="",N54="",R54="",),"",IF(ISERROR(ROUND(AVERAGE(F54,J54,N54,R54),0)),"",ROUND(AVERAGE(F54,J54,N54,R54),0)))
A55: 4 | B55: ='INPUT DATA'!B56:D56 -> CABEL, LOURENE A. | V55: =IF(OR(F55="",J55="",N55="",R55="",),"",IF(ISERROR(ROUND(AVERAGE(F55,J55,N55,R55),0)),"",ROUND(AVERAGE(F55,J55,N55,R55),0)))
A56: 5 | B56: ='INPUT DATA'!B57:D57 -> CAMIGAO, DHENISE CLARE V. | V56: =IF(OR(F56="",J56="",N56="",R56="",),"",IF(ISERROR(ROUND(AVERAGE(F56,J56,N56,R56),0)),"",ROUND(AVERAGE(F56,J56,N56,R56),0)))
A57: 6 | B57: ='INPUT DATA'!B58:D58 -> CARISMA, NATHALIA MAE M. | V57: =IF(OR(F57="",J57="",N57="",R57="",),"",IF(ISERROR(ROUND(AVERAGE(F57,J57,N57,R57),0)),"",ROUND(AVERAGE(F57,J57,N57,R57),0)))
A58: 7 | B58: ='INPUT DATA'!B59:D59 -> CLARO, REANZ P. | V58: =IF(OR(F58="",J58="",N58="",R58="",),"",IF(ISERROR(ROUND(AVERAGE(F58,J58,N58,R58),0)),"",ROUND(AVERAGE(F58,J58,N58,R58),0)))
...

Sheet PE-HEALTH
A1: Summary of Quarterly Grades
C5: REGION | G5: XI | L5: DIVISION | O5: PANABO CITY
B6: SCHOOL NAME | G6: QUEZON NATIONAL HIGH SCHOOL | S6: SCHOOL ID | W6: 316405
B7: LEARNERS' NAMES | F7: GRADE & SECTION: | K7: =ARTS!K7 -> 8 - ARIES | S7: SCHOOL YEAR: | W7: =ARTS!W7 -> 2025 - 2026
F8: TEACHER: | K8: =ARTS!K8 -> JUVELYN MATUTIS | S8: SUBJECT: | W8: PE AND HEALTH
F9: PE AND HEALTH | J9: PE AND HEALTH | N9: PE AND HEALTH | R9: PE AND HEALTH | V9: PE AND HEALTH
F10: 1st Quarter | J10: 2nd Quarter | N10: 3rd Quarter | R10: 4th Quarter | V10: FINAL GRADE
B11: MALE
A12: 1 | B12: ='INPUT DATA'!B12:D12 -> ANUBLING, REGIE C. | F12: 80 | J12: 75 | N12: 78 | R12: 90 | V12: =IF(OR(F12="",J12="",N12="",R12="",),"",IF(ISERROR(ROUND(AVERAGE(F12,J12,N12,R12),0)),"",ROUND(AVERAGE(F12,J12,N12,R12),0))) -> 81
A13: 2 | B13: ='INPUT DATA'!B13:D13 -> BANGCOY, JOHN PAUL P. | F13: 76 | V13: =IF(OR(F13="",J13="",N13="",R13="",),"",IF(ISERROR(ROUND(AVERAGE(F13,J13,N13,R13),0)),"",ROUND(AVERAGE(F13,J13,N13,R13),0)))
A14: 3 | B14: ='INPUT DATA'!B14:D14 -> BARRIENTOS, JOHN PAUL M. | F14: 91 | J14: 87 | N14: 88 | R14: 95 | V14: =IF(OR(F14="",J14="",N14="",R14="",),"",IF(ISERROR(ROUND(AVERAGE(F14,J14,N14,R14),0)),"",ROUND(AVERAGE(F14,J14,N14,R14),0))) -> 90
A15: 4 | B15: ='INPUT DATA'!B15:D15 -> BRIGOLE, ROMEL | F15: 65 | J15: 65 | N15: 65 | R15: 70 | V15: =IF(OR(F15="",J15="",N15="",R15="",),"",IF(ISERROR(ROUND(AVERAGE(F15,J15,N15,R15),0)),"",ROUND(AVERAGE(F15,J15,N15,R15),0))) -> 66
A16: 5 | B16: ='INPUT DATA'!B16:D16 -> BULAHAN,ROVIC L. | F16: 89 | J16: 87 | N16: 88 | R16: 95 | V16: =IF(OR(F16="",J16="",N16="",R16="",),"",IF(ISERROR(ROUND(AVERAGE(F16,J16,N16,R16),0)),"",ROUND(AVERAGE(F16,J16,N16,R16),0))) -> 90
A17: 6 | B17: ='INPUT DATA'!B17:D17 -> CIJAS, ROLIE JR. A. | F17: 90 | J17: 89 | N17: 90 | R17: 90 | V17: =IF(OR(F17="",J17="",N17="",R17="",),"",IF(ISERROR(ROUND(AVERAGE(F17,J17,N17,R17),0)),"",ROUND(AVERAGE(F17,J17,N17,R17),0))) -> 90
A18: 7 | B18: ='INPUT DATA'!B18:D18 -> GARCIA, DAVE P. | F18: 84 | J18: 84 | N18: 83 | R18: 90 | V18: =IF(OR(F18="",J18="",N18="",R18="",),"",IF(ISERROR(ROUND(AVERAGE(F18,J18,N18,R18),0)),"",ROUND(AVERAGE(F18,J18,N18,R18),0))) -> 85
A19: 8 | B19: ='INPUT DATA'!B19:D19 -> GONZALES, JAMES A. | D19: 0 | F19: 82 | J19: 85 | N19: 85 | R19: 90 | V19: =IF(OR(F19="",J19="",N19="",R19="",),"",IF(ISERROR(ROUND(AVERAGE(F19,J19,N19,R19),0)),"",ROUND(AVERAGE(F19,J19,N19,R19),0))) -> 86
A20: 9 | B20: ='INPUT DATA'!B20:D20 -> LAGUNA, J.B. B. | F20: 90 | J20: 87 | N20: 85 | R20: 95 | V20: =IF(OR(F20="",J20="",N20="",R20="",),"",IF(ISERROR(ROUND(AVERAGE(F20,J20,N20,R20),0)),"",ROUND(AVERAGE(F20,J20,N20,R20),0))) -> 89
A21: 10 | B21: ='INPUT DATA'!B21:D21 -> LARODA, STEVEN S. | F21: 86 | J21: 84 | N21: 80 | R21: 90 | V21: =IF(OR(F21="",J21="",N21="",R21="",),"",IF(ISERROR(ROUND(AVERAGE(F21,J21,N21,R21),0)),"",ROUND(AVERAGE(F21,J21,N21,R21),0))) -> 85
A22: 11 | B22: ='INPUT DATA'!B22:D22 -> MERINO, SEDRIK R. | D22: 0 | F22: 85 | J22: 72 | N22: 70 | R22: 70 | V22: =IF(OR(F22="",J22="",N22="",R22="",),"",IF(ISERROR(ROUND(AVERAGE(F22,J22,N22,R22),0)),"",ROUND(AVERAGE(F22,J22,N22,R22),0))) -> 74
A23: 12 | B23: ='INPUT DATA'!B23:D23 -> MONTERAS, VINCENT S. | F23: 89 | J23: 80 | N23: 80 | R23: 78 | V23: =IF(OR(F23="",J23="",N23="",R23="",),"",IF(ISERROR(ROUND(AVERAGE(F23,J23,N23,R23),0)),"",ROUND(AVERAGE(F23,J23,N23,R23),0))) -> 82
A24: 13 | B24: ='INPUT DATA'!B24:D24 -> NACAWILI, ANDRIE L. | F24: 86 | J24: 87 | N24: 87 | R24: 90 | V24: =IF(OR(F24="",J24="",N24="",R24="",),"",IF(ISERROR(ROUND(AVERAGE(F24,J24,N24,R24),0)),"",ROUND(AVERAGE(F24,J24,N24,R24),0))) -> 88
A25: 14 | B25: ='INPUT DATA'!B25:D25 -> OLIVERIO, CYREL JAY G. | F25: 79 | J25: 73 | N25: 77 | R25: 70 | V25: =IF(OR(F25="",J25="",N25="",R25="",),"",IF(ISERROR(ROUND(AVERAGE(F25,J25,N25,R25),0)),"",ROUND(AVERAGE(F25,J25,N25,R25),0))) -> 75
A26: 15 | B26: ='INPUT DATA'!B26:D26 -> ORBITA,BRENN JOHN A. | F26: 85 | J26: 85 | N26: 85 | R26: 90 | V26: =IF(OR(F26="",J26="",N26="",R26="",),"",IF(ISERROR(ROUND(AVERAGE(F26,J26,N26,R26),0)),"",ROUND(AVERAGE(F26,J26,N26,R26),0))) -> 86
A27: 16 | B27: ='INPUT DATA'!B27:D27 -> PAINLO,SHERWIN V. | F27: 93 | J27: 89 | N27: 90 | R27: 95 | V27: =IF(OR(F27="",J27="",N27="",R27="",),"",IF(ISERROR(ROUND(AVERAGE(F27,J27,N27,R27),0)),"",ROUND(AVERAGE(F27,J27,N27,R27),0))) -> 92
A28: 17 | B28: ='INPUT DATA'!B28:D28 -> RAMIREZ, MATTEO JOHN DAVE D. | F28: 60 | V28: =IF(OR(F28="",J28="",N28="",R28="",),"",IF(ISERROR(ROUND(AVERAGE(F28,J28,N28,R28),0)),"",ROUND(AVERAGE(F28,J28,N28,R28),0)))
A29: 18 | B29: ='INPUT DATA'!B29:D29 -> SIGUIRA, JASTINE B. | F29: 74 | V29: =IF(OR(F29="",J29="",N29="",R29="",),"",IF(ISERROR(ROUND(AVERAGE(F29,J29,N29,R29),0)),"",ROUND(AVERAGE(F29,J29,N29,R29),0)))
A30: 19 | B30: ='INPUT DATA'!B30:D30 -> TAA, JHONVINZ Y. | F30: 84 | J30: 77 | N30: 79 | R30: 80 | V30: =IF(OR(F30="",J30="",N30="",R30="",),"",IF(ISERROR(ROUND(AVERAGE(F30,J30,N30,R30),0)),"",ROUND(AVERAGE(F30,J30,N30,R30),0))) -> 80
