Workbook
Name TRANSMUTATION_TABLE: 'DO NOT DELETE'!$G$2:$J$42

Sheet INPUT DATA
A1: Input Data Sheet for E-Class Record
C4: REGION | G4: XI | L4: DIVISION | O4: PANABO CITY
B5: SCHOOL NAME | G5: QUEZON NATIONAL HIGH SCHOOL | T5: SCHOOL ID | X5: 316405 | AD5: SCHOOL YEAR | AG5: 2025-2026
F7: GRADE & SECTION: | K7: 8 - ARIES | Q7: TEACHER: | S7: JENIVIVE ORTEGA PUNAY | AC7: SUBJECT: | AG7: FILIPINO
B8: LEARNERS' NAMES
B11: MALE
A12: 1 | B12: ANOBLING, REGIE C.
A13: 2 | B13: BANGCOY, JOHN PAUL P.
A14: 3 | B14: BARRIENTOS, JOHN PAUL M.
A15: 4 | B15: BRIGOLE, ROMEL
A16: 5 | B16: BULAHAN,ROVIC L.
A17: 6 | B17: CIJAS, ROLIE JR. A.
A18: 7 | B18: GARCIA, DAVE P.
A19: 8 | B19: GONZALES, JAMES
A20: 9 | B20: LAGUNA, JB
A21: 10 | B21: LARODA, STEVEN S.
A22: 11 | B22: MERINO, SEDRIK R.
A23: 12 | B23: MONTERAS, VINCENT S.
... A32: 21 | B32: CABO, JEREM
A33: 22
A34: 23
A35: 24
A36: 25
A37: 26
A38: 27
A39: 28 | C39: 0 | D39: 0 | E39: 0
A40: 29 | C40: 0 | D40: 0 | E40: 0
A41: 30 | C41: 0 | D41: 0 | E41: 0
A42: 31 | C42: 0 | D42: 0 | E42: 0
A43: 32 | C43: 0 | D43: 0 | E43: 0
A44: 33 | C44: 0 | D44: 0 | E44: 0
A45: 34 | C45: 0 | D45: 0 | E45: 0
A46: 35 | C46: 0 | D46: 0 | E46: 0
A47: 36 | C47: 0 | D47: 0 | E47: 0
A48: 37 | C48: 0 | D48: 0 | E48: 0
A49: 38 | C49: 0 | D49: 0 | E49: 0
A50: 39 | C50: 0 | D50: 0 | E50: 0
... A61: 50 | C61: 0 | D61: 0 | E61: 0
B62: FEMALE
A63: 1 | B63: ANGCOY, PRINCESS NAILLE T.
...

Sheet FIL_Q1
A1: Class Record
A3: (Pursuant to Deped Order 8 series of 2015)
C4: REGION | G4: ='INPUT DATA'!G4 -> XI | L4: DIVISION | O4: ='INPUT DATA'!O4 -> PANABO CITY
B5: SCHOOL NAME | G5: ='INPUT DATA'!G5 -> QUEZON NATIONAL HIGH SCHOOL | T5: SCHOOL ID | AD5: SCHOOL YEAR | AG5: ='INPUT DATA'!AG5 -> 2025-2026
A7: FIRST QUARTER | F7: GRADE & SECTION: | K7: ='INPUT DATA'!K7 -> 8 - ARIES | Q7: TEACHER: | S7: ='INPUT DATA'!S7 -> JENIVIVE ORTEGA PUNAY | AC7: SUBJECT: | AG7: ='INPUT DATA'!AG7 -> FILIPINO
B8: LEARNERS' NAMES | F8: WRITTEN WORKS (30%) | S8: PERFORMANCE TASKS (50%) | AF8: QUARTERLY ASSESSMENT (20%) | AI8: Initial | AJ8: Quarterly
F9: 1 | G9: 2 | H9: 3 | I9: 4 | J9: 5 | K9: 6 | L9: 7 | M9: 8 | N9: 9 | O9: 10 | P9: Total | Q9: PS | R9: WS | S9: 1 | T9: 2 | U9: 3 | V9: 4 | W9: 5 | X9: 6 | Y9: 7 | Z9: 8 | AA9: 9 | AB9: 10 | AC9: Total | AD9: PS | AE9: WS | AF9: 1 | AG9: PS | AH9: WS | AI9: Grade | AJ9: Grade
B10: HIGHEST POSSIBLE SCORE | P10: =IF(COUNT($F10:$O10)=0,"",SUM($F10:$O10)) | Q10: 100 | R10: 0.3 | AC10: =IF(COUNT($S10:$AB10)=0,"",SUM($S10:$AB10)) | AD10: 100 | AE10: 0.5 | AG10: 100 | AH10: 0.2
B11: MALE
A12: 1 | B12: ='INPUT DATA'!B12 -> ANOBLING, REGIE C. | P12: =IF(COUNT($F12:$O12)=0,"",SUM($F12:$O12)) | Q12: =IF(ISERROR(IF($P12="","",ROUND(($P12/$P$10)*$Q$10,2))),"",IF($P12="","",ROUND(($P12/$P$10)*$Q$10,2))) | R12: =IF($Q12="","",ROUND($Q12*$R$10,2)) | AC12: =IF(COUNT($S12:$AB12)=0,"",SUM($S12:$AB12)) | AD12: =IF(ISERROR(IF($AC12="","",ROUND(($AC12/$AC$10)*$AD$10,2))),"",IF($AC12="","",ROUND(($AC12/$AC$10)*$AD$10,2))) | AE12: =IF($AD12="","",ROUND($AD12*$AE$10,2)) | AG12: =IF(ISERROR(IF($AF12="","",ROUND(($AF12/$AF$10)*$AG$10,2))),"",IF($AF12="","",ROUND(($AF12/$AF$10)*$AG$10,2))) | AH12: =IF($AG12="","",ROUND($AG12*$AH$10,2)) | AI12: =IF(ISERROR(IF($AF12="","",ROUND(SUM($R12,$AE12,$AH12),2))),"",IF($AF12="","",ROUND(SUM($R12,$AE12,$AH12),2))) | AJ12: =IF(ISERROR(IF($AF12="","",VLOOKUP(AI12,TRANSMUTATION_TABLE,4,TRUE))),"",IF($AF12="","",VLOOKUP(AI12,TRANSMUTATION_TABLE,4,TRUE)))
A13: 2 | B13: ='INPUT DATA'!B13 -> BANGCOY, JOHN PAUL P. | P13: =IF(COUNT($F13:$O13)=0,"",SUM($F13:$O13)) | Q13: =IF(ISERROR(IF($P13="","",ROUND(($P13/$P$10)*$Q$10,2))),"",IF($P13="","",ROUND(($P13/$P$10)*$Q$10,2))) | R13: =IF($Q13="","",ROUND($Q13*$R$10,2)) | AC13: =IF(COUNT($S13:$AB13)=0,"",SUM($S13:$AB13)) | AD13: =IF(ISERROR(IF($AC13="","",ROUND(($AC13/$AC$10)*$AD$10,2))),"",IF($AC13="","",ROUND(($AC13/$AC$10)*$AD$10,2))) | AE13: =IF($AD13="","",ROUND($AD13*$AE$10,2)) | AG13: =IF(ISERROR(IF($AF13="","",ROUND(($AF13/$AF$10)*$AG$10,2))),"",IF($AF13="","",ROUND(($AF13/$AF$10)*$AG$10,2))) | AH13: =IF($AG13="","",ROUND($AG13*$AH$10,2)) | AI13: =IF(ISERROR(IF($AF13="","",ROUND(SUM($R13,$AE13,$AH13),2))),"",IF($AF13="","",ROUND(SUM($R13,$AE13,$AH13),2))) | AJ13: =IF(ISERROR(IF($AF13="","",VLOOKUP(AI13,TRANSMUTATION_TABLE,4,TRUE))),"",IF($AF13="","",VLOOKUP(AI13,TRANSMUTATION_TABLE,4,TRUE)))
A14: 3 | B14: ='INPUT DATA'!B14 -> BARRIENTOS, JOHN PAUL M. | P14: =IF(COUNT($F14:$O14)=0,"",SUM($F14:$O14)) | Q14: =IF(ISERROR(IF($P14="","",ROUND(($P14/$P$10)*$Q$10,2))),"",IF($P14="","",ROUND(($P14/$P$10)*$Q$10,2))) | R14: =IF($Q14="","",ROUND($Q14*$R$10,2)) | AC14: =IF(COUNT($S14:$AB14)=0,"",SUM($S14:$AB14)) | AD14: =IF(ISERROR(IF($AC14="","",ROUND(($AC14/$AC$10)*$AD$10,2))),"",IF($AC14="","",ROUND(($AC14/$AC$10)*$AD$10,2))) | AE14: =IF($AD14="","",ROUND($AD14*$AE$10,2)) | AG14: =IF(ISERROR(IF($AF14="","",ROUND(($AF14/$AF$10)*$AG$10,2))),"",IF($AF14="","",ROUND(($AF14/$AF$10)*$AG$10,2))) | AH14: =IF($AG14="","",ROUND($AG14*$AH$10,2)) | AI14: =IF(ISERROR(IF($AF14="","",ROUND(SUM($R14,$AE14,$AH14),2))),"",IF($AF14="","",ROUND(SUM($R14,$AE14,$AH14),2))) | AJ14: =IF(ISERROR(IF($AF14="","",VLOOKUP(AI14,TRANSMUTATION_TABLE,4,TRUE))),"",IF($AF14="","",VLOOKUP(AI14,TRANSMUTATION_TABLE,4,TRUE)))
A15: 4 | B15: ='INPUT DATA'!B15 -> BRIGOLE, ROMEL | P15: =IF(COUNT($F15:$O15)=0,"",SUM($F15:$O15)) | Q15: =IF(ISERROR(IF($P15="","",ROUND(($P15/$P$10)*$Q$10,2))),"",IF($P15="","",ROUND(($P15/$P$10)*$Q$10,2))) | R15: =IF($Q15="","",ROUND($Q15*$R$10,2)) | AC15: =IF(COUNT($S15:$AB15)=0,"",SUM($S15:$AB15)) | AD15: =IF(ISERROR(IF($AC15="","",ROUND(($AC15/$AC$10)*$AD$10,2))),"",IF($AC15="","",ROUND(($AC15/$AC$10)*$AD$10,2))) | AE15: =IF($AD15="","",ROUND($AD15*$AE$10,2)) | AG15: =IF(ISERROR(IF($AF15="","",ROUND(($AF15/$AF$10)*$AG$10,2))),"",IF($AF15="","",ROUND(($AF15/$AF$10)*$AG$10,2))) | AH15: =IF($AG15="","",ROUND($AG15*$AH$10,2)) | AI15: =IF(ISERROR(IF($AF15="","",ROUND(SUM($R15,$AE15,$AH15),2))),"",IF($AF15="","",ROUND(SUM($R15,$AE15,$AH15),2))) | AJ15: =IF(ISERROR(IF($AF15="","",VLOOKUP(AI15,TRANSMUTATION_TABLE,4,TRUE))),"",IF($AF15="","",VLOOKUP(AI15,TRANSMUTATION_TABLE,4,TRUE)))
A16: 5 | B16: ='INPUT DATA'!B16 -> BULAHAN,ROVIC L. | P16: =IF(COUNT($F16:$O16)=0,"",SUM($F16:$O16)) | Q16: =IF(ISERROR(IF($P16="","",ROUND(($P16/$P$10)*$Q$10,2))),"",IF($P16="","",ROUND(($P16/$P$10)*$Q$10,2))) | R16: =IF($Q16="","",ROUND($Q16*$R$10,2)) | AC16: =IF(COUNT($S16:$AB16)=0,"",SUM($S16:$AB16)) | AD16: =IF(ISERROR(IF($AC16="","",ROUND(($AC16/$AC$10)*$AD$10,2))),"",IF($AC16="","",ROUND(($AC16/$AC$10)*$AD$10,2))) | AE16: =IF($AD16="","",ROUND($AD16*$AE$10,2)) | AG16: =IF(ISERROR(IF($AF16="","",ROUND(($AF16/$AF$10)*$AG$10,2))),"",IF($AF16="","",ROUND(($AF16/$AF$10)*$AG$10,2))) | AH16: =IF($AG16="","",ROUND($AG16*$AH$10,2)) | AI16: =IF(ISERROR(IF($AF16="","",ROUND(SUM($R16,$AE16,$AH16),2))),"",IF($AF16="","",ROUND(SUM($R16,$AE16,$AH16),2))) | AJ16: =IF(ISERROR(IF($AF16="","",VLOOKUP(AI16,TRANSMUTATION_TABLE,4,TRUE))),"",IF($AF16="","",VLOOKUP(AI16,TRANSMUTATION_TABLE,4,TRUE)))
A17: 6 | B17: ='INPUT DATA'!B17 -> CIJAS, ROLIE JR. A. | P17: =IF(COUNT($F17:$O17)=0,"",SUM($F17:$O17)) | Q17: =IF(ISERROR(IF($P17="","",ROUND(($P17/$P$10)*$Q$10,2))),"",IF($P17="","",ROUND(($P17/$P$10)*$Q$10,2))) | R17: =IF($Q17="","",ROUND($Q17*$R$10,2)) | AC17: =IF(COUNT($S17:$AB17)=0,"",SUM($S17:$AB17)) | AD17: =IF(ISERROR(IF($AC17="","",ROUND(($AC17/$AC$10)*$AD$10,2))),"",IF($AC17="","",ROUND(($AC17/$AC$10)*$AD$10,2))) | AE17: =IF($AD17="","",ROUND($AD17*$AE$10,2)) | AG17: =IF(ISERROR(IF($AF17="","",ROUND(($AF17/$AF$10)*$AG$10,2))),"",IF($AF17="","",ROUND(($AF17/$AF$10)*$AG$10,2))) | AH17: =IF($AG17="","",ROUND($AG17*$AH$10,2)) | AI17: =IF(ISERROR(IF($AF17="","",ROUND(SUM($R17,$AE17,$AH17),2))),"",IF($AF17="","",ROUND(SUM($R17,$AE17,$AH17),2))) | AJ17: =IF(ISERROR(IF($AF17="","",VLOOKUP(AI17,TRANSMUTATION_TABLE,4,TRUE))),"",IF($AF17="","",VLOOKUP(AI17,TRANSMUTATION_TABLE,4,TRUE)))
A18: 7 | B18: ='INPUT DATA'!B18 -> GARCIA, DAVE P. | P18: =IF(COUNT($F18:$O18)=0,"",SUM($F18:$O18)) | Q18: =IF(ISERROR(IF($P18="","",ROUND(($P18/$P$10)*$Q$10,2))),"",IF($P18="","",ROUND(($P18/$P$10)*$Q$10,2))) | R18: =IF($Q18="","",ROUND($Q18*$R$10,2)) | AC18: =IF(COUNT($S18:$AB18)=0,"",SUM($S18:$AB18)) | AD18: =IF(ISERROR(IF($AC18="","",ROUND(($AC18/$AC$10)*$AD$10,2))),"",IF($AC18="","",ROUND(($AC18/$AC$10)*$AD$10,2))) | AE18: =IF($AD18="","",ROUND($AD18*$AE$10,2)) | AG18: =IF(ISERROR(IF($AF18="","",ROUND(($AF18/$AF$10)*$AG$10,2))),"",IF($AF18="","",ROUND(($AF18/$AF$10)*$AG$10,2))) | AH18: =IF($AG18="","",ROUND($AG18*$AH$10,2)) | AI18: =IF(ISERROR(IF($AF18="","",ROUND(SUM($R18,$AE18,$AH18),2))),"",IF($AF18="","",ROUND(SUM($R18,$AE18,$AH18),2))) | AJ18: =IF(ISERROR(IF($AF18="","",VLOOKUP(AI18,TRANSMUTATION_TABLE,4,TRUE))),"",IF($AF18="","",VLOOKUP(AI18,TRANSMUTATION_TABLE,4,TRUE)))
A19: 8 | B19: ='INPUT DATA'!B19 -> GONZALES, JAMES | D19: 0 | P19: =IF(COUNT($F19:$O19)=0,"",SUM($F19:$O19)) | Q19: =IF(ISERROR(IF($P19="","",ROUND(($P19/$P$10)*$Q$10,2))),"",IF($P19="","",ROUND(($P19/$P$10)*$Q$10,2))) | R19: =IF($Q19="","",ROUND($Q19*$R$10,2)) | AC19: =IF(COUNT($S19:$AB19)=0,"",SUM($S19:$AB19)) | AD19: =IF(ISERROR(IF($AC19="","",ROUND(($AC19/$AC$10)*$AD$10,2))),"",IF($AC19="","",ROUND(($AC19/$AC$10)*$AD$10,2))) | AE19: =IF($AD19="","",ROUND($AD19*$AE$10,2)) | AG19: =IF(ISERROR(IF($AF19="","",ROUND(($AF19/$AF$10)*$AG$10,2))),"",IF($AF19="","",ROUND(($AF19/$AF$10)*$AG$10,2))) | AH19: =IF($AG19="","",ROUND($AG19*$AH$10,2)) | AI19: =IF(ISERROR(IF($AF19="","",ROUND(SUM($R19,$AE19,$AH19),2))),"",IF($AF19="","",ROUND(SUM($R19,$AE19,$AH19),2))) | AJ19: =IF(ISERROR(IF($AF19="","",VLOOKUP(AI19,TRANSMUTATION_TABLE,4,TRUE))),"",IF($AF19="","",VLOOKUP(AI19,TRANSMUTATION_TABLE,4,TRUE)))
A20: 9 | B20: ='INPUT DATA'!B20 -> LAGUNA, JB | P20: =IF(COUNT($F20:$O20)=0,"",SUM($F20:$O20)) | Q20: =IF(ISERROR(IF($P20="","",ROUND(($P20/$P$10)*$Q$10,2))),"",IF($P20="","",ROUND(($P20/$P$10)*$Q$10,2))) | R20: =IF($Q20="","",ROUND($Q20*$R$10,2)) | AC20: =IF(COUNT($S20:$AB20)=0,"",SUM($S20:$AB20)) | AD20: =IF(ISERROR(IF($AC20="","",ROUND(($AC20/$AC$10)*$AD$10,2))),"",IF($AC20="","",ROUND(($AC20/$AC$10)*$AD$10,2))) | AE20: =IF($AD20="","",ROUND($AD20*$AE$10,2)) | AG20: =IF(ISERROR(IF($AF20="","",ROUND(($AF20/$AF$10)*$AG$10,2))),"",IF($AF20="","",ROUND(($AF20/$AF$10)*$AG$10,2))) | AH20: =IF($AG20="","",ROUND($AG20*$AH$10,2)) | AI20: =IF(ISERROR(IF($AF20="","",ROUND(SUM($R20,$AE20,$AH20),2))),"",IF($AF20="","",ROUND(SUM($R20,$AE20,$AH20),2))) | AJ20: =IF(ISERROR(IF($AF20="","",VLOOKUP(AI20,TRANSMUTATION_TABLE,4,TRUE))),"",IF($AF20="","",VLOOKUP(AI20,TRANSMUTATION_TABLE,4,TRUE)))
A21: 10 | B21: ='INPUT DATA'!B21 -> LARODA, STEVEN S. | P21: =IF(COUNT($F21:$O21)=0,"",SUM($F21:$O21)) | Q21: =IF(ISERROR(IF($P21="","",ROUND(($P21/$P$10)*$Q$10,2))),"",IF($P21="","",ROUND(($P21/$P$10)*$Q$10,2))) | R21: =IF($Q21="","",ROUND($Q21*$R$10,2)) | AC21: =IF(COUNT($S21:$AB21)=0,"",SUM($S21:$AB21)) | AD21: =IF(ISERROR(IF($AC21="","",ROUND(($AC21/$AC$10)*$AD$10,2))),"",IF($AC21="","",ROUND(($AC21/$AC$10)*$AD$10,2))) | AE21: =IF($AD21="","",ROUND($AD21*$AE$10,2)) | AG21: =IF(ISERROR(IF($AF21="","",ROUND(($AF21/$AF$10)*$AG$10,2))),"",IF($AF21="","",ROUND(($AF21/$AF$10)*$AG$10,2))) | AH21: =IF($AG21="","",ROUND($AG21*$AH$10,2)) | AI21: =IF(ISERROR(IF($AF21="","",ROUND(SUM($R21,$AE21,$AH21),2))),"",IF($AF21="","",ROUND(SUM($R21,$AE21,$AH21),2))) | AJ21: =IF(ISERROR(IF($AF21="","",VLOOKUP(AI21,TRANSMUTATION_TABLE,4,TRUE))),"",IF($AF21="","",VLOOKUP(AI21,TRANSMUTATION_TABLE,4,TRUE)))
A22: 11 | B22: ='INPUT DATA'!B22 -> MERINO, SEDRIK R. | D22: 0 | P22: =IF(COUNT($F22:$O22)=0,"",SUM($F22:$O22)) | Q22: =IF(ISERROR(IF($P22="","",ROUND(($P22/$P$10)*$Q$10,2))),"",IF($P22="","",ROUND(($P22/$P$10)*$Q$10,2))) | R22: =IF($Q22="","",ROUND($Q22*$R$10,2)) | AC22: =IF(COUNT($S22:$AB22)=0,"",SUM($S22:$AB22)) | AD22: =IF(ISERROR(IF($AC22="","",ROUND(($AC22/$AC$10)*$AD$10,2))),"",IF($AC22="","",ROUND(($AC22/$AC$10)*$AD$10,2))) | AE22: =IF($AD22="","",ROUND($AD22*$AE$10,2)) | AG22: =IF(ISERROR(IF($AF22="","",ROUND(($AF22/$AF$10)*$AG$10,2))),"",IF($AF22="","",ROUND(($AF22/$AF$10)*$AG$10,2))) | AH22: =IF($AG22="","",ROUND($AG22*$AH$10,2)) | AI22: =IF(ISERROR(IF($AF22="","",ROUND(SUM($R22,$AE22,$AH22),2))),"",IF($AF22="","",ROUND(SUM($R22,$AE22,$AH22),2))) | AJ22: =IF(ISERROR(IF($AF22="","",VLOOKUP(AI22,TRANSMUTATION_TABLE,4,TRUE))),"",IF($AF22="","",VLOOKUP(AI22,TRANSMUTATION_TABLE,4,TRUE)))
A23: 12 | B23: ='INPUT DATA'!B23 -> MONTERAS, VINCENT S. | P23: =IF(COUNT($F23:$O23)=0,"",SUM($F23:$O23)) | Q23: =IF(ISERROR(IF($P23="","",ROUND(($P23/$P$10)*$Q$10,2))),"",IF($P23="","",ROUND(($P23/$P$10)*$Q$10,2))) | R23: =IF($Q23="","",ROUND($Q23*$R$10,2)) | AC23: =IF(COUNT($S23:$AB23)=0,"",SUM($S23:$AB23)) | AD23: =IF(ISERROR(IF($AC23="","",ROUND(($AC23/$AC$10)*$AD$10,2))),"",IF($AC23="","",ROUND(($AC23/$AC$10)*$AD$10,2))) | AE23: =IF($AD23="","",ROUND($AD23*$AE$10,2)) | AG23: =IF(ISERROR(IF($AF23="","",ROUND(($AF23/$AF$10)*$AG$10,2))),"",IF($AF23="","",ROUND(($AF23/$AF$10)*$AG$10,2))) | AH23: =IF($AG23="","",ROUND($AG23*$AH$10,2)) | AI23: =IF(ISERROR(IF($AF23="","",ROUND(SUM($R23,$AE23,$AH23),2))),"",IF($AF23="","",ROUND(SUM($R23,$AE23,$AH23),2))) | AJ23: =IF(ISERROR(IF($AF23="","",VLOOKUP(AI23,TRANSMUTATION_TABLE,4,TRUE))),"",IF($AF23="","",VLOOKUP(AI23,TRANSMUTATION_TABLE,4,TRUE)))
A24: 13 | B24: ='INPUT DATA'!B24 -> NACAWILI, ANDRIE L. | P24: =IF(COUNT($F24:$O24)=0,"",SUM($F24:$O24)) | Q24: =IF(ISERROR(IF($P24="","",ROUND(($P24/$P$10)*$Q$10,2))),"",IF($P24="","",ROUND(($P24/$P$10)*$Q$10,2))) | R24: =IF($Q24="","",ROUND($Q24*$R$10,2)) | AC24: =IF(COUNT($S24:$AB24)=0,"",SUM($S24:$AB24)) | AD24: =IF(ISERROR(IF($AC24="","",ROUND(($AC24/$AC$10)*$AD$10,2))),"",IF($AC24="","",ROUND(($AC24/$AC$10)*$AD$10,2))) | AE24: =IF($AD24="","",ROUND($AD24*$AE$10,2)) | AG24: =IF(ISERROR(IF($AF24="","",ROUND(($AF24/$AF$10)*$AG$10,2))),"",IF($AF24="","",ROUND(($AF24/$AF$10)*$AG$10,2))) | AH24: =IF($AG24="","",ROUND($AG24*$AH$10,2)) | AI24: =IF(ISERROR(IF($AF24="","",ROUND(SUM($R24,$AE24,$AH24),2))),"",IF($AF24="","",ROUND(SUM($R24,$AE24,$AH24),2))) | AJ24: =IF(ISERROR(IF($AF24="","",VLOOKUP(AI24,TRANSMUTATION_TABLE,4,TRUE))),"",IF($AF24="","",VLOOKUP(AI24,TRANSMUTATION_TABLE,4,TRUE)))
A25: 14 | B25: ='INPUT DATA'!B25 -> OLIVERIO, CYREL JAY G. | P25: =IF(COUNT($F25:$O25)=0,"",SUM($F25:$O25)) | Q25: =IF(ISERROR(IF($P25="","",ROUND(($P25/$P$10)*$Q$10,2))),"",IF($P25="","",ROUND(($P25/$P$10)*$Q$10,2))) | R25: =IF($Q25="","",ROUND($Q25*$R$10,2)) | AC25: =IF(COUNT($S25:$AB25)=0,"",SUM($S25:$AB25)) | AD25: =IF(ISERROR(IF($AC25="","",ROUND(($AC25/$AC$10)*$AD$10,2))),"",IF($AC25="","",ROUND(($AC25/$AC$10)*$AD$10,2))) | AE25: =IF($AD25="","",ROUND($AD25*$AE$10,2)) | AG25: =IF(ISERROR(IF($AF25="","",ROUND(($AF25/$AF$10)*$AG$10,2))),"",IF($AF25="","",ROUND(($AF25/$AF$10)*$AG$10,2))) | AH25: =IF($AG25="","",ROUND($AG25*$AH$10,2)) | AI25: =IF(ISERROR(IF($AF25="","",ROUND(SUM($R25,$AE25,$AH25),2))),"",IF($AF25="","",ROUND(SUM($R25,$AE25,$AH25),2))) | AJ25: =IF(ISERROR(IF($AF25="","",VLOOKUP(AI25,TRANSMUTATION_TABLE,4,TRUE))),"",IF($AF25="","",VLOOKUP(AI25,TRANSMUTATION_TABLE,4,TRUE)))
A26: 15 | B26: ='INPUT DATA'!B26 -> ORBITA,BRENN JOHN A. | P26: =IF(COUNT($F26:$O26)=0,"",SUM($F26:$O26)) | Q26: =IF(ISERROR(IF($P26="","",ROUND(($P26/$P$10)*$Q$10,2))),"",IF($P26="","",ROUND(($P26/$P$10)*$Q$10,2))) | R26: =IF($Q26="","",ROUND($Q26*$R$10,2)) | AC26: =IF(COUNT($S26:$AB26)=0,"",SUM($S26:$AB26)) | AD26: =IF(ISERROR(IF($AC26="","",ROUND(($AC26/$AC$10)*$AD$10,2))),"",IF($AC26="","",ROUND(($AC26/$AC$10)*$AD$10,2))) | AE26: =IF($AD26="","",ROUND($AD26*$AE$10,2)) | AG26: =IF(ISERROR(IF($AF26="","",ROUND(($AF26/$AF$10)*$AG$10,2))),"",IF($AF26="","",ROUND(($AF26/$AF$10)*$AG$10,2))) | AH26: =IF($AG26="","",ROUND($AG26*$AH$10,2)) | AI26: =IF(ISERROR(IF($AF26="","",ROUND(SUM($R26,$AE26,$AH26),2))),"",IF($AF26="","",ROUND(SUM($R26,$AE26,$AH26),2))) | AJ26: =IF(ISERROR(IF($AF26="","",VLOOKUP(AI26,TRANSMUTATION_TABLE,4,TRUE))),"",IF($AF26="","",VLOOKUP(AI26,TRANSMUTATION_TABLE,4,TRUE)))
A27: 16 | B27: ='INPUT DATA'!B27 -> PAINLO,SHERWIN V. | P27: =IF(COUNT($F27:$O27)=0,"",SUM($F27:$O27)) | Q27: =IF(ISERROR(IF($P27="","",ROUND(($P27/$P$10)*$Q$10,2))),"",IF($P27="","",ROUND(($P27/$P$10)*$Q$10,2))) | R27: =IF($Q27="","",ROUND($Q27*$R$10,2)) | AC27: =IF(COUNT($S27:$AB27)=0,"",SUM($S27:$AB27)) | AD27: =IF(ISERROR(IF($AC27="","",ROUND(($AC27/$AC$10)*$AD$10,2))),"",IF($AC27="","",ROUND(($AC27/$AC$10)*$AD$10,2))) | AE27: =IF($AD27="","",ROUND($AD27*$AE$10,2)) | AG27: =IF(ISERROR(IF($AF27="","",ROUND(($AF27/$AF$10)*$AG$10,2))),"",IF($AF27="","",ROUND(($AF27/$AF$10)*$AG$10,2))) | AH27: =IF($AG27="","",ROUND($AG27*$AH$10,2)) | AI27: =IF(ISERROR(IF($AF27="","",ROUND(SUM($R27,$AE27,$AH27),2))),"",IF($AF27="","",ROUND(SUM($R27,$AE27,$AH27),2))) | AJ27: =IF(ISERROR(IF($AF27="","",VLOOKUP(AI27,TRANSMUTATION_TABLE,4,TRUE))),"",IF($AF27="","",VLOOKUP(AI27,TRANSMUTATION_TABLE,4,TRUE)))
A28: 17 | B28: ='INPUT DATA'!B28 -> RAMIREZ, MATTEO JOHN DAVE D. | P28: =IF(COUNT($F28:$O28)=0,"",SUM($F28:$O28)) | Q28: =IF(ISERROR(IF($P28="","",ROUND(($P28/$P$10)*$Q$10,2))),"",IF($P28="","",ROUND(($P28/$P$10)*$Q$10,2))) | R28: =IF($Q28="","",ROUND($Q28*$R$10,2)) | AC28: =IF(COUNT($S28:$AB28)=0,"",SUM($S28:$AB28)) | AD28: =IF(ISERROR(IF($AC28="","",ROUND(($AC28/$AC$10)*$AD$10,2))),"",IF($AC28="","",ROUND(($AC28/$AC$10)*$AD$10,2))) | AE28: =IF($AD28="","",ROUND($AD28*$AE$10,2)) | AG28: =IF(ISERROR(IF($AF28="","",ROUND(($AF28/$AF$10)*$AG$10,2))),"",IF($AF28="","",ROUND(($AF28/$AF$10)*$AG$10,2))) | AH28: =IF($AG28="","",ROUND($AG28*$AH$10,2)) | AI28: =IF(ISERROR(IF($AF28="","",ROUND(SUM($R28,$AE28,$AH28),2))),"",IF($AF28="","",ROUND(SUM($R28,$AE28,$AH28),2))) | AJ28: =IF(ISERROR(IF($AF28="","",VLOOKUP(AI28,TRANSMUTATION_TABLE,4,TRUE))),"",IF($AF28="","",VLOOKUP(AI28,TRANSMUTATION_TABLE,4,TRUE)))
A29: 18 | B29: ='INPUT DATA'!B29 -> SIGUIRA, JASTINE B. | P29: =IF(COUNT($F29:$O29)=0,"",SUM($F29:$O29)) | Q29: =IF(ISERROR(IF($P29="","",ROUND(($P29/$P$10)*$Q$10,2))),"",IF($P29="","",ROUND(($P29/$P$10)*$Q$10,2))) | R29: =IF($Q29="","",ROUND($Q29*$R$10,2)) | AC29: =IF(COUNT($S29:$AB29)=0,"",SUM($S29:$AB29)) | AD29: =IF(ISERROR(IF($AC29="","",ROUND(($AC29/$AC$10)*$AD$10,2))),"",IF($AC29="","",ROUND(($AC29/$AC$10)*$AD$10,2))) | AE29: =IF($AD29="","",ROUND($AD29*$AE$10,2)) | AG29: =IF(ISERROR(IF($AF29="","",ROUND(($AF29/$AF$10)*$AG$10,2))),"",IF($AF29="","",ROUND(($AF29/$AF$10)*$AG$10,2))) | AH29: =IF($AG29="","",ROUND($AG29*$AH$10,2)) | AI29: =IF(ISERROR(IF($AF29="","",ROUND(SUM($R29,$AE29,$AH29),2))),"",IF($AF29="","",ROUND(SUM($R29,$AE29,$AH29),2))) | AJ29: =IF(ISERROR(IF($AF29="","",VLOOKUP(AI29,TRANSMUTATION_TABLE,4,TRUE))),"",IF($AF29="","",VLOOKUP(AI29,TRANSMUTATION_TABLE,4,TRUE)))
A30: 19 | B30: ='INPUT DATA'!B30 -> TAA, JHONVINZ Y. | P30: =IF(COUNT($F30:$O30)=0,"",SUM($F30:$O30)) | Q30: =IF(ISERROR(IF($P30="","",ROUND(($P30/$P$10)*$Q$10,2))),"",IF($P30="","",ROUND(($P30/$P$10)*$Q$10,2))) | R30: =IF($Q30="","",ROUND($Q30*$R$10,2)) | AC30: =IF(COUNT($S30:$AB30)=0,"",SUM($S30:$AB30)) | AD30: =IF(ISERROR(IF($AC30="","",ROUND(($AC30/$AC$10)*$AD$10,2))),"",IF($AC30="","",ROUND(($AC30/$AC$10)*$AD$10,2))) | AE30: =IF($AD30="","",ROUND($AD30*$AE$10,2)) | AG30: =IF(ISERROR(IF($AF30="","",ROUND(($AF30/$AF$10)*$AG$10,2))),"",IF($AF30="","",ROUND(($AF30/$AF$10)*$AG$10,2))) | AH30: =IF($AG30="","",ROUND($AG30*$AH$10,2)) | AI30: =IF(ISERROR(IF($AF30="","",ROUND(SUM($R30,$AE30,$AH30),2))),"",IF($AF30="","",ROUND(SUM($R30,$AE30,$AH30),2))) | AJ30: =IF(ISERROR(IF($AF30="","",VLOOKUP(AI30,TRANSMUTATION_TABLE,4,TRUE))),"",IF($AF30="","",VLOOKUP(AI30,TRANSMUTATION_TABLE,4,TRUE)))
A31: 20 | B31: ='INPUT DATA'!B31 -> ZOILO, JOHN LORENCE M. | P31: =IF(COUNT($F31:$O31)=0,"",SUM($F31:$O31)) | Q31: =IF(ISERROR(IF($P31="","",ROUND(($P31/$P$10)*$Q$10,2))),"",IF($P31="","",ROUND(($P31/$P$10)*$Q$10,2))) | R31: =IF($Q31="","",ROUND($Q31*$R$10,2)) | AC31: =IF(COUNT($S31:$AB31)=0,"",SUM($S31:$AB31)) | AD31: =IF(ISERROR(IF($AC31="","",ROUND(($AC31/$AC$10)*$AD$10,2))),"",IF($AC31="","",ROUND(($AC31/$AC$10)*$AD$10,2))) | AE31: =IF($AD31="","",ROUND($AD31*$AE$10,2)) | AG31: =IF(ISERROR(IF($AF31="","",ROUND(($AF31/$AF$10)*$AG$10,2))),"",IF($AF31="","",ROUND(($AF31/$AF$10)*$AG$10,2))) | AH31: =IF($AG31="","",ROUND($AG31*$AH$10,2)) | AI31: =IF(ISERROR(IF($AF31="","",ROUND(SUM($R31,$AE31,$AH31),2))),"",IF($AF31="","",ROUND(SUM($R31,$AE31,$AH31),2))) | AJ31: =IF(ISERROR(IF($AF31="","",VLOOKUP(AI31,TRANSMUTATION_TABLE,4,TRUE))),"",IF($AF31="","",VLOOKUP(AI31,TRANSMUTATION_TABLE,4,TRUE)))
A32: 21 | B32: ='INPUT DATA'!B32 -> CABO, JEREM | P32: =IF(COUNT($F32:$O32)=0,"",SUM($F32:$O32)) | Q32: =IF(ISERROR(IF($P32="","",ROUND(($P32/$P$10)*$Q$10,2))),"",IF($P32="","",ROUND(($P32/$P$10)*$Q$10,2))) | R32: =IF($Q32="","",ROUND($Q32*$R$10,2)) | AC32: =IF(COUNT($S32:$AB32)=0,"",SUM($S32:$AB32)) | AD32: =IF(ISERROR(IF($AC32="","",ROUND(($AC32/$AC$10)*$AD$10,2))),"",IF($AC32="","",ROUND(($AC32/$AC$10)*$AD$10,2))) | AE32: =IF($AD32="","",ROUND($AD32*$AE$10,2)) | AG32: =IF(ISERROR(IF($AF32="","",ROUND(($AF32/$AF$10)*$AG$10,2))),"",IF($AF32="","",ROUND(($AF32/$AF$10)*$AG$10,2))) | AH32: =IF($AG32="","",ROUND($AG32*$AH$10,2)) | AI32: =IF(ISERROR(IF($AF32="","",ROUND(SUM($R32,$AE32,$AH32),2))),"",IF($AF32="","",ROUND(SUM($R32,$AE32,$AH32),2))) | AJ32: =IF(ISERROR(IF($AF32="","",VLOOKUP(AI32,TRANSMUTATION_TABLE,4,TRUE))),"",IF($AF32="","",VLOOKUP(AI32,TRANSMUTATION_TABLE,4,TRUE)))
A33: 22 | B33: ='INPUT DATA'!B33 -> 0 | P33: =IF(COUNT($F33:$O33)=0,"",SUM($F33:$O33)) | Q33: =IF(ISERROR(IF($P33="","",ROUND(($P33/$P$10)*$Q$10,2))),"",IF($P33="","",ROUND(($P33/$P$10)*$Q$10,2))) | R33: =IF($Q33="","",ROUND($Q33*$R$10,2)) | AC33: =IF(COUNT($S33:$AB33)=0,"",SUM($S33:$AB33)) | AD33: =IF(ISERROR(IF($AC33="","",ROUND(($AC33/$AC$10)*$AD$10,2))),"",IF($AC33="","",ROUND(($AC33/$AC$10)*$AD$10,2))) | AE33: =IF($AD33="","",ROUND($AD33*$AE$10,2)) | AG33: =IF(ISERROR(IF($AF33="","",ROUND(($AF33/$AF$10)*$AG$10,2))),"",IF($AF33="","",ROUND(($AF33/$AF$10)*$AG$10,2))) | AH33: =IF($AG33="","",ROUND($AG33*$AH$10,2)) | AI33: =IF(ISERROR(IF($AF33="","",ROUND(SUM($R33,$AE33,$AH33),2))),"",IF($AF33="","",ROUND(SUM($R33,$AE33,$AH33),2))) | AJ33: =IF(ISERROR(IF($AF33="","",VLOOKUP(AI33,TRANSMUTATION_TABLE,4,TRUE))),"",IF($AF33="","",VLOOKUP(AI33,TRANSMUTATION_TABLE,4,TRUE)))
A34: 23 | B34: ='INPUT DATA'!B34 -> 0 | P34: =IF(COUNT($F34:$O34)=0,"",SUM($F34:$O34)) | Q34: =IF(ISERROR(IF($P34="","",ROUND(($P34/$P$10)*$Q$10,2))),"",IF($P34="","",ROUND(($P34/$P$10)*$Q$10,2))) | R34: =IF($Q34="","",ROUND($Q34*$R$10,2)) | AC34: =IF(COUNT($S34:$AB34)=0,"",SUM($S34:$AB34)) | AD34: =IF(ISERROR(IF($AC34="","",ROUND(($AC34/$AC$10)*$AD$10,2))),"",IF($AC34="","",ROUND(($AC34/$AC$10)*$AD$10,2))) | AE34: =IF($AD34="","",ROUND($AD34*$AE$10,2)) | AG34: =IF(ISERROR(IF($AF34="","",ROUND(($AF34/$AF$10)*$AG$10,2))),"",IF($AF34="","",ROUND(($AF34/$AF$10)*$AG$10,2))) | AH34: =IF($AG34="","",ROUND($AG34*$AH$10,2)) | AI34: =IF(ISERROR(IF($AF34="","",ROUND(SUM($R34,$AE34,$AH34),2))),"",IF($AF34="","",ROUND(SUM($R34,$AE34,$AH34),2))) | AJ34: =IF(ISERROR(IF($AF34="","",VLOOKUP(AI34,TRANSMUTATION_TABLE,4,TRUE))),"",IF($AF34="","",VLOOKUP(AI34,TRANSMUTATION_TABLE,4,TRUE)))
... A61: 50 | B61: ='INPUT DATA'!B61 -> 0 | P61: =IF(COUNT($F61:$O61)=0,"",SUM($F61:$O61)) | Q61: =IF(ISERROR(IF($P61="","",ROUND(($P61/$P$10)*$Q$10,2))),"",IF($P61="","",ROUND(($P61/$P$10)*$Q$10,2))) | R61: =IF($Q61="","",ROUND($Q61*$R$10,2)) | AC61: =IF(COUNT($S61:$AB61)=0,"",SUM($S61:$AB61)) | AD61: =IF(ISERROR(IF($AC61="","",ROUND(($AC61/$AC$10)*$AD$10,2))),"",IF($AC61="","",ROUND(($AC61/$AC$10)*$AD$10,2))) | AE61: =IF($AD61="","",ROUND($AD61*$AE$10,2)) | AG61: =IF(ISERROR(IF($AF61="","",ROUND(($AF61/$AF$10)*$AG$10,2))),"",IF($AF61="","",ROUND(($AF61/$AF$10)*$AG$10,2))) | AH61: =IF($AG61="","",ROUND($AG61*$AH$10,2)) | AI61: =IF(ISERROR(IF($AF61="","",ROUND(SUM($R61,$AE61,$AH61),2))),"",IF($AF61="","",ROUND(SUM($R61,$AE61,$AH61),2))) | AJ61: =IF(ISERROR(IF($AF61="","",VLOOKUP(AI61,TRANSMUTATION_TABLE,4,TRUE))),"",IF($AF61="","",VLOOKUP(AI61,TRANSMUTATION_TABLE,4,TRUE)))
B62: FEMALE
A63: 1 | B63: ='INPUT DATA'!B63 -> ANGCOY, PRINCESS NAILLE T. | P63: =IF(COUNT($F63:$O63)=0,"",SUM($F63:$O63)) | Q63: =IF(ISERROR(IF($P63="","",ROUND(($P63/$P$10)*$Q$10,2))),"",IF($P63="","",ROUND(($P63/$P$10)*$Q$10,2))) | R63: =IF($Q63="","",ROUND($Q63*$R$10,2)) | AC63: =IF(COUNT($S63:$AB63)=0,"",SUM($S63:$AB63)) | AD63: =IF(ISERROR(IF($AC63="","",ROUND(($AC63/$AC$10)*$AD$10,2))),"",IF($AC63="","",ROUND(($AC63/$AC$10)*$AD$10,2))) | AE63: =IF($AD63="","",ROUND($AD63*$AE$10,2)) | AG63: =IF(ISERROR(IF($AF63="","",ROUND(($AF63/$AF$10)*$AG$10,2))),"",IF($AF63="","",ROUND(($AF63/$AF$10)*$AG$10,2))) | AH63: =IF($AG63="","",ROUND($AG63*$AH$10,2)) | AI63: =IF(ISERROR(IF($AF63="","",ROUND(SUM($R63,$AE63,$AH63),2))),"",IF($AF63="","",ROUND(SUM($R63,$AE63,$AH63),2))) | AJ63: =IF(ISERROR(IF($AF63="","",VLOOKUP(AI63,TRANSMUTATION_TABLE,4,TRUE))),"",IF($AF63="","",VLOOKUP(AI63,TRANSMUTATION_TABLE,4,TRUE)))
A64: 2 | B64: ='INPUT DATA'!B64 -> BIMOS, SHEILLA KATE | P64: =IF(COUNT($F64:$O64)=0,"",SUM($F64:$O64)) | Q64: =IF(ISERROR(IF($P64="","",ROUND(($P64/$P$10)*$Q$10,2))),"",IF($P64="","",ROUND(($P64/$P$10)*$Q$10,2))) | R64: =IF($Q64="","",ROUND($Q64*$R$10,2)) | AC64: =IF(COUNT($S64:$AB64)=0,"",SUM($S64:$AB64)) | AD64: =IF(ISERROR(IF($AC64="","",ROUND(($AC64/$AC$10)*$AD$10,2))),"",IF($AC64="","",ROUND(($AC64/$AC$10)*$AD$10,2))) | AE64: =IF($AD64="","",ROUND($AD64*$AE$10,2)) | AG64: =IF(ISERROR(IF($AF64="","",ROUND(($AF64/$AF$10)*$AG$10,2))),"",IF($AF64="","",ROUND(($AF64/$AF$10)*$AG$10,2))) | AH64: =IF($AG64="","",ROUND($AG64*$AH$10,2)) | AI64: =IF(ISERROR(IF($AF64="","",ROUND(SUM($R64,$AE64,$AH64),2))),"",IF($AF64="","",ROUND(SUM($R64,$AE64,$AH64),2))) | AJ64: =IF(ISERROR(IF($AF64="","",VLOOKUP(AI64,TRANSMUTATION_TABLE,4,TRUE))),"",IF($AF64="","",VLOOKUP(AI64,TRANSMUTATION_TABLE,4,TRUE)))
A65: 3 | B65: ='INPUT DATA'!B65 -> BONGABONG, DWEYN ZAIRA A. | P65: =IF(COUNT($F65:$O65)=0,"",SUM($F65:$O65)) | Q65: =IF(ISERROR(IF($P65="","",ROUND(($P65/$P$10)*$Q$10,2))),"",IF($P65="","",ROUND(($P65/$P$10)*$Q$10,2))) | R65: =IF($Q65="","",ROUND($Q65*$R$10,2)) | AC65: =IF(COUNT($S65:$AB65)=0,"",SUM($S65:$AB65)) | AD65: =IF(ISERROR(IF($AC65="","",ROUND(($AC65/$AC$10)*$AD$10,2))),"",IF($AC65="","",ROUND(($AC65/$AC$10)*$AD$10,2))) | AE65: =IF($AD65="","",ROUND($AD65*$AE$10,2)) | AG65: =IF(ISERROR(IF($AF65="","",ROUND(($AF65/$AF$10)*$AG$10,2))),"",IF($AF65="","",ROUND(($AF65/$AF$10)*$AG$10,2))) | AH65: =IF($AG65="","",ROUND($AG65*$AH$10,2)) | AI65: =IF(ISERROR(IF($AF65="","",ROUND(SUM($R65,$AE65,$AH65),2))),"",IF($AF65="","",ROUND(SUM($R65,$AE65,$AH65),2))) | AJ65: =IF(ISERROR(IF($AF65="","",VLOOKUP(AI65,TRANSMUTATION_TABLE,4,TRUE))),"",IF($AF65="","",VLOOKUP(AI65,TRANSMUTATION_TABLE,4,TRUE)))
A66: 4 | B66: ='INPUT DATA'!B66 -> CABEL, LOURENE A. | P66: =IF(COUNT($F66:$O66)=0,"",SUM($F66:$O66)) | Q66: =IF(ISERROR(IF($P66="","",ROUND(($P66/$P$10)*$Q$10,2))),"",IF($P66="","",ROUND(($P66/$P$10)*$Q$10,2))) | R66: =IF($Q66="","",ROUND($Q66*$R$10,2)) | AC66: =IF(COUNT($S66:$AB66)=0,"",SUM($S66:$AB66)) | AD66: =IF(ISERROR(IF($AC66="","",ROUND(($AC66/$AC$10)*$AD$10,2))),"",IF($AC66="","",ROUND(($AC66/$AC$10)*$AD$10,2))) | AE66: =IF($AD66="","",ROUND($AD66*$AE$10,2)) | AG66: =IF(ISERROR(IF($AF66="","",ROUND(($AF66/$AF$10)*$AG$10,2))),"",IF($AF66="","",ROUND(($AF66/$AF$10)*$AG$10,2))) | AH66: =IF($AG66="","",ROUND($AG66*$AH$10,2)) | AI66: =IF(ISERROR(IF($AF66="","",ROUND(SUM($R66,$AE66,$AH66),2))),"",IF($AF66="","",ROUND(SUM($R66,$AE66,$AH66),2))) | AJ66: =IF(ISERROR(IF($AF66="","",VLOOKUP(AI66,TRANSMUTATION_TABLE,4,TRUE))),"",IF($AF66="","",VLOOKUP(AI66,TRANSMUTATION_TABLE,4,TRUE)))
A67: 5 | B67: ='INPUT DATA'!B67 -> CAMIGAO, DHENISE CLARE V. | P67: =IF(COUNT($F67:$O67)=0,"",SUM($F67:$O67)) | Q67: =IF(ISERROR(IF($P67="","",ROUND(($P67/$P$10)*$Q$10,2))),"",IF($P67="","",ROUND(($P67/$P$10)*$Q$10,2))) | R67: =IF($Q67="","",ROUND($Q67*$R$10,2)) | AC67: =IF(COUNT($S67:$AB67)=0,"",SUM($S67:$AB67)) | AD67: =IF(ISERROR(IF($AC67="","",ROUND(($AC67/$AC$10)*$AD$10,2))),"",IF($AC67="","",ROUND(($AC67/$AC$10)*$AD$10,2))) | AE67: =IF($AD67="","",ROUND($AD67*$AE$10,2)) | AG67: =IF(ISERROR(IF($AF67="","",ROUND(($AF67/$AF$10)*$AG$10,2))),"",IF($AF67="","",ROUND(($AF67/$AF$10)*$AG$10,2))) | AH67: =IF($AG67="","",ROUND($AG67*$AH$10,2)) | AI67: =IF(ISERROR(IF($AF67="","",ROUND(SUM($R67,$AE67,$AH67),2))),"",IF($AF67="","",ROUND(SUM($R67,$AE67,$AH67),2))) | AJ67: =IF(ISERROR(IF($AF67="","",VLOOKUP(AI67,TRANSMUTATION_TABLE,4,TRUE))),"",IF($AF67="","",VLOOKUP(AI67,TRANSMUTATION_TABLE,4,TRUE)))
A68: 6 | B68: ='INPUT DATA'!B68 -> CARISMA, NATHALIA MAE M. | P68: =IF(COUNT($F68:$O68)=0,"",SUM($F68:$O68)) | Q68: =IF(ISERROR(IF($P68="","",ROUND(($P68/$P$10)*$Q$10,2))),"",IF($P68="","",ROUND(($P68/$P$10)*$Q$10,2))) | R68: =IF($Q68="","",ROUND($Q68*$R$10,2)) | AC68: =IF(COUNT($S68:$AB68)=0,"",SUM($S68:$AB68)) | AD68: =IF(ISERROR(IF($AC68="","",ROUND(($AC68/$AC$10)*$AD$10,2))),"",IF($AC68="","",ROUND(($AC68/$AC$10)*$AD$10,2))) | AE68: =IF($AD68="","",ROUND($AD68*$AE$10,2)) | AG68: =IF(ISERROR(IF($AF68="","",ROUND(($AF68/$AF$10)*$AG$10,2))),"",IF($AF68="","",ROUND(($AF68/$AF$10)*$AG$10,2))) | AH68: =IF($AG68="","",ROUND($AG68*$AH$10,2)) | AI68: =IF(ISERROR(IF($AF68="","",ROUND(SUM($R68,$AE68,$AH68),2))),"",IF($AF68="","",ROUND(SUM($R68,$AE68,$AH68),2))) | AJ68: =IF(ISERROR(IF($AF68="","",VLOOKUP(AI68,TRANSMUTATION_TABLE,4,TRUE))),"",IF($AF68="","",VLOOKUP(AI68,TRANSMUTATION_TABLE,4,TRUE)))
...

Sheet FIL_Q2
A1: Class Record
A3: (Pursuant to Deped Order 8 series of 2015)
C4: REGION | G4: ='INPUT DATA'!G4 -> XI | L4: DIVISION | O4: ='INPUT DATA'!O4 -> PANABO CITY
B5: SCHOOL NAME | G5: ='INPUT DATA'!G5 -> QUEZON NATIONAL HIGH SCHOOL | T5: SCHOOL ID | AD5: SCHOOL YEAR | AG5: ='INPUT DATA'!AG5 -> 2025-2026
A7: SECOND QUARTER | F7: GRADE & SECTION: | K7: ='INPUT DATA'!K7 -> 8 - ARIES | Q7: TEACHER: | S7: ='INPUT DATA'!S7 -> JENIVIVE ORTEGA PUNAY | AC7: SUBJECT: | AG7: ='INPUT DATA'!AG7 -> FILIPINO
B8: LEARNERS' NAMES | F8: WRITTEN WORKS (30%) | S8: PERFORMANCE TASKS (50%) | AF8: QUARTERLY ASSESSMENT (20%) | AI8: Initial | AJ8: Quarterly
F9: 1 | G9: 2 | H9: 3 | I9: 4 | J9: 5 | K9: 6 | L9: 7 | M9: 8 | N9: 9 | O9: 10 | P9: Total | Q9: PS | R9: WS | S9: 1 | T9: 2 | U9: 3 | V9: 4 | W9: 5 | X9: 6 | Y9: 7 | Z9: 8 | AA9: 9 | AB9: 10 | AC9: Total | AD9: PS | AE9: WS | AF9: 1 | AG9: PS | AH9: WS | AI9: Grade | AJ9: Grade
B10: HIGHEST POSSIBLE SCORE | F10: 10 | G10: 10 | H10: 10 | I10: 5 | J10: 20 | K10: 10 | L10: 180 | P10: =IF(COUNT($F10:$O10)=0,"",SUM($F10:$O10)) -> 245 | Q10: 100 | R10: 0.3 | S10: 5 | T10: 40 | U10: 50 | V10: 100 | W10: 100 | X10: 20 | Y10: 100 | AC10: =IF(COUNT($S10:$AB10)=0,"",SUM($S10:$AB10)) -> 415 | AD10: 100 | AE10: 0.5 | AF10: 40 | AG10: 100 | AH10: 0.2
B11: MALE | F11: quiz | G11: report quiz | H11: quiz | I11: report quiz | J11: quiz PanAmHap | K11: talasalitaan | L11: notebook | S11: reading | T11: sanaysayeditoryal | U11: essay with Maam Rose | V11: group report | W11: group-differentiated act | X11: kaligirang pangkasaysayanPanHap | Y11: video-animation | AK11: Adj +5 | AN11: mps
A12: 1 | B12: ='INPUT DATA'!B12 -> ANOBLING, REGIE C. | F12: 3 | G12: 10 | K12: 4 | P12: =IF(COUNT($F12:$O12)=0,"",SUM($F12:$O12)) -> 17 | Q12: =IF(ISERROR(IF($P12="","",ROUND(($P12/$P$10)*$Q$10,2))),"",IF($P12="","",ROUND(($P12/$P$10)*$Q$10,2))) -> 6.94 | R12: =IF($Q12="","",ROUND($Q12*$R$10,2)) -> 2.08 | S12: 5 | U12: 43 | W12: 94 | Y12: 93 | AC12: =IF(COUNT($S12:$AB12)=0,"",SUM($S12:$AB12)) -> 235 | AD12: =IF(ISERROR(IF($AC12="","",ROUND(($AC12/$AC$10)*$AD$10,2))),"",IF($AC12="","",ROUND(($AC12/$AC$10)*$AD$10,2))) -> 56.63 | AE12: =IF($AD12="","",ROUND($AD12*$AE$10,2)) -> 28.32 | AF12: 13 | AG12: =IF(ISERROR(IF($AF12="","",ROUND(($AF12/$AF$10)*$AG$10,2))),"",IF($AF12="","",ROUND(($AF12/$AF$10)*$AG$10,2))) -> 32.5 | AH12: =IF($AG12="","",ROUND($AG12*$AH$10,2)) -> 6.5 | AI12: =IF(ISERROR(IF($AF12="","",ROUND(SUM($R12,$AE12,$AH12),2))),"",IF($AF12="","",ROUND(SUM($R12,$AE12,$AH12),2))) -> 36.9 | AJ12: =IF(ISERROR(IF($AF12="","",VLOOKUP(AI12,TRANSMUTATION_TABLE,4,TRUE))),"",IF($AF12="","",VLOOKUP(AI12,TRANSMUTATION_TABLE,4,TRUE))) -> 69 | AK12: =AJ12+5 -> 74 | AL12: 75 | AN12: =AF12+5 -> 18
A13: 2 | B13: ='INPUT DATA'!B13 -> BANGCOY, JOHN PAUL P. | P13: =IF(COUNT($F13:$O13)=0,"",SUM($F13:$O13)) | Q13: =IF(ISERROR(IF($P13="","",ROUND(($P13/$P$10)*$Q$10,2))),"",IF($P13="","",ROUND(($P13/$P$10)*$Q$10,2))) | R13: =IF($Q13="","",ROUND($Q13*$R$10,2)) | AC13: =IF(COUNT($S13:$AB13)=0,"",SUM($S13:$AB13)) | AD13: =IF(ISERROR(IF($AC13="","",ROUND(($AC13/$AC$10)*$AD$10,2))),"",IF($AC13="","",ROUND(($AC13/$AC$10)*$AD$10,2))) | AE13: =IF($AD13="","",ROUND($AD13*$AE$10,2)) | AF13: 0 | AG13: =IF(ISERROR(IF($AF13="","",ROUND(($AF13/$AF$10)*$AG$10,2))),"",IF($AF13="","",ROUND(($AF13/$AF$10)*$AG$10,2))) -> 0 | AH13: =IF($AG13="","",ROUND($AG13*$AH$10,2)) -> 0 | AI13: =IF(ISERROR(IF($AF13="","",ROUND(SUM($R13,$AE13,$AH13),2))),"",IF($AF13="","",ROUND(SUM($R13,$AE13,$AH13),2))) -> 0 | AJ13: =IF(ISERROR(IF($AF13="","",VLOOKUP(AI13,TRANSMUTATION_TABLE,4,TRUE))),"",IF($AF13="","",VLOOKUP(AI13,TRANSMUTATION_TABLE,4,TRUE))) -> 60
A14: 3 | B14: ='INPUT DATA'!B14 -> BARRIENTOS, JOHN PAUL M. | G14: 10 | I14: 4 | J14: 20 | K14: 9 | L14: 90 | P14: =IF(COUNT($F14:$O14)=0,"",SUM($F14:$O14)) -> 133 | Q14: =IF(ISERROR(IF($P14="","",ROUND(($P14/$P$10)*$Q$10,2))),"",IF($P14="","",ROUND(($P14/$P$10)*$Q$10,2))) -> 54.29 | R14: =IF($Q14="","",ROUND($Q14*$R$10,2)) -> 16.29 | S14: 5 | U14: 40 | V14: 95 | W14: 90 | X14: 20 | Y14: 98 | AC14: =IF(COUNT($S14:$AB14)=0,"",SUM($S14:$AB14)) -> 348 | AD14: =IF(ISERROR(IF($AC14="","",ROUND(($AC14/$AC$10)*$AD$10,2))),"",IF($AC14="","",ROUND(($AC14/$AC$10)*$AD$10,2))) -> 83.86 | AE14: =IF($AD14="","",ROUND($AD14*$AE$10,2)) -> 41.93 | AF14: 22 | AG14: =IF(ISERROR(IF($AF14="","",ROUND(($AF14/$AF$10)*$AG$10,2))),"",IF($AF14="","",ROUND(($AF14/$AF$10)*$AG$10,2))) -> 55 | AH14: =IF($AG14="","",ROUND($AG14*$AH$10,2)) -> 11 | AI14: =IF(ISERROR(IF($AF14="","",ROUND(SUM($R14,$AE14,$AH14),2))),"",IF($AF14="","",ROUND(SUM($R14,$AE14,$AH14),2))) -> 69.22 | AJ14: =IF(ISERROR(IF($AF14="","",VLOOKUP(AI14,TRANSMUTATION_TABLE,4,TRUE))),"",IF($AF14="","",VLOOKUP(AI14,TRANSMUTATION_TABLE,4,TRUE))) -> 80 | AK14: =AJ14+5 -> 85 | AL14: 85 | AN14: =AF14+5 -> 27
A15: 4 | B15: ='INPUT DATA'!B15 -> BRIGOLE, ROMEL | G15: 2 | H15: 10 | K15: 0 | P15: =IF(COUNT($F15:$O15)=0,"",SUM($F15:$O15)) -> 12 | Q15: =IF(ISERROR(IF($P15="","",ROUND(($P15/$P$10)*$Q$10,2))),"",IF($P15="","",ROUND(($P15/$P$10)*$Q$10,2))) -> 4.9 | R15: =IF($Q15="","",ROUND($Q15*$R$10,2)) -> 1.47 | Y15: 98 | AC15: =IF(COUNT($S15:$AB15)=0,"",SUM($S15:$AB15)) -> 98 | AD15: =IF(ISERROR(IF($AC15="","",ROUND(($AC15/$AC$10)*$AD$10,2))),"",IF($AC15="","",ROUND(($AC15/$AC$10)*$AD$10,2))) -> 23.61 | AE15: =IF($AD15="","",ROUND($AD15*$AE$10,2)) -> 11.81 | AF15: 13 | AG15: =IF(ISERROR(IF($AF15="","",ROUND(($AF15/$AF$10)*$AG$10,2))),"",IF($AF15="","",ROUND(($AF15/$AF$10)*$AG$10,2))) -> 32.5 | AH15: =IF($AG15="","",ROUND($AG15*$AH$10,2)) -> 6.5 | AI15: =IF(ISERROR(IF($AF15="","",ROUND(SUM($R15,$AE15,$AH15),2))),"",IF($AF15="","",ROUND(SUM($R15,$AE15,$AH15),2))) -> 19.78 | AJ15: =IF(ISERROR(IF($AF15="","",VLOOKUP(AI15,TRANSMUTATION_TABLE,4,TRUE))),"",IF($AF15="","",VLOOKUP(AI15,TRANSMUTATION_TABLE,4,TRUE))) -> 64 | AK15: =AJ15+5 -> 69 | AL15: 75 | AN15: =AF15+5 -> 18
A16: 5 | B16: ='INPUT DATA'!B16 -> BULAHAN,ROVIC L. | G16: 10 | H16: 10 | I16: 4 | J16: 17 | K16: 8 | L16: 120 | P16: =IF(COUNT($F16:$O16)=0,"",SUM($F16:$O16)) -> 169 | Q16: =IF(ISERROR(IF($P16="","",ROUND(($P16/$P$10)*$Q$10,2))),"",IF($P16="","",ROUND(($P16/$P$10)*$Q$10,2))) -> 68.98 | R16: =IF($Q16="","",ROUND($Q16*$R$10,2)) -> 20.69 | S16: 5 | T16: 34 | U16: 40 | V16: 95 | W16: 90 | X16: 20 | Y16: 98 | AC16: =IF(COUNT($S16:$AB16)=0,"",SUM($S16:$AB16)) -> 382 | AD16: =IF(ISERROR(IF($AC16="","",ROUND(($AC16/$AC$10)*$AD$10,2))),"",IF($AC16="","",ROUND(($AC16/$AC$10)*$AD$10,2))) -> 92.05 | AE16: =IF($AD16="","",ROUND($AD16*$AE$10,2)) -> 46.03 | AF16: 26 | AG16: =IF(ISERROR(IF($AF16="","",ROUND(($AF16/$AF$10)*$AG$10,2))),"",IF($AF16="","",ROUND(($AF16/$AF$10)*$AG$10,2))) -> 65 | AH16: =IF($AG16="","",ROUND($AG16*$AH$10,2)) -> 13 | AI16: =IF(ISERROR(IF($AF16="","",ROUND(SUM($R16,$AE16,$AH16),2))),"",IF($AF16="","",ROUND(SUM($R16,$AE16,$AH16),2))) -> 79.72 | AJ16: =IF(ISERROR(IF($AF16="","",VLOOKUP(AI16,TRANSMUTATION_TABLE,4,TRUE))),"",IF($AF16="","",VLOOKUP(AI16,TRANSMUTATION_TABLE,4,TRUE))) -> 87 | AK16: =AJ16+5 -> 92 | AL16: 92 | AN16: =AF16+5 -> 31
A17: 6 | B17: ='INPUT DATA'!B17 -> CIJAS, ROLIE JR. A. | G17: 10 | I17: 2 | J17: 16 | K17: 10 | L17: 90 | P17: =IF(COUNT($F17:$O17)=0,"",SUM($F17:$O17)) -> 128 | Q17: =IF(ISERROR(IF($P17="","",ROUND(($P17/$P$10)*$Q$10,2))),"",IF($P17="","",ROUND(($P17/$P$10)*$Q$10,2))) -> 52.24 | R17: =IF($Q17="","",ROUND($Q17*$R$10,2)) -> 15.67 | S17: 5 | T17: 33 | U17: 43 | V17: 97 | X17: 20 | Y17: 98 | AC17: =IF(COUNT($S17:$AB17)=0,"",SUM($S17:$AB17)) -> 296 | AD17: =IF(ISERROR(IF($AC17="","",ROUND(($AC17/$AC$10)*$AD$10,2))),"",IF($AC17="","",ROUND(($AC17/$AC$10)*$AD$10,2))) -> 71.33 | AE17: =IF($AD17="","",ROUND($AD17*$AE$10,2)) -> 35.67 | AF17: 31 | AG17: =IF(ISERROR(IF($AF17="","",ROUND(($AF17/$AF$10)*$AG$10,2))),"",IF($AF17="","",ROUND(($AF17/$AF$10)*$AG$10,2))) -> 77.5 | AH17: =IF($AG17="","",ROUND($AG17*$AH$10,2)) -> 15.5 | AI17: =IF(ISERROR(IF($AF17="","",ROUND(SUM($R17,$AE17,$AH17),2))),"",IF($AF17="","",ROUND(SUM($R17,$AE17,$AH17),2))) -> 66.84 | AJ17: =IF(ISERROR(IF($AF17="","",VLOOKUP(AI17,TRANSMUTATION_TABLE,4,TRUE))),"",IF($AF17="","",VLOOKUP(AI17,TRANSMUTATION_TABLE,4,TRUE))) -> 79 | AK17: =AJ17+5 -> 84 | AL17: 84 | AN17: =AF17+5 -> 36
A18: 7 | B18: ='INPUT DATA'!B18 -> GARCIA, DAVE P. | F18: 8 | G18: 10 | I18: 3 | J18: 11 | P18: =IF(COUNT($F18:$O18)=0,"",SUM($F18:$O18)) -> 32 | Q18: =IF(ISERROR(IF($P18="","",ROUND(($P18/$P$10)*$Q$10,2))),"",IF($P18="","",ROUND(($P18/$P$10)*$Q$10,2))) -> 13.06 | R18: =IF($Q18="","",ROUND($Q18*$R$10,2)) -> 3.92 | S18: 5 | T18: 36 | U18: 40 | V18: 96 | W18: 94 | Y18: 98 | AC18: =IF(COUNT($S18:$AB18)=0,"",SUM($S18:$AB18)) -> 369 | AD18: =IF(ISERROR(IF($AC18="","",ROUND(($AC18/$AC$10)*$AD$10,2))),"",IF($AC18="","",ROUND(($AC18/$AC$10)*$AD$10,2))) -> 88.92 | AE18: =IF($AD18="","",ROUND($AD18*$AE$10,2)) -> 44.46 | AF18: 20 | AG18: =IF(ISERROR(IF($AF18="","",ROUND(($AF18/$AF$10)*$AG$10,2))),"",IF($AF18="","",ROUND(($AF18/$AF$10)*$AG$10,2))) -> 50 | AH18: =IF($AG18="","",ROUND($AG18*$AH$10,2)) -> 10 | AI18: =IF(ISERROR(IF($AF18="","",ROUND(SUM($R18,$AE18,$AH18),2))),"",IF($AF18="","",ROUND(SUM($R18,$AE18,$AH18),2))) -> 58.38 | AJ18: =IF(ISERROR(IF($AF18="","",VLOOKUP(AI18,TRANSMUTATION_TABLE,4,TRUE))),"",IF($AF18="","",VLOOKUP(AI18,TRANSMUTATION_TABLE,4,TRUE))) -> 74 | AK18: =AJ18+5 -> 79 | AL18: 78 | AN18: =AF18+5 -> 25
A19: 8 | B19: ='INPUT DATA'!B19 -> GONZALES, JAMES | D19: 0 | F19: 3 | G19: 10 | H19: 10 | I19: 4 | J19: 14 | K19: 10 | L19: 60 | P19: =IF(COUNT($F19:$O19)=0,"",SUM($F19:$O19)) -> 111 | Q19: =IF(ISERROR(IF($P19="","",ROUND(($P19/$P$10)*$Q$10,2))),"",IF($P19="","",ROUND(($P19/$P$10)*$Q$10,2))) -> 45.31 | R19: =IF($Q19="","",ROUND($Q19*$R$10,2)) -> 13.59 | S19: 5 | T19: 33 | U19: 45 | V19: 92 | Y19: 93 | AC19: =IF(COUNT($S19:$AB19)=0,"",SUM($S19:$AB19)) -> 268 | AD19: =IF(ISERROR(IF($AC19="","",ROUND(($AC19/$AC$10)*$AD$10,2))),"",IF($AC19="","",ROUND(($AC19/$AC$10)*$AD$10,2))) -> 64.58 | AE19: =IF($AD19="","",ROUND($AD19*$AE$10,2)) -> 32.29 | AF19: 14 | AG19: =IF(ISERROR(IF($AF19="","",ROUND(($AF19/$AF$10)*$AG$10,2))),"",IF($AF19="","",ROUND(($AF19/$AF$10)*$AG$10,2))) -> 35 | AH19: =IF($AG19="","",ROUND($AG19*$AH$10,2)) -> 7 | AI19: =IF(ISERROR(IF($AF19="","",ROUND(SUM($R19,$AE19,$AH19),2))),"",IF($AF19="","",ROUND(SUM($R19,$AE19,$AH19),2))) -> 52.88 | AJ19: =IF(ISERROR(IF($AF19="","",VLOOKUP(AI19,TRANSMUTATION_TABLE,4,TRUE))),"",IF($AF19="","",VLOOKUP(AI19,TRANSMUTATION_TABLE,4,TRUE))) -> 73 | AK19: =AJ19+5 -> 78 | AL19: 78 | AN19: =AF19+5 -> 19
A20: 9 | B20: ='INPUT DATA'!B20 -> LAGUNA, JB | F20: 5 | G20: 10 | H20: 10 | I20: 5 | J20: 16 | K20: 9 | L20: 110 | P20: =IF(COUNT($F20:$O20)=0,"",SUM($F20:$O20)) -> 165 | Q20: =IF(ISERROR(IF($P20="","",ROUND(($P20/$P$10)*$Q$10,2))),"",IF($P20="","",ROUND(($P20/$P$10)*$Q$10,2))) -> 67.35 | R20: =IF($Q20="","",ROUND($Q20*$R$10,2)) -> 20.21 | S20: 5 | T20: 34 | U20: 42 | V20: 98 | W20: 90 | X20: 18 | Y20: 93 | AC20: =IF(COUNT($S20:$AB20)=0,"",SUM($S20:$AB20)) -> 380 | AD20: =IF(ISERROR(IF($AC20="","",ROUND(($AC20/$AC$10)*$AD$10,2))),"",IF($AC20="","",ROUND(($AC20/$AC$10)*$AD$10,2))) -> 91.57 | AE20: =IF($AD20="","",ROUND($AD20*$AE$10,2)) -> 45.79 | AF20: 15 | AG20: =IF(ISERROR(IF($AF20="","",ROUND(($AF20/$AF$10)*$AG$10,2))),"",IF($AF20="","",ROUND(($AF20/$AF$10)*$AG$10,2))) -> 37.5 | AH20: =IF($AG20="","",ROUND($AG20*$AH$10,2)) -> 7.5 | AI20: =IF(ISERROR(IF($AF20="","",ROUND(SUM($R20,$AE20,$AH20),2))),"",IF($AF20="","",ROUND(SUM($R20,$AE20,$AH20),2))) -> 73.5 | AJ20: =IF(ISERROR(IF($AF20="","",VLOOKUP(AI20,TRANSMUTATION_TABLE,4,TRUE))),"",IF($AF20="","",VLOOKUP(AI20,TRANSMUTATION_TABLE,4,TRUE))) -> 83 | AK20: =AJ20+5 -> 88 | AL20: 88 | AN20: =AF20+5 -> 20
A21: 10 | B21: ='INPUT DATA'!B21 -> LARODA, STEVEN S. | F21: 5 | G21: 8 | H21: 10 | I21: 1 | J21: 13 | K21: 8 | L21: 80 | P21: =IF(COUNT($F21:$O21)=0,"",SUM($F21:$O21)) -> 125 | Q21: =IF(ISERROR(IF($P21="","",ROUND(($P21/$P$10)*$Q$10,2))),"",IF($P21="","",ROUND(($P21/$P$10)*$Q$10,2))) -> 51.02 | R21: =IF($Q21="","",ROUND($Q21*$R$10,2)) -> 15.31 | S21: 5 | T21: 33 | W21: 94 | X21: 18 | Y21: 98 | AC21: =IF(COUNT($S21:$AB21)=0,"",SUM($S21:$AB21)) -> 248 | AD21: =IF(ISERROR(IF($AC21="","",ROUND(($AC21/$AC$10)*$AD$10,2))),"",IF($AC21="","",ROUND(($AC21/$AC$10)*$AD$10,2))) -> 59.76 | AE21: =IF($AD21="","",ROUND($AD21*$AE$10,2)) -> 29.88 | AF21: 23 | AG21: =IF(ISERROR(IF($AF21="","",ROUND(($AF21/$AF$10)*$AG$10,2))),"",IF($AF21="","",ROUND(($AF21/$AF$10)*$AG$10,2))) -> 57.5 | AH21: =IF($AG21="","",ROUND($AG21*$AH$10,2)) -> 11.5 | AI21: =IF(ISERROR(IF($AF21="","",ROUND(SUM($R21,$AE21,$AH21),2))),"",IF($AF21="","",ROUND(SUM($R21,$AE21,$AH21),2))) -> 56.69 | AJ21: =IF(ISERROR(IF($AF21="","",VLOOKUP(AI21,TRANSMUTATION_TABLE,4,TRUE))),"",IF($AF21="","",VLOOKUP(AI21,TRANSMUTATION_TABLE,4,TRUE))) -> 74 | AK21: =AJ21+5 -> 79 | AL21: 79 | AN21: =AF21+5 -> 28
A22: 11 | B22: ='INPUT DATA'!B22 -> MERINO, SEDRIK R. | D22: 0 | G22: 1 | H22: 10 | I22: 1 | J22: 5 | P22: =IF(COUNT($F22:$O22)=0,"",SUM($F22:$O22)) -> 17 | Q22: =IF(ISERROR(IF($P22="","",ROUND(($P22/$P$10)*$Q$10,2))),"",IF($P22="","",ROUND(($P22/$P$10)*$Q$10,2))) -> 6.94 | R22: =IF($Q22="","",ROUND($Q22*$R$10,2)) -> 2.08 | S22: 5 | W22: 95 | Y22: 98 | AC22: =IF(COUNT($S22:$AB22)=0,"",SUM($S22:$AB22)) -> 198 | AD22: =IF(ISERROR(IF($AC22="","",ROUND(($AC22/$AC$10)*$AD$10,2))),"",IF($AC22="","",ROUND(($AC22/$AC$10)*$AD$10,2))) -> 47.71 | AE22: =IF($AD22="","",ROUND($AD22*$AE$10,2)) -> 23.86 | AF22: 12 | AG22: =IF(ISERROR(IF($AF22="","",ROUND(($AF22/$AF$10)*$AG$10,2))),"",IF($AF22="","",ROUND(($AF22/$AF$10)*$AG$10,2))) -> 30 | AH22: =IF($AG22="","",ROUND($AG22*$AH$10,2)) -> 6 | AI22: =IF(ISERROR(IF($AF22="","",ROUND(SUM($R22,$AE22,$AH22),2))),"",IF($AF22="","",ROUND(SUM($R22,$AE22,$AH22),2))) -> 31.94 | AJ22: =IF(ISERROR(IF($AF22="","",VLOOKUP(AI22,TRANSMUTATION_TABLE,4,TRUE))),"",IF($AF22="","",VLOOKUP(AI22,TRANSMUTATION_TABLE,4,TRUE))) -> 67 | AK22: =AJ22+5 -> 72 | AL22: 75 | AN22: =AF22+5 -> 17
A23: 12 | B23: ='INPUT DATA'!B23 -> MONTERAS, VINCENT S. | F23: 6 | G23: 9 | H23: 10 | I23: 2 | K23: 9 | L23: 80 | P23: =IF(COUNT($F23:$O23)=0,"",SUM($F23:$O23)) -> 116 | Q23: =IF(ISERROR(IF($P23="","",ROUND(($P23/$P$10)*$Q$10,2))),"",IF($P23="","",ROUND(($P23/$P$10)*$Q$10,2))) -> 47.35 | R23: =IF($Q23="","",ROUND($Q23*$R$10,2)) -> 14.21 | S23: 5 | V23: 97 | Y23: 92 | AC23: =IF(COUNT($S23:$AB23)=0,"",SUM($S23:$AB23)) -> 194 | AD23: =IF(ISERROR(IF($AC23="","",ROUND(($AC23/$AC$10)*$AD$10,2))),"",IF($AC23="","",ROUND(($AC23/$AC$10)*$AD$10,2))) -> 46.75 | AE23: =IF($AD23="","",ROUND($AD23*$AE$10,2)) -> 23.38 | AF23: 22 | AG23: =IF(ISERROR(IF($AF23="","",ROUND(($AF23/$AF$10)*$AG$10,2))),"",IF($AF23="","",ROUND(($AF23/$AF$10)*$AG$10,2))) -> 55 | AH23: =IF($AG23="","",ROUND($AG23*$AH$10,2)) -> 11 | AI23: =IF(ISERROR(IF($AF23="","",ROUND(SUM($R23,$AE23,$AH23),2))),"",IF($AF23="","",ROUND(SUM($R23,$AE23,$AH23),2))) -> 48.59 | AJ23: =IF(ISERROR(IF($AF23="","",VLOOKUP(AI23,TRANSMUTATION_TABLE,4,TRUE))),"",IF($AF23="","",VLOOKUP(AI23,TRANSMUTATION_TABLE,4,TRUE))) -> 72 | AK23: =AJ23+5 -> 77 | AL23: 77 | AN23: =AF23+5 -> 27
A24: 13 | B24: ='INPUT DATA'!B24 -> NACAWILI, ANDRIE L. | G24: 10 | H24: 10 | K24: 10 | L24: 20 | P24: =IF(COUNT($F24:$O24)=0,"",SUM($F24:$O24)) -> 50 | Q24: =IF(ISERROR(IF($P24="","",ROUND(($P24/$P$10)*$Q$10,2))),"",IF($P24="","",ROUND(($P24/$P$10)*$Q$10,2))) -> 20.41 | R24: =IF($Q24="","",ROUND($Q24*$R$10,2)) -> 6.12 | S24: 5 | T24: 33 | U24: 46 | V24: 97 | W24: 94 | X24: 20 | Y24: 98 | AC24: =IF(COUNT($S24:$AB24)=0,"",SUM($S24:$AB24)) -> 393 | AD24: =IF(ISERROR(IF($AC24="","",ROUND(($AC24/$AC$10)*$AD$10,2))),"",IF($AC24="","",ROUND(($AC24/$AC$10)*$AD$10,2))) -> 94.7 | AE24: =IF($AD24="","",ROUND($AD24*$AE$10,2)) -> 47.35 | AF24: 32 | AG24: =IF(ISERROR(IF($AF24="","",ROUND(($AF24/$AF$10)*$AG$10,2))),"",IF($AF24="","",ROUND(($AF24/$AF$10)*$AG$10,2))) -> 80 | AH24: =IF($AG24="","",ROUND($AG24*$AH$10,2)) -> 16 | AI24: =IF(ISERROR(IF($AF24="","",ROUND(SUM($R24,$AE24,$AH24),2))),"",IF($AF24="","",ROUND(SUM($R24,$AE24,$AH24),2))) -> 69.47 | AJ24: =IF(ISERROR(IF($AF24="","",VLOOKUP(AI24,TRANSMUTATION_TABLE,4,TRUE))),"",IF($AF24="","",VLOOKUP(AI24,TRANSMUTATION_TABLE,4,TRUE))) -> 80 | AK24: =AJ24+5 -> 85 | AL24: 85 | AN24: =AF24+5 -> 37
A25: 14 | B25: ='INPUT DATA'!B25 -> OLIVERIO, CYREL JAY G. | J25: 4 | K25: 2 | P25: =IF(COUNT($F25:$O25)=0,"",SUM($F25:$O25)) -> 6 | Q25: =IF(ISERROR(IF($P25="","",ROUND(($P25/$P$10)*$Q$10,2))),"",IF($P25="","",ROUND(($P25/$P$10)*$Q$10,2))) -> 2.45 | R25: =IF($Q25="","",ROUND($Q25*$R$10,2)) -> 0.74 | T25: 33 | Y25: 98 | AC25: =IF(COUNT($S25:$AB25)=0,"",SUM($S25:$AB25)) -> 131 | AD25: =IF(ISERROR(IF($AC25="","",ROUND(($AC25/$AC$10)*$AD$10,2))),"",IF($AC25="","",ROUND(($AC25/$AC$10)*$AD$10,2))) -> 31.57 | AE25: =IF($AD25="","",ROUND($AD25*$AE$10,2)) -> 15.79 | AF25: 14 | AG25: =IF(ISERROR(IF($AF25="","",ROUND(($AF25/$AF$10)*$AG$10,2))),"",IF($AF25="","",ROUND(($AF25/$AF$10)*$AG$10,2))) -> 35 | AH25: =IF($AG25="","",ROUND($AG25*$AH$10,2)) -> 7 | AI25: =IF(ISERROR(IF($AF25="","",ROUND(SUM($R25,$AE25,$AH25),2))),"",IF($AF25="","",ROUND(SUM($R25,$AE25,$AH25),2))) -> 23.53 | AJ25: =IF(ISERROR(IF($AF25="","",VLOOKUP(AI25,TRANSMUTATION_TABLE,4,TRUE))),"",IF($AF25="","",VLOOKUP(AI25,TRANSMUTATION_TABLE,4,TRUE))) -> 65 | AK25: =AJ25+5 -> 70 | AL25: 74 | AN25: =AF25+5 -> 19
A26: 15 | B26: ='INPUT DATA'!B26 -> ORBITA,BRENN JOHN A. | F26: 4 | G26: 10 | I26: 4 | J26: 18 | K26: 6 | P26: =IF(COUNT($F26:$O26)=0,"",SUM($F26:$O26)) -> 42 | Q26: =IF(ISERROR(IF($P26="","",ROUND(($P26/$P$10)*$Q$10,2))),"",IF($P26="","",ROUND(($P26/$P$10)*$Q$10,2))) -> 17.14 | R26: =IF($Q26="","",ROUND($Q26*$R$10,2)) -> 5.14 | S26: 5 | T26: 33 | V26: 98 | W26: 90 | X26: 18 | Y26: 93 | AC26: =IF(COUNT($S26:$AB26)=0,"",SUM($S26:$AB26)) -> 337 | AD26: =IF(ISERROR(IF($AC26="","",ROUND(($AC26/$AC$10)*$AD$10,2))),"",IF($AC26="","",ROUND(($AC26/$AC$10)*$AD$10,2))) -> 81.2 | AE26: =IF($AD26="","",ROUND($AD26*$AE$10,2)) -> 40.6 | AF26: 14 | AG26: =IF(ISERROR(IF($AF26="","",ROUND(($AF26/$AF$10)*$AG$10,2))),"",IF($AF26="","",ROUND(($AF26/$AF$10)*$AG$10,2))) -> 35 | AH26: =IF($AG26="","",ROUND($AG26*$AH$10,2)) -> 7 | AI26: =IF(ISERROR(IF($AF26="","",ROUND(SUM($R26,$AE26,$AH26),2))),"",IF($AF26="","",ROUND(SUM($R26,$AE26,$AH26),2))) -> 52.74 | AJ26: =IF(ISERROR(IF($AF26="","",VLOOKUP(AI26,TRANSMUTATION_TABLE,4,TRUE))),"",IF($AF26="","",VLOOKUP(AI26,TRANSMUTATION_TABLE,4,TRUE))) -> 73 | AK26: =AJ26+5 -> 78 | AL26: 78 | AN26: =AF26+5 -> 19
A27: 16 | B27: ='INPUT DATA'!B27 -> PAINLO,SHERWIN V. | F27: 5 | G27: 10 | H27: 10 | I27: 4 | J27: 14 | K27: 8 | L27: 100 | P27: =IF(COUNT($F27:$O27)=0,"",SUM($F27:$O27)) -> 151 | Q27: =IF(ISERROR(IF($P27="","",ROUND(($P27/$P$10)*$Q$10,2))),"",IF($P27="","",ROUND(($P27/$P$10)*$Q$10,2))) -> 61.63 | R27: =IF($Q27="","",ROUND($Q27*$R$10,2)) -> 18.49 | S27: 5 | T27: 33 | U27: 40 | V27: 98 | W27: 90 | Y27: 93 | AC27: =IF(COUNT($S27:$AB27)=0,"",SUM($S27:$AB27)) -> 359 | AD27: =IF(ISERROR(IF($AC27="","",ROUND(($AC27/$AC$10)*$AD$10,2))),"",IF($AC27="","",ROUND(($AC27/$AC$10)*$AD$10,2))) -> 86.51 | AE27: =IF($AD27="","",ROUND($AD27*$AE$10,2)) -> 43.26 | AF27: 32 | AG27: =IF(ISERROR(IF($AF27="","",ROUND(($AF27/$AF$10)*$AG$10,2))),"",IF($AF27="","",ROUND(($AF27/$AF$10)*$AG$10,2))) -> 80 | AH27: =IF($AG27="","",ROUND($AG27*$AH$10,2)) -> 16 | AI27: =IF(ISERROR(IF($AF27="","",ROUND(SUM($R27,$AE27,$AH27),2))),"",IF($AF27="","",ROUND(SUM($R27,$AE27,$AH27),2))) -> 77.75 | AJ27: =IF(ISERROR(IF($AF27="","",VLOOKUP(AI27,TRANSMUTATION_TABLE,4,TRUE))),"",IF($AF27="","",VLOOKUP(AI27,TRANSMUTATION_TABLE,4,TRUE))) -> 86 | AK27: =AJ27+5 -> 91 | AL27: 91 | AN27: =AF27+5 -> 37
A28: 17 | B28: ='INPUT DATA'!B28 -> RAMIREZ, MATTEO JOHN DAVE D. | P28: =IF(COUNT($F28:$O28)=0,"",SUM($F28:$O28)) | Q28: =IF(ISERROR(IF($P28="","",ROUND(($P28/$P$10)*$Q$10,2))),"",IF($P28="","",ROUND(($P28/$P$10)*$Q$10,2))) | R28: =IF($Q28="","",ROUND($Q28*$R$10,2)) | W28: 95 | AC28: =IF(COUNT($S28:$AB28)=0,"",SUM($S28:$AB28)) -> 95 | AD28: =IF(ISERROR(IF($AC28="","",ROUND(($AC28/$AC$10)*$AD$10,2))),"",IF($AC28="","",ROUND(($AC28/$AC$10)*$AD$10,2))) -> 22.89 | AE28: =IF($AD28="","",ROUND($AD28*$AE$10,2)) -> 11.45 | AF28: 16 | AG28: =IF(ISERROR(IF($AF28="","",ROUND(($AF28/$AF$10)*$AG$10,2))),"",IF($AF28="","",ROUND(($AF28/$AF$10)*$AG$10,2))) -> 40 | AH28: =IF($AG28="","",ROUND($AG28*$AH$10,2)) -> 8 | AI28: =IF(ISERROR(IF($AF28="","",ROUND(SUM($R28,$AE28,$AH28),2))),"",IF($AF28="","",ROUND(SUM($R28,$AE28,$AH28),2))) -> 19.45 | AJ28: =IF(ISERROR(IF($AF28="","",VLOOKUP(AI28,TRANSMUTATION_TABLE,4,TRUE))),"",IF($AF28="","",VLOOKUP(AI28,TRANSMUTATION_TABLE,4,TRUE))) -> 64 | AK28: =AJ28+5 -> 69 | AN28: =AF28+5 -> 21
A29: 18 | B29: ='INPUT DATA'!B29 -> SIGUIRA, JASTINE B. | H29: 10 | P29: =IF(COUNT($F29:$O29)=0,"",SUM($F29:$O29)) -> 10 | Q29: =IF(ISERROR(IF($P29="","",ROUND(($P29/$P$10)*$Q$10,2))),"",IF($P29="","",ROUND(($P29/$P$10)*$Q$10,2))) -> 4.08 | R29: =IF($Q29="","",ROUND($Q29*$R$10,2)) -> 1.22 | S29: 5 | W29: 95 | AC29: =IF(COUNT($S29:$AB29)=0,"",SUM($S29:$AB29)) -> 100 | AD29: =IF(ISERROR(IF($AC29="","",ROUND(($AC29/$AC$10)*$AD$10,2))),"",IF($AC29="","",ROUND(($AC29/$AC$10)*$AD$10,2))) -> 24.1 | AE29: =IF($AD29="","",ROUND($AD29*$AE$10,2)) -> 12.05 | AF29: 16 | AG29: =IF(ISERROR(IF($AF29="","",ROUND(($AF29/$AF$10)*$AG$10,2))),"",IF($AF29="","",ROUND(($AF29/$AF$10)*$AG$10,2))) -> 40 | AH29: =IF($AG29="","",ROUND($AG29*$AH$10,2)) -> 8 | AI29: =IF(ISERROR(IF($AF29="","",ROUND(SUM($R29,$AE29,$AH29),2))),"",IF($AF29="","",ROUND(SUM($R29,$AE29,$AH29),2))) -> 21.27 | AJ29: =IF(ISERROR(IF($AF29="","",VLOOKUP(AI29,TRANSMUTATION_TABLE,4,TRUE))),"",IF($AF29="","",VLOOKUP(AI29,TRANSMUTATION_TABLE,4,TRUE))) -> 65 | AK29: =AJ29+5 -> 70 | AN29: =AF29+5 -> 21
A30: 19 | B30: ='INPUT DATA'!B30 -> TAA, JHONVINZ Y. | H30: 10 | I30: 2 | K30: 8 | P30: =IF(COUNT($F30:$O30)=0,"",SUM($F30:$O30)) -> 20 | Q30: =IF(ISERROR(IF($P30="","",ROUND(($P30/$P$10)*$Q$10,2))),"",IF($P30="","",ROUND(($P30/$P$10)*$Q$10,2))) -> 8.16 | R30: =IF($Q30="","",ROUND($Q30*$R$10,2)) -> 2.45 | S30: 5 | V30: 92 | Y30: 95 | AC30: =IF(COUNT($S30:$AB30)=0,"",SUM($S30:$AB30)) -> 192 | AD30: =IF(ISERROR(IF($AC30="","",ROUND(($AC30/$AC$10)*$AD$10,2))),"",IF($AC30="","",ROUND(($AC30/$AC$10)*$AD$10,2))) -> 46.27 | AE30: =IF($AD30="","",ROUND($AD30*$AE$10,2)) -> 23.14 | AF30: 7 | AG30: =IF(ISERROR(IF($AF30="","",ROUND(($AF30/$AF$10)*$AG$10,2))),"",IF($AF30="","",ROUND(($AF30/$AF$10)*$AG$10,2))) -> 17.5 | AH30: =IF($AG30="","",ROUND($AG30*$AH$10,2)) -> 3.5 | AI30: =IF(ISERROR(IF($AF30="","",ROUND(SUM($R30,$AE30,$AH30),2))),"",IF($AF30="","",ROUND(SUM($R30,$AE30,$AH30),2))) -> 29.09 | AJ30: =IF(ISERROR(IF($AF30="","",VLOOKUP(AI30,TRANSMUTATION_TABLE,4,TRUE))),"",IF($AF30="","",VLOOKUP(AI30,TRANSMUTATION_TABLE,4,TRUE))) -> 67 | AK30: =AJ30+5 -> 72 | AL30: 74 | AN30: =AF30+5 -> 12
A31: 20 | B31: ='INPUT DATA'!B31 -> ZOILO, JOHN LORENCE M. | F31: 4 | G31: 10 | H31: 10 | I31: 5 | J31: 19 | K31: 7 | L31: 50 | P31: =IF(COUNT($F31:$O31)=0,"",SUM($F31:$O31)) -> 105 | Q31: =IF(ISERROR(IF($P31="","",ROUND(($P31/$P$10)*$Q$10,2))),"",IF($P31="","",ROUND(($P31/$P$10)*$Q$10,2))) -> 42.86 | R31: =IF($Q31="","",ROUND($Q31*$R$10,2)) -> 12.86 | S31: 5 | T31: 36 | V31: 97 | W31: 90 | X31: 18 | Y31: 93 | AC31: =IF(COUNT($S31:$AB31)=0,"",SUM($S31:$AB31)) -> 339 | AD31: =IF(ISERROR(IF($AC31="","",ROUND(($AC31/$AC$10)*$AD$10,2))),"",IF($AC31="","",ROUND(($AC31/$AC$10)*$AD$10,2))) -> 81.69 | AE31: =IF($AD31="","",ROUND($AD31*$AE$10,2)) -> 40.85 | AF31: 18 | AG31: =IF(ISERROR(IF($AF31="","",ROUND(($AF31/$AF$10)*$AG$10,2))),"",IF($AF31="","",ROUND(($AF31/$AF$10)*$AG$10,2))) -> 45 | AH31: =IF($AG31="","",ROUND($AG31*$AH$10,2)) -> 9 | AI31: =IF(ISERROR(IF($AF31="","",ROUND(SUM($R31,$AE31,$AH31),2))),"",IF($AF31="","",ROUND(SUM($R31,$AE31,$AH31),2))) -> 62.71 | AJ31: =IF(ISERROR(IF($AF31="","",VLOOKUP(AI31,TRANSMUTATION_TABLE,4,TRUE))),"",IF($AF31="","",VLOOKUP(AI31,TRANSMUTATION_TABLE,4,TRUE))) -> 76 | AK31: =AJ31+5 -> 81 | AL31: 79 | AN31: =AF31+5 -> 23
A32: 21 | B32: ='INPUT DATA'!B32 -> CABO, JEREM | P32: =IF(COUNT($F32:$O32)=0,"",SUM($F32:$O32)) | Q32: =IF(ISERROR(IF($P32="","",ROUND(($P32/$P$10)*$Q$10,2))),"",IF($P32="","",ROUND(($P32/$P$10)*$Q$10,2))) | R32: =IF($Q32="","",ROUND($Q32*$R$10,2)) | AC32: =IF(COUNT($S32:$AB32)=0,"",SUM($S32:$AB32)) | AD32: =IF(ISERROR(IF($AC32="","",ROUND(($AC32/$AC$10)*$AD$10,2))),"",IF($AC32="","",ROUND(($AC32/$AC$10)*$AD$10,2))) | AE32: =IF($AD32="","",ROUND($AD32*$AE$10,2)) | AG32: =IF(ISERROR(IF($AF32="","",ROUND(($AF32/$AF$10)*$AG$10,2))),"",IF($AF32="","",ROUND(($AF32/$AF$10)*$AG$10,2))) | AH32: =IF($AG32="","",ROUND($AG32*$AH$10,2)) | AI32: =IF(ISERROR(IF($AF32="","",ROUND(SUM($R32,$AE32,$AH32),2))),"",IF($AF32="","",ROUND(SUM($R32,$AE32,$AH32),2))) | AJ32: =IF(ISERROR(IF($AF32="","",VLOOKUP(AI32,TRANSMUTATION_TABLE,4,TRUE))),"",IF($AF32="","",VLOOKUP(AI32,TRANSMUTATION_TABLE,4,TRUE)))
A33: 22 | B33: ='INPUT DATA'!B33 -> 0 | P33: =IF(COUNT($F33:$O33)=0,"",SUM($F33:$O33)) | Q33: =IF(ISERROR(IF($P33="","",ROUND(($P33/$P$10)*$Q$10,2))),"",IF($P33="","",ROUND(($P33/$P$10)*$Q$10,2))) | R33: =IF($Q33="","",ROUND($Q33*$R$10,2)) | AC33: =IF(COUNT($S33:$AB33)=0,"",SUM($S33:$AB33)) | AD33: =IF(ISERROR(IF($AC33="","",ROUND(($AC33/$AC$10)*$AD$10,2))),"",IF($AC33="","",ROUND(($AC33/$AC$10)*$AD$10,2))) | AE33: =IF($AD33="","",ROUND($AD33*$AE$10,2)) | AG33: =IF(ISERROR(IF($AF33="","",ROUND(($AF33/$AF$10)*$AG$10,2))),"",IF($AF33="","",ROUND(($AF33/$AF$10)*$AG$10,2))) | AH33: =IF($AG33="","",ROUND($AG33*$AH$10,2)) | AI33: =IF(ISERROR(IF($AF33="","",ROUND(SUM($R33,$AE33,$AH33),2))),"",IF($AF33="","",ROUND(SUM($R33,$AE33,$AH33),2))) | AJ33: =IF(ISERROR(IF($AF33="","",VLOOKUP(AI33,TRANSMUTATION_TABLE,4,TRUE))),"",IF($AF33="","",VLOOKUP(AI33,TRANSMUTATION_TABLE,4,TRUE)))
A34: 23 | B34: ='INPUT DATA'!B34 -> 0 | P34: =IF(COUNT($F34:$O34)=0,"",SUM($F34:$O34)) | Q34: =IF(ISERROR(IF($P34="","",ROUND(($P34/$P$10)*$Q$10,2))),"",IF($P34="","",ROUND(($P34/$P$10)*$Q$10,2))) | R34: =IF($Q34="","",ROUND($Q34*$R$10,2)) | AC34: =IF(COUNT($S34:$AB34)=0,"",SUM($S34:$AB34)) | AD34: =IF(ISERROR(IF($AC34="","",ROUND(($AC34/$AC$10)*$AD$10,2))),"",IF($AC34="","",ROUND(($AC34/$AC$10)*$AD$10,2))) | AE34: =IF($AD34="","",ROUND($AD34*$AE$10,2)) | AG34: =IF(ISERROR(IF($AF34="","",ROUND(($AF34/$AF$10)*$AG$10,2))),"",IF($AF34="","",ROUND(($AF34/$AF$10)*$AG$10,2))) | AH34: =IF($AG34="","",ROUND($AG34*$AH$10,2)) | AI34: =IF(ISERROR(IF($AF34="","",ROUND(SUM($R34,$AE34,$AH34),2))),"",IF($AF34="","",ROUND(SUM($R34,$AE34,$AH34),2))) | AJ34: =IF(ISERROR(IF($AF34="","",VLOOKUP(AI34,TRANSMUTATION_TABLE,4,TRUE))),"",IF($AF34="","",VLOOKUP(AI34,TRANSMUTATION_TABLE,4,TRUE)))
A35: 24 | B35: ='INPUT DATA'!B35 -> 0 | P35: =IF(COUNT($F35:$O35)=0,"",SUM($F35:$O35)) | Q35: =IF(ISERROR(IF($P35="","",ROUND(($P35/$P$10)*$Q$10,2))),"",IF($P35="","",ROUND(($P35/$P$10)*$Q$10,2))) | R35: =IF($Q35="","",ROUND($Q35*$R$10,2)) | AC35: =IF(COUNT($S35:$AB35)=0,"",SUM($S35:$AB35)) | AD35: =IF(ISERROR(IF($AC35="","",ROUND(($AC35/$AC$10)*$AD$10,2))),"",IF($AC35="","",ROUND(($AC35/$AC$10)*$AD$10,2))) | AE35: =IF($AD35="","",ROUND($AD35*$AE$10,2)) | AG35: =IF(ISERROR(IF($AF35="","",ROUND(($AF35/$AF$10)*$AG$10,2))),"",IF($AF35="","",ROUND(($AF35/$AF$10)*$AG$10,2))) | AH35: =IF($AG35="","",ROUND($AG35*$AH$10,2)) | AI35: =IF(ISERROR(IF($AF35="","",ROUND(SUM($R35,$AE35,$AH35),2))),"",IF($AF35="","",ROUND(SUM($R35,$AE35,$AH35),2))) | AJ35: =IF(ISERROR(IF($AF35="","",VLOOKUP(AI35,TRANSMUTATION_TABLE,4,TRUE))),"",IF($AF35="","",VLOOKUP(AI35,TRANSMUTATION_TABLE,4,TRUE)))
A36: 25 | B36: ='INPUT DATA'!B36 -> 0 | P36: =IF(COUNT($F36:$O36)=0,"",SUM($F36:$O36)) | Q36: =IF(ISERROR(IF($P36="","",ROUND(($P36/$P$10)*$Q$10,2))),"",IF($P36="","",ROUND(($P36/$P$10)*$Q$10,2))) | R36: =IF($Q36="","",ROUND($Q36*$R$10,2)) | AC36: =IF(COUNT($S36:$AB36)=0,"",SUM($S36:$AB36)) | AD36: =IF(ISERROR(IF($AC36="","",ROUND(($AC36/$AC$10)*$AD$10,2))),"",IF($AC36="","",ROUND(($AC36/$AC$10)*$AD$10,2))) | AE36: =IF($AD36="","",ROUND($AD36*$AE$10,2)) | AG36: =IF(ISERROR(IF($AF36="","",ROUND(($AF36/$AF$10)*$AG$10,2))),"",IF($AF36="","",ROUND(($AF36/$AF$10)*$AG$10,2))) | AH36: =IF($AG36="","",ROUND($AG36*$AH$10,2)) | AI36: =IF(ISERROR(IF($AF36="","",ROUND(SUM($R36,$AE36,$AH36),2))),"",IF($AF36="","",ROUND(SUM($R36,$AE36,$AH36),2))) | AJ36: =IF(ISERROR(IF($AF36="","",VLOOKUP(AI36,TRANSMUTATION_TABLE,4,TRUE))),"",IF($AF36="","",VLOOKUP(AI36,TRANSMUTATION_TABLE,4,TRUE)))
A37: 26 | B37: ='INPUT DATA'!B37 -> 0 | P37: =IF(COUNT($F37:$O37)=0,"",SUM($F37:$O37)) | Q37: =IF(ISERROR(IF($P37="","",ROUND(($P37/$P$10)*$Q$10,2))),"",IF($P37="","",ROUND(($P37/$P$10)*$Q$10,2))) | R37: =IF($Q37="","",ROUND($Q37*$R$10,2)) | AC37: =IF(COUNT($S37:$AB37)=0,"",SUM($S37:$AB37)) | AD37: =IF(ISERROR(IF($AC37="","",ROUND(($AC37/$AC$10)*$AD$10,2))),"",IF($AC37="","",ROUND(($AC37/$AC$10)*$AD$10,2))) | AE37: =IF($AD37="","",ROUND($AD37*$AE$10,2)) | AG37: =IF(ISERROR(IF($AF37="","",ROUND(($AF37/$AF$10)*$AG$10,2))),"",IF($AF37="","",ROUND(($AF37/$AF$10)*$AG$10,2))) | AH37: =IF($AG37="","",ROUND($AG37*$AH$10,2)) | AI37: =IF(ISERROR(IF($AF37="","",ROUND(SUM($R37,$AE37,$AH37),2))),"",IF($AF37="","",ROUND(SUM($R37,$AE37,$AH37),2))) | AJ37: =IF(ISERROR(IF($AF37="","",VLOOKUP(AI37,TRANSMUTATION_TABLE,4,TRUE))),"",IF($AF37="","",VLOOKUP(AI37,TRANSMUTATION_TABLE,4,TRUE)))
A38: 27 | B38: ='INPUT DATA'!B38 -> 0 | P38: =IF(COUNT($F38:$O38)=0,"",SUM($F38:$O38)) | Q38: =IF(ISERROR(IF($P38="","",ROUND(($P38/$P$10)*$Q$10,2))),"",IF($P38="","",ROUND(($P38/$P$10)*$Q$10,2))) | R38: =IF($Q38="","",ROUND($Q38*$R$10,2)) | AC38: =IF(COUNT($S38:$AB38)=0,"",SUM($S38:$AB38)) | AD38: =IF(ISERROR(IF($AC38="","",ROUND(($AC38/$AC$10)*$AD$10,2))),"",IF($AC38="","",ROUND(($AC38/$AC$10)*$AD$10,2))) | AE38: =IF($AD38="","",ROUND($AD38*$AE$10,2)) | AG38: =IF(ISERROR(IF($AF38="","",ROUND(($AF38/$AF$10)*$AG$10,2))),"",IF($AF38="","",ROUND(($AF38/$AF$10)*$AG$10,2))) | AH38: =IF($AG38="","",ROUND($AG38*$AH$10,2)) | AI38: =IF(ISERROR(IF($AF38="","",ROUND(SUM($R38,$AE38,$AH38),2))),"",IF($AF38="","",ROUND(SUM($R38,$AE38,$AH38),2))) | AJ38: =IF(ISERROR(IF($AF38="","",VLOOKUP(AI38,TRANSMUTATION_TABLE,4,TRUE))),"",IF($AF38="","",VLOOKUP(AI38,TRANSMUTATION_TABLE,4,TRUE)))
